Workbook

Sheet Guide
A1: GT AI Opportunity Discovery Toolkit
A2: Where exactly does AI fit in this organisation - and where is automation enough? A facilitated workshop tool of the GT AI Strategy & Roadmap service, built on a 240-entry, standards-based AI use-case library.
B4: WHAT THIS TOOLKIT ANSWERS
B5: 1. Is the organisation positioned for AI? | C5: Do you have the DATA (digital, joined-up, reliable, with history and outcomes) and the SCALE / CAPACITY (volumes, people, budget, technology team) for AI - or is automation enough for now? Result: one of four archetypes and a ceiling on solution complexity.
B6: 2. Where exactly does AI fit? | C6: Process by process, selected from the GT AI Use-Case Library for the client's sector: which solution family fits (automate, off-the-shelf AI, configured AI, custom / agentic AI), is the data there, what is the risk tier - and what exactly GT recommends.
B7: 3. What should be done first? | C7: Value x feasibility, risk-adjusted priority, horizon (H1 / H2 / H3), opportunity report, roadmap lanes and one-page use-case canvases.
B8: Not a readiness test | C8: Governance and capability maturity are measured by the GT AI Readiness & Risk Assessment (AI Ready7-based). This toolkit locates the opportunities and the right type of solution for each.
B10: HOW TO USE IT (WORKSHOP SEQUENCE)
B11: 1. AI Position | C11: Select the sector, then answer 12 questions with leadership, IT and finance (about 30 minutes). Data Position and Scale & Capacity scores place the organisation in an archetype.
B12: 2. Use-Case Library | C12: 240 use cases: 60 cross-industry plus 180 sector-specific entries (banking, insurance, capital markets, healthcare, telecom, government, retail, hospitality, manufacturing, energy, logistics, real estate, education, professional services). Each entry carries the GT recommendation, data needed, KPIs, regulatory notes and a minimum risk tier.
B13: 3. AI Fit Diagnostic | C13: Select up to 50 use cases from the library (the list shows cross-industry + the selected sector) and answer 9 inputs each (yellow). Custom processes can be typed in - then select the task nature and function. Everything else calculates, including the library recommendation.
B14: 4. Opportunity Report | C14: The client-ready output: AI position, verdict mix, where AI fits by function, the top 10 opportunities with GT recommendations and the sector lens.
B15: 5. Roadmap | C15: Opportunities placed automatically in H1 / H2 / H3 lanes plus the enabling foundations they depend on.
B16: 6. Use-Case Canvas | C16: Pick an opportunity number; a one-page canvas is produced (recommendation, data, KPIs, risk tier, regulatory notes, minimum controls, next step).
B17: 7. Sector Profiles | C17: Value at stake, automation & AI potential, value pools and key regulators for each sector.
B18: Reference | C18: Solution families, archetypes, verdicts, minimum controls, function taxonomy (APQC) and the standards behind each step.
B19: Colour legend | C19: Yellow = input | Purple / lavender = header or calculated | Verdict colours: green = AI fit now, blue = automate, yellow = data gap, orange = stretch, grey = redesign first
B21: DECISION LOGIC (SUMMARY)
B22: Solution family | C22: From the nature of the task (library default, or override). 10 families, ISO/IEC 22989 / OECD-based, each with a complexity level 1-5 and a minimum data requirement.
B23: Data gate | C23: Data available for the process >= the family's minimum requirement -> 'Data ready', otherwise 'Data gap'.
B24: Organisational fit | C24: Family level <= the archetype's ceiling -> 'Within current position', otherwise 'Beyond current position'.
B25: Verdict (in order) | C25: Process not standardised -> Redesign first; family needs no AI -> Automate; data gap -> AI later; beyond position -> Stretch; otherwise -> AI fit now.
B26: Value (1-5) | C26: 30% volume + 25% effort (hours / month) + 25% strategic importance + 20% customer / quality impact.
B27: Feasibility (1-5) | C27: 30% data fit + 25% process standardisation + 25% solution simplicity + 20% organisational fit.
B28: Risk tier | C28: AIAF-style inherent risk: affects individuals' rights / access (+2), personal or confidential data (+1), autonomy (+0 to +2), impact of errors (+1 if 4, +2 if 5): 4+ High, 2-3 Medium, 0-1 Low; never below the library's minimum tier (EU AI Act Annex III / sector rules).
B29: Priority | C29: Value x Feasibility, reduced 15% for High risk and 20% where the process must be redesigned first. Ranked 1..n.
B30: Horizon | C30: H1: quick wins / fill-ins that fit now or need only automation. H2: strategic bets, stretch items, redesigned processes - and any High-risk or agentic (level 5) use case, which waits for its impact assessment and controls. H3: items blocked by data gaps. Backlog: deprioritised.

Sheet 1. AI Position
A1: 1. Organisational AI Position
A2: Does the organisation have the data and the scale / capacity for AI - or is automation enough for now? Select the sector and one answer per question (yellow). This screen does not measure governance maturity.
B4: Organisation | C4: Grant Thornton Bahrain (illustrative)
B5: Sector (filters the use-case library) | C5: Professional services
B6: Scope of discovery | C6: Whole firm - audit, tax, advisory and support functions
B7: Assessment date | C7: 04/10/2026
B8: Facilitated by | C8: GT AI Service Line
A10: # | B10: Question | C10: Answer (select) | D10: Why it matters | E10: Points
A11: A. DATA POSITION - is the data there for AI?
A12: D1 | B12: How are your core business processes run today? | C12: Core systems (e.g., ERP, CRM, core banking) for the main processes | D12: Think of the 3-5 processes that generate most of your revenue or workload. | E12: =IFERROR(MATCH(C12,Lists!$S$2:$S$5,0),"") -> 3
A13: D2 | B13: How much digital history do you keep for your core activities (transactions, customers, cases, operations)? | C13: 3+ years in core systems | D13: AI that predicts, scores or detects patterns learns from history. | E13: =IFERROR(MATCH(C13,Lists!$T$2:$T$5,0),"") -> 3
A14: D3 | B14: How reliable is that data, and does it have owners? | C14: Some owners; known quality issues not tracked | D14: Data quality and ownership - ISO/IEC 5259 / ISO/IEC 42001 Annex A.7. | E14: =IFERROR(MATCH(C14,Lists!$U$2:$U$5,0),"") -> 2
A15: D4 | B15: Where do your documents and knowledge live (contracts, policies, reports, emails, manuals)? | C15: A document-management system or SharePoint with structure | D15: Generative AI and knowledge assistants work on documents rather than tables. | E15: =IFERROR(MATCH(C15,Lists!$V$2:$V$5,0),"") -> 3
A16: D5 | B16: Can data move between your systems? | C16: Some APIs or integrations between key systems | D16: Integration determines whether AI outputs can be used inside the workflow. | E16: =IFERROR(MATCH(C16,Lists!$W$2:$W$5,0),"") -> 3
A17: D6 | B17: Do you record outcomes against your data (e.g., fraud confirmed, claim paid, customer churned, invoice disputed)? | C17: Occasionally / informally | D17: Recorded outcomes ('labels') are what supervised machine learning needs. | E17: =IFERROR(MATCH(C17,Lists!$X$2:$X$5,0),"") -> 2
A18: B. SCALE & CAPACITY - is there enough volume and capacity to justify and run AI?
A19: S1 | B19: How many employees does the organisation have? | C19: 50 - 249 | D19: Scale drives the size of the prize and what can be sustained. | E19: =IFERROR(MATCH(C19,Lists!$Y$2:$Y$5,0),"") -> 2
A20: S2 | B20: How many repetitive transactions / cases does your largest process handle per month? | C20: 500 - 5,000 | D20: e.g., invoices, applications, claims, customer requests, bookings. | E20: =IFERROR(MATCH(C20,Lists!$Z$2:$Z$5,0),"") -> 2
A21: S3 | B21: What technology capability do you have in-house? | C21: Small IT team (support and vendor management) | D21: Who would configure, integrate and run a solution? | E21: =IFERROR(MATCH(C21,Lists!$AA$2:$AA$5,0),"") -> 2
A22: S4 | B22: What budget could be made available for digital / AI initiatives in the next 12 months? | C22: BHD 50,000 - 250,000 | D22: Indicative only - used to size the type of solution that is realistic. | E22: =IFERROR(MATCH(C22,Lists!$AB$2:$AB$5,0),"") -> 3
A23: S5 | B23: How many customer / citizen interactions do you handle through digital channels? | C23: Moderate | D23: Web, app, email, WhatsApp, call centre. | E23: =IFERROR(MATCH(C23,Lists!$AC$2:$AC$5,0),"") -> 2
A24: S6 | B24: What capacity do you have to run change projects alongside day-to-day work? | C24: Several projects in parallel | D24: Leadership bandwidth, project management, change management. | E24: =IFERROR(MATCH(C24,Lists!$AD$2:$AD$5,0),"") -> 3
A26: RESULT - AI POSITION
B27: Answered | C27: =COUNT(E12,E13,E14,E15,E16,E17)+COUNT(E19,E20,E21,E22,E23,E24)&" of 12" -> 12 of 12
B28: Data Position score | C28: =IF(COUNT(E12,E13,E14,E15,E16,E17)=6,(N(E12)+N(E13)+N(E14)+N(E15)+N(E16)+N(E17)-6)/18,"") -> 0.55555556
B29: Scale & Capacity score | C29: =IF(COUNT(E19,E20,E21,E22,E23,E24)=6,(N(E19)+N(E20)+N(E21)+N(E22)+N(E23)+N(E24)-6)/18,"") -> 0.44444444
B30: Archetype | C30: =IF(OR(C28="",C29=""),"",IF(C28<0.5,IF(C29<0.5,1,2),IF(C29<0.5,3,4))) -> 3
B31: AI position | C31: =IF(C30="","Complete all 12 questions",INDEX(Lists!$AH$2:$AH$5,C30)) -> Buy and configure AI
B32: Solution ceiling today | C32: =IF(C30="","",INDEX(Lists!$AI$2:$AI$5,C30)&" - "&INDEX(Lists!$AM$2:$AM$6,INDEX(Lists!$AI$2:$AI$5,C30))) -> 4 - Configured AI on own data
B33: What it means | C33: =IF(C30="","",INDEX(Lists!$AJ$2:$AJ$5,C30)) -> Good data, limited scale / capacity: adopt and configure proven AI products rather than build.
B34: Detail | C34: =IF(C30="","",INDEX(Lists!$AK$2:$AK$5,C30)) -> The data supports AI, but in-house capacity and scale favour buying. Configure AI products on your own data (knowledge assistants, intelligent document processing, conversational AI, vendor ML modules). Custom models and autonomous agents only through partners and pilots.
B35: Foundation flag | C35: =IF(E12=1,"Core processes are largely manual / paper-based: digitise them first - AI and automation need digital inputs.",IF(AND(N(E13)>0,N(E13)<=2,N(E17)<=1),"Little digital history and no recorded outcomes: predictive / ML use cases will fail the data gate until data is captured.","No foundation red flags from the position screen.")) -> No foundation red flags from the position screen.
A37: POSITION MATRIX - the highlighted box is where the organisation sits
B38: Data Position HIGH (>= 50%) | C38: C. Buy and configure AI Good data, limited scale / capacity: adopt and configure proven AI products rather than build. | D38: D. Build and scale AI Data and scale support custom AI: build a portfolio, including advanced analytics and governed agentic AI.
B39: Data Position LOW (< 50%) | C39: A. Automation is enough - for now Digitise and automate first; use AI that is already built into everyday tools. | D39: B. Data foundations first Scale is there but the data is not: fix data foundations while automating and adopting off-the-shelf AI.
C40: Scale & Capacity LOW (< 50%) | D40: Scale & Capacity HIGH (>= 50%)

Sheet 2. Use-Case Library
A1: 2. GT AI Use-Case Library (240 entries)
A2: Cross-industry (APQC functions) and sector-specific AI and automation use cases with GT recommendations, data needs, KPIs, regulatory notes and a minimum risk tier. Select entries in the AI Fit Diagnostic; the dropdown there shows cross-industry + the sector chosen on sheet 1.
A4: ID | B4: Sector | C4: Function (APQC) | D4: Process / use case | E4: Typical pain point | F4: Nature of the task | G4: Solution family | H4: GT recommendation | I4: Data needed | J4: KPIs | K4: Regulatory & risk notes | L4: Min. risk
A5: XI-01 | B5: Cross-industry | C5: Finance & accounting | D5: Supplier invoice capture & posting | E5: Invoices keyed manually from PDF / email into the ERP | F5: Extract information from documents, forms or emails | G5: Intelligent document processing (IDP) | H5: Capture invoices with intelligent document processing, validate against PO and vendor master, post automatically; route exceptions to AP. | I5: Invoice PDFs / scans, vendor master, purchase orders | J5: Touchless invoice rate; cost per invoice; posting cycle time | K5: Segregation of duties in approval; vendor bank-detail change controls (payment fraud). | L5: Low | M5: XI-01 | Supplier invoice capture & posting | N5: =OR('1. AI Position'!$C$5="",'1. AI Position'!$C$5="Other",B5="Cross-industry",B5='1. AI Position'!$C$5) -> TRUE | O5: =IF(N5,COUNTIF($N$5:N5,TRUE),"") -> 1
A6: XI-02 | B6: Cross-industry | C6: Finance & accounting | D6: Three-way match & payment approval | E6: PO, goods receipt and invoice checked by hand | F6: Check or approve items against fixed criteria (rules, thresholds, checklists) | G6: Rules engine / workflow automation | H6: Configure tolerance-based three-way matching in the ERP workflow; auto-approve within tolerance and escalate exceptions. | I6: POs, goods receipts, invoices | J6: Auto-match rate; late-payment penalties; exceptions per 100 invoices | K6: Approval limits and SoD must be enforced in the workflow. | L6: Low | M6: XI-02 | Three-way match & payment approval | N6: =OR('1. AI Position'!$C$5="",'1. AI Position'!$C$5="Other",B6="Cross-industry",B6='1. AI Position'!$C$5) -> TRUE | O6: =IF(N6,COUNTIF($N$5:N6,TRUE),"") -> 2
A7: XI-03 | B7: Cross-industry | C7: Finance & accounting | D7: Bank reconciliations | E7: Spreadsheet matching every month | F7: Produce reports, dashboards or reconciliations from existing data | G7: BI, dashboards & reconciliation automation | H7: Deploy a reconciliation tool with rule-based auto-matching; add ML-assisted fuzzy matching only once rules are exhausted. | I7: Bank statements (MT940 / CSV), GL cash entries | J7: Auto-match %; days to reconcile; unreconciled items ageing | K7: Reviewer sign-off retained; audit trail of matches. | L7: Low | M7: XI-03 | Bank reconciliations | N7: =OR('1. AI Position'!$C$5="",'1. AI Position'!$C$5="Other",B7="Cross-industry",B7='1. AI Position'!$C$5) -> TRUE | O7: =IF(N7,COUNTIF($N$5:N7,TRUE),"") -> 3
A8: XI-04 | B8: Cross-industry | C8: Finance & accounting | D8: Intercompany reconciliation & eliminations | E8: Late intercompany agreements delay the close | F8: Produce reports, dashboards or reconciliations from existing data | G8: BI, dashboards & reconciliation automation | H8: Standardise intercompany coding, automate matching and elimination journals in the consolidation tool. | I8: Intercompany ledgers, entity mapping | J8: Intercompany differences at close; close days | K8: - | L8: Low | M8: XI-04 | Intercompany reconciliation & eliminations | N8: =OR('1. AI Position'!$C$5="",'1. AI Position'!$C$5="Other",B8="Cross-industry",B8='1. AI Position'!$C$5) -> TRUE | O8: =IF(N8,COUNTIF($N$5:N8,TRUE),"") -> 4
A9: XI-05 | B9: Cross-industry | C9: Finance & accounting | D9: Month-end close & management packs | E9: Manual report packs delivered late | F9: Produce reports, dashboards or reconciliations from existing data | G9: BI, dashboards & reconciliation automation | H9: Close-checklist workflow plus automated report packs (e.g., Power BI); GenAI drafts variance commentary for finance review. | I9: GL, budgets, KPI definitions | J9: Close days; report delivery date; manual adjustments | K9: GenAI commentary reviewed before release; no confidential data in public tools. | L9: Low | M9: XI-05 | Month-end close & management packs | N9: =OR('1. AI Position'!$C$5="",'1. AI Position'!$C$5="Other",B9="Cross-industry",B9='1. AI Position'!$C$5) -> TRUE | O9: =IF(N9,COUNTIF($N$5:N9,TRUE),"") -> 5
A10: XI-06 | B10: Cross-industry | C10: Finance & accounting | D10: Cash-flow forecasting | E10: Spreadsheet forecasts with poor accuracy | F10: Forecast, score, classify or detect anomalies from historical data | G10: Predictive analytics / machine learning | H10: Driver-based ML forecast using AR / AP history and seasonality; run in parallel with the manual forecast for three cycles before relying on it. | I10: 2-3 years of AR / AP, bank and payroll history | J10: Forecast accuracy (MAPE); idle cash; borrowing cost | K10: Model owner and back-testing documented. | L10: Low | M10: XI-06 | Cash-flow forecasting | N10: =OR('1. AI Position'!$C$5="",'1. AI Position'!$C$5="Other",B10="Cross-industry",B10='1. AI Position'!$C$5) -> TRUE | O10: =IF(N10,COUNTIF($N$5:N10,TRUE),"") -> 6
A11: XI-07 | B11: Cross-industry | C11: Finance & accounting | D11: Collections & dunning | E11: Overdue invoices chased manually | F11: Move or re-key data between systems following fixed rules | G11: Workflow automation / RPA | H11: Automated dunning workflow with reminders by email / WhatsApp and promise-to-pay tracking; add payment-propensity scoring once history allows. | I11: AR ledger, customer contacts, payment history | J11: DSO; overdue %; collector productivity | K11: Fair-treatment and contact-time rules; customer consent for WhatsApp. | L11: Low | M11: XI-07 | Collections & dunning | N11: =OR('1. AI Position'!$C$5="",'1. AI Position'!$C$5="Other",B11="Cross-industry",B11='1. AI Position'!$C$5) -> TRUE | O11: =IF(N11,COUNTIF($N$5:N11,TRUE),"") -> 7
A12: XI-08 | B12: Cross-industry | C12: Finance & accounting | D12: VAT return preparation | E12: Collating transactions and VAT codes by hand | F12: Move or re-key data between systems following fixed rules | G12: Workflow automation / RPA | H12: Automate extraction and validation of VAT-coded transactions and populate the NBR VAT return template; reviewer sign-off before filing. | I12: Sales / purchase ledgers, VAT codes | J12: Preparation hours; filing errors; penalties | K12: NBR VAT law compliance; maker-checker on filing. | L12: Low | M12: XI-08 | VAT return preparation | N12: =OR('1. AI Position'!$C$5="",'1. AI Position'!$C$5="Other",B12="Cross-industry",B12='1. AI Position'!$C$5) -> TRUE | O12: =IF(N12,COUNTIF($N$5:N12,TRUE),"") -> 8
A13: XI-09 | B13: Cross-industry | C13: Finance & accounting | D13: Expense claims audit | E13: Receipts checked manually against policy | F13: Extract information from documents, forms or emails | G13: Intelligent document processing (IDP) | H13: Receipt capture with IDP, a rules engine for policy checks and duplicate / anomaly flags for review. | I13: Receipts, expense policy, card feeds | J13: Claims processed per FTE; policy breaches detected; reimbursement time | K13: Employee data - PDPL; transparent policy rules. | L13: Low | M13: XI-09 | Expense claims audit | N13: =OR('1. AI Position'!$C$5="",'1. AI Position'!$C$5="Other",B13="Cross-industry",B13='1. AI Position'!$C$5) -> TRUE | O13: =IF(N13,COUNTIF($N$5:N13,TRUE),"") -> 9
A14: XI-10 | B14: Cross-industry | C14: Finance & accounting | D14: Financial statements & disclosure drafting | E14: Mapping trial balances and drafting notes manually | F14: Draft, summarise, translate or review text | G14: Generative AI assistant (off-the-shelf) | H14: Rules-based TB-to-line mapping with AI suggestions; GenAI drafts notes from approved templates; qualified accountant review and sign-off. | I14: Trial balance, prior-year FS, IFRS disclosure checklist | J14: Preparation hours; review points; restatements | K14: IFRS compliance; professional review mandatory; IESBA independence where an auditor provides it (GT AI FS tool - in preparation). | L14: Medium | M14: XI-10 | Financial statements & disclosure drafting | N14: =OR('1. AI Position'!$C$5="",'1. AI Position'!$C$5="Other",B14="Cross-industry",B14='1. AI Position'!$C$5) -> TRUE | O14: =IF(N14,COUNTIF($N$5:N14,TRUE),"") -> 10
A15: XI-11 | B15: Cross-industry | C15: Finance & accounting | D15: Budget narratives & variance commentary | E15: Commentary written from scratch each month | F15: Draft, summarise, translate or review text | G15: Generative AI assistant (off-the-shelf) | H15: GenAI drafts budget and variance commentary from approved KPI tables; finance edits and approves. | I15: Budget vs actuals, KPI definitions | J15: Hours per pack; timeliness | K15: Confidential financials only in approved enterprise tools. | L15: Low | M15: XI-11 | Budget narratives & variance commentary | N15: =OR('1. AI Position'!$C$5="",'1. AI Position'!$C$5="Other",B15="Cross-industry",B15='1. AI Position'!$C$5) -> TRUE | O15: =IF(N15,COUNTIF($N$5:N15,TRUE),"") -> 11
A16: XI-12 | B16: Cross-industry | C16: Finance & accounting | D16: Fixed-asset register & depreciation | E16: Asset additions and disposals updated manually | F16: Move or re-key data between systems following fixed rules | G16: Workflow automation / RPA | H16: Automate asset creation from capex POs and depreciation runs; dashboard for physical-verification exceptions. | I16: Capex POs, asset register | J16: Register accuracy; close hours | K16: - | L16: Low | M16: XI-12 | Fixed-asset register & depreciation | N16: =OR('1. AI Position'!$C$5="",'1. AI Position'!$C$5="Other",B16="Cross-industry",B16='1. AI Position'!$C$5) -> TRUE | O16: =IF(N16,COUNTIF($N$5:N16,TRUE),"") -> 12
... A244: PRO-15 | B244: Professional services | C244: Knowledge & collaboration | D244: Methodology & knowledge Q&A | E244: Staff search across manuals and past work | F244: Answer questions from internal knowledge, policies or past work | G244: GenAI knowledge assistant (RAG on own content) | H244: Grounded assistant over firm methodologies and sanitised precedents. | I244: Methodologies, sanitised precedents | J244: Search time; reuse | K244: Client confidentiality in precedents. | L244: Low | M244: PRO-15 | Methodology & knowledge Q&A | N244: =OR('1. AI Position'!$C$5="",'1. AI Position'!$C$5="Other",B244="Cross-industry",B244='1. AI Position'!$C$5) -> TRUE | O244: =IF(N244,COUNTIF($N$5:N244,TRUE),"") -> 75

Sheet 3. AI Fit Diagnostic
A1: 3. AI Fit Diagnostic - process by process
A2: Select a use case from the library (column B; type a custom process if it is not in the library, then select its task nature and function in D-E) and answer the yellow inputs F-N. Effort = staff hours spent on the process per month (all people involved).
B3: Organisation's AI position (from sheet 1): | C3: ='1. AI Position'!$C$31 -> Buy and configure AI | F3: Solution ceiling level: | I3: =IF('1. AI Position'!$C$30="",5,INDEX(Lists!$AI$2:$AI$5,'1. AI Position'!$C$30)) -> 4
B4: Quadrant threshold (value and feasibility, 1-5): | C4: 3.25 | D4: ="Library entries offered: "&COUNTIF(Lists!$BA$2:$BA$241,"?*") -> Library entries offered: 75
A6: INPUTS (yellow) | O6: AUTO-CALCULATED (recommendation and notes come from the GT AI Use-Case Library)
A7: # | B7: Use case (select from library, or type a custom process) | C7: Client-specific note (optional) | D7: Task nature - custom entries / override | E7: Function - custom entries only | F7: Volume | G7: Effort (hrs / month) | H7: Process standardised? | I7: Data available for this process | J7: Strategic importance (1-5) | K7: Customer / quality impact (1-5) | L7: Affects individuals' rights or access? | M7: Personal or confidential data? | N7: Intended autonomy | O7: Library ID | P7: Function | Q7: Nature of the task | R7: Solution family | S7: Level | T7: AI? | U7: Data gate | V7: Organisational fit | W7: VERDICT | X7: Value | Y7: Feasib-ility | Z7: Risk tier | AA7: Quadrant | AB7: Priority score | AC7: Rank | AD7: Horizon | AE7: Est. hours released / yr | AF7: GT recommendation (library) | AG7: Regulatory & risk notes (library) | AH7: h | AI7: key | AJ7: name
A8: 1 | B8: PRO-01 | Audit - journal-entry testing (full population) | F8: High (more than 1,000 a month) | G8: 300 | H8: Partly - common steps, some variation | I8: Digital history available | J8: 5 | K8: 5 | L8: No | M8: Yes | N8: Human approves each AI output | O8: =IF(B8="","",IFERROR(INDEX('2. Use-Case Library'!$A$5:$A$244,MATCH(B8,'2. Use-Case Library'!$M$5:$M$244,0)),"Custom")) -> PRO-01 | P8: =IF(B8="","",IF(O8="Custom",IF(E8="","(select function in E)",E8),INDEX('2. Use-Case Library'!$C$5:$C$244,MATCH($O8,'2. Use-Case Library'!$A$5:$A$244,0)))) -> Core operations & service delivery | Q8: =IF(B8="","",IF(D8<>"",D8,IF(O8="Custom","",INDEX('2. Use-Case Library'!$F$5:$F$244,MATCH($O8,'2. Use-Case Library'!$A$5:$A$244,0))))) -> Forecast, score, classify or detect anomalies from historical data | R8: =IF(Q8="","",INDEX(Lists!$B$2:$B$11,MATCH(Q8,Lists!$A$2:$A$11,0))) -> Predictive analytics / machine learning | S8: =IF(R8="","",INDEX(Lists!$C$2:$C$11,MATCH(R8,Lists!$B$2:$B$11,0))) -> 5 | T8: =IF(R8="","",INDEX(Lists!$D$2:$D$11,MATCH(R8,Lists!$B$2:$B$11,0))) -> Yes | U8: =IF(OR(R8="",I8=""),"",IF(INDEX(Lists!$N$2:$N$5,MATCH(I8,Lists!$M$2:$M$5,0))>=INDEX(Lists!$E$2:$E$11,MATCH(R8,Lists!$B$2:$B$11,0)),"Data ready","Data gap")) -> Data ready | V8: =IF(R8="","",IF(S8<=IF('1. AI Position'!$C$30="",5,INDEX(Lists!$AI$2:$AI$5,'1. AI Position'!$C$30)),"Within current position","Beyond current position")) -> Beyond current position | W8: =IF(B8="","",IF(OR(COUNTA(F8:N8)<9,Q8=""),"Complete inputs",IF(H8="No - varies by person / team","Redesign / standardise first",IF(T8="No","Automate - AI not needed",IF(U8="Data gap","AI later - close data gap first",IF(V8="Beyond current position","Stretch - partner or later stage","AI fit now")))))) -> Stretch - partner or later stage | X8: =IF(OR(W8="",W8="Complete inputs"),"",ROUND(0.3*INDEX(Lists!$N$8:$N$10,MATCH(F8,Lists!$M$8:$M$10,0))+0.25*IF(G8<20,1,IF(G8<80,2,IF(G8<160,3,IF(G8<480,4,5))))+0.25*J8+0.2*K8,2)) -> 4.75 | Y8: =IF(X8="","",ROUND(0.3*IF(U8="Data ready",5,IF(INDEX(Lists!$N$2:$N$5,MATCH(I8,Lists!$M$2:$M$5,0))=INDEX(Lists!$E$2:$E$11,MATCH(R8,Lists!$B$2:$B$11,0))-1,3,1))+0.25*INDEX(Lists!$N$13:$N$15,MATCH(H8,Lists!$M$13:$M$15,0))+0.25*(6-S8)+0.2*IF(V8="Within current position",5,2),2)) -> 2.9 | Z8: =IF(X8="","",CHOOSE(MAX(IF(T8="No",IF(L8="Yes",2,1),IF(IF(L8="Yes",2,0)+IF(M8="Yes",1,0)+INDEX(Lists!$N$18:$N$20,MATCH(N8,Lists!$M$18:$M$20,0))+IF(K8=5,2,IF(K8>=4,1,0))>=4,3,IF(IF(L8="Yes",2,0)+IF(M8="Yes",1,0)+INDEX(Lists!$N$18:$N$20,MATCH(N8,Lists!$M$18:$M$20,0))+IF(K8=5,2,IF(K8>=4,1,0))>=2,2,1))),IF($O8="Custom",1,MATCH(INDEX('2. Use-Case Library'!$L$5:$L$244,MATCH($O8,'2. Use-Case Library'!$A$5:$A$244,0)),{"Low","Medium","High"},0))),"Low","Medium","High")) -> High | AA8: =IF(X8="","",IF(AND(X8>=$C$4,Y8>=$C$4),"Quick win",IF(X8>=$C$4,"Strategic bet",IF(Y8>=$C$4,"Fill-in","Deprioritise")))) -> Strategic bet | AB8: =IF(X8="","",ROUND(X8*Y8*IF(Z8="High",0.85,1)*IF(W8="Redesign / standardise first",0.8,1),2)) -> 11.71 | AC8: =IF(AB8="","",RANK(AB8,$AB$8:$AB$57)+COUNTIF($AB$7:AB7,AB8)) -> 15 | AD8: =IF(AH8="","",INDEX(Lists!$AV$2:$AV$5,AH8)) -> H2 - Next (6-12 months) | AE8: =IF(AB8="","",ROUND(G8*12*INDEX(Lists!$F$2:$F$11,MATCH(R8,Lists!$B$2:$B$11,0)),0)) -> 720 | AF8: =IF(OR(B8="",R8=""),"",IF(O8="Custom",INDEX(Lists!$I$2:$I$11,MATCH(R8,Lists!$B$2:$B$11,0)),INDEX('2. Use-Case Library'!$H$5:$H$244,MATCH($O8,'2. Use-Case Library'!$A$5:$A$244,0)))) -> Full-population JE analytics with rules and ML anomaly scoring; auditor investigates and concludes. | AG8: =IF(OR(B8="",O8="Custom"),"",INDEX('2. Use-Case Library'!$K$5:$K$244,MATCH($O8,'2. Use-Case Library'!$A$5:$A$244,0))) -> ISA 240 / 330; documentation in working papers; client-data confidentiality. | AH8: =IF(AB8="","",IF(AA8="Deprioritise",4,IF(W8="AI later - close data gap first",3,IF(OR(W8="Redesign / standardise first",W8="Stretch - partner or later stage",AA8="Strategic bet",Z8="High",S8=5),2,1)))) -> 2 | AI8: =IF(AC8="","",AH8*100+AC8) -> 215 | AJ8: =IF(B8="","",IF(O8="Custom",B8,INDEX('2. Use-Case Library'!$D$5:$D$244,MATCH($O8,'2. Use-Case Library'!$A$5:$A$244,0)))) -> Audit - journal-entry testing (full population)
A9: 2 | B9: PRO-02 | Audit - working papers & memo drafting | F9: Medium (100 - 1,000 a month) | G9: 400 | H9: Yes - documented and consistent | I9: Digital history available | J9: 4 | K9: 4 | L9: No | M9: Yes | N9: Human approves each AI output | O9: =IF(B9="","",IFERROR(INDEX('2. Use-Case Library'!$A$5:$A$244,MATCH(B9,'2. Use-Case Library'!$M$5:$M$244,0)),"Custom")) -> PRO-02 | P9: =IF(B9="","",IF(O9="Custom",IF(E9="","(select function in E)",E9),INDEX('2. Use-Case Library'!$C$5:$C$244,MATCH($O9,'2. Use-Case Library'!$A$5:$A$244,0)))) -> Core operations & service delivery | Q9: =IF(B9="","",IF(D9<>"",D9,IF(O9="Custom","",INDEX('2. Use-Case Library'!$F$5:$F$244,MATCH($O9,'2. Use-Case Library'!$A$5:$A$244,0))))) -> Draft, summarise, translate or review text | R9: =IF(Q9="","",INDEX(Lists!$B$2:$B$11,MATCH(Q9,Lists!$A$2:$A$11,0))) -> Generative AI assistant (off-the-shelf) | S9: =IF(R9="","",INDEX(Lists!$C$2:$C$11,MATCH(R9,Lists!$B$2:$B$11,0))) -> 3 | T9: =IF(R9="","",INDEX(Lists!$D$2:$D$11,MATCH(R9,Lists!$B$2:$B$11,0))) -> Yes | U9: =IF(OR(R9="",I9=""),"",IF(INDEX(Lists!$N$2:$N$5,MATCH(I9,Lists!$M$2:$M$5,0))>=INDEX(Lists!$E$2:$E$11,MATCH(R9,Lists!$B$2:$B$11,0)),"Data ready","Data gap")) -> Data ready | V9: =IF(R9="","",IF(S9<=IF('1. AI Position'!$C$30="",5,INDEX(Lists!$AI$2:$AI$5,'1. AI Position'!$C$30)),"Within current position","Beyond current position")) -> Within current position | W9: =IF(B9="","",IF(OR(COUNTA(F9:N9)<9,Q9=""),"Complete inputs",IF(H9="No - varies by person / team","Redesign / standardise first",IF(T9="No","Automate - AI not needed",IF(U9="Data gap","AI later - close data gap first",IF(V9="Beyond current position","Stretch - partner or later stage","AI fit now")))))) -> AI fit now | X9: =IF(OR(W9="",W9="Complete inputs"),"",ROUND(0.3*INDEX(Lists!$N$8:$N$10,MATCH(F9,Lists!$M$8:$M$10,0))+0.25*IF(G9<20,1,IF(G9<80,2,IF(G9<160,3,IF(G9<480,4,5))))+0.25*J9+0.2*K9,2)) -> 3.7 | Y9: =IF(X9="","",ROUND(0.3*IF(U9="Data ready",5,IF(INDEX(Lists!$N$2:$N$5,MATCH(I9,Lists!$M$2:$M$5,0))=INDEX(Lists!$E$2:$E$11,MATCH(R9,Lists!$B$2:$B$11,0))-1,3,1))+0.25*INDEX(Lists!$N$13:$N$15,MATCH(H9,Lists!$M$13:$M$15,0))+0.25*(6-S9)+0.2*IF(V9="Within current position",5,2),2)) -> 4.5 | Z9: =IF(X9="","",CHOOSE(MAX(IF(T9="No",IF(L9="Yes",2,1),IF(IF(L9="Yes",2,0)+IF(M9="Yes",1,0)+INDEX(Lists!$N$18:$N$20,MATCH(N9,Lists!$M$18:$M$20,0))+IF(K9=5,2,IF(K9>=4,1,0))>=4,3,IF(IF(L9="Yes",2,0)+IF(M9="Yes",1,0)+INDEX(Lists!$N$18:$N$20,MATCH(N9,Lists!$M$18:$M$20,0))+IF(K9=5,2,IF(K9>=4,1,0))>=2,2,1))),IF($O9="Custom",1,MATCH(INDEX('2. Use-Case Library'!$L$5:$L$244,MATCH($O9,'2. Use-Case Library'!$A$5:$A$244,0)),{"Low","Medium","High"},0))),"Low","Medium","High")) -> Medium | AA9: =IF(X9="","",IF(AND(X9>=$C$4,Y9>=$C$4),"Quick win",IF(X9>=$C$4,"Strategic bet",IF(Y9>=$C$4,"Fill-in","Deprioritise")))) -> Quick win | AB9: =IF(X9="","",ROUND(X9*Y9*IF(Z9="High",0.85,1)*IF(W9="Redesign / standardise first",0.8,1),2)) -> 16.65 | AC9: =IF(AB9="","",RANK(AB9,$AB$8:$AB$57)+COUNTIF($AB$7:AB8,AB9)) -> 4 | AD9: =IF(AH9="","",INDEX(Lists!$AV$2:$AV$5,AH9)) -> H1 - Now (0-6 months) | AE9: =IF(AB9="","",ROUND(G9*12*INDEX(Lists!$F$2:$F$11,MATCH(R9,Lists!$B$2:$B$11,0)),0)) -> 1440 | AF9: =IF(OR(B9="",R9=""),"",IF(O9="Custom",INDEX(Lists!$I$2:$I$11,MATCH(R9,Lists!$B$2:$B$11,0)),INDEX('2. Use-Case Library'!$H$5:$H$244,MATCH($O9,'2. Use-Case Library'!$A$5:$A$244,0)))) -> GenAI drafting within methodology templates in an approved environment; reviewer sign-off. | AG9: =IF(OR(B9="",O9="Custom"),"",INDEX('2. Use-Case Library'!$K$5:$K$244,MATCH($O9,'2. Use-Case Library'!$A$5:$A$244,0))) -> ISQM 1; human review; client confidentiality. | AH9: =IF(AB9="","",IF(AA9="Deprioritise",4,IF(W9="AI later - close data gap first",3,IF(OR(W9="Redesign / standardise first",W9="Stretch - partner or later stage",AA9="Strategic bet",Z9="High",S9=5),2,1)))) -> 1 | AI9: =IF(AC9="","",AH9*100+AC9) -> 104 | AJ9: =IF(B9="","",IF(O9="Custom",B9,INDEX('2. Use-Case Library'!$D$5:$D$244,MATCH($O9,'2. Use-Case Library'!$A$5:$A$244,0)))) -> Audit - working papers & memo drafting
A10: 3 | B10: PRO-03 | Audit - bank & external confirmations | F10: High (more than 1,000 a month) | G10: 120 | H10: Yes - documented and consistent | I10: Digital history available | J10: 3 | K10: 3 | L10: No | M10: Yes | N10: Human approves each AI output | O10: =IF(B10="","",IFERROR(INDEX('2. Use-Case Library'!$A$5:$A$244,MATCH(B10,'2. Use-Case Library'!$M$5:$M$244,0)),"Custom")) -> PRO-03 | P10: =IF(B10="","",IF(O10="Custom",IF(E10="","(select function in E)",E10),INDEX('2. Use-Case Library'!$C$5:$C$244,MATCH($O10,'2. Use-Case Library'!$A$5:$A$244,0)))) -> Core operations & service delivery | Q10: =IF(B10="","",IF(D10<>"",D10,IF(O10="Custom","",INDEX('2. Use-Case Library'!$F$5:$F$244,MATCH($O10,'2. Use-Case Library'!$A$5:$A$244,0))))) -> Extract information from documents, forms or emails | R10: =IF(Q10="","",INDEX(Lists!$B$2:$B$11,MATCH(Q10,Lists!$A$2:$A$11,0))) -> Intelligent document processing (IDP) | S10: =IF(R10="","",INDEX(Lists!$C$2:$C$11,MATCH(R10,Lists!$B$2:$B$11,0))) -> 3 | T10: =IF(R10="","",INDEX(Lists!$D$2:$D$11,MATCH(R10,Lists!$B$2:$B$11,0))) -> Light | U10: =IF(OR(R10="",I10=""),"",IF(INDEX(Lists!$N$2:$N$5,MATCH(I10,Lists!$M$2:$M$5,0))>=INDEX(Lists!$E$2:$E$11,MATCH(R10,Lists!$B$2:$B$11,0)),"Data ready","Data gap")) -> Data ready | V10: =IF(R10="","",IF(S10<=IF('1. AI Position'!$C$30="",5,INDEX(Lists!$AI$2:$AI$5,'1. AI Position'!$C$30)),"Within current position","Beyond current position")) -> Within current position | W10: =IF(B10="","",IF(OR(COUNTA(F10:N10)<9,Q10=""),"Complete inputs",IF(H10="No - varies by person / team","Redesign / standardise first",IF(T10="No","Automate - AI not needed",IF(U10="Data gap","AI later - close data gap first",IF(V10="Beyond current position","Stretch - partner or later stage","AI fit now")))))) -> AI fit now | X10: =IF(OR(W10="",W10="Complete inputs"),"",ROUND(0.3*INDEX(Lists!$N$8:$N$10,MATCH(F10,Lists!$M$8:$M$10,0))+0.25*IF(G10<20,1,IF(G10<80,2,IF(G10<160,3,IF(G10<480,4,5))))+0.25*J10+0.2*K10,2)) -> 3.6 | Y10: =IF(X10="","",ROUND(0.3*IF(U10="Data ready",5,IF(INDEX(Lists!$N$2:$N$5,MATCH(I10,Lists!$M$2:$M$5,0))=INDEX(Lists!$E$2:$E$11,MATCH(R10,Lists!$B$2:$B$11,0))-1,3,1))+0.25*INDEX(Lists!$N$13:$N$15,MATCH(H10,Lists!$M$13:$M$15,0))+0.25*(6-S10)+0.2*IF(V10="Within current position",5,2),2)) -> 4.5 | Z10: =IF(X10="","",CHOOSE(MAX(IF(T10="No",IF(L10="Yes",2,1),IF(IF(L10="Yes",2,0)+IF(M10="Yes",1,0)+INDEX(Lists!$N$18:$N$20,MATCH(N10,Lists!$M$18:$M$20,0))+IF(K10=5,2,IF(K10>=4,1,0))>=4,3,IF(IF(L10="Yes",2,0)+IF(M10="Yes",1,0)+INDEX(Lists!$N$18:$N$20,MATCH(N10,Lists!$M$18:$M$20,0))+IF(K10=5,2,IF(K10>=4,1,0))>=2,2,1))),IF($O10="Custom",1,MATCH(INDEX('2. Use-Case Library'!$L$5:$L$244,MATCH($O10,'2. Use-Case Library'!$A$5:$A$244,0)),{"Low","Medium","High"},0))),"Low","Medium","High")) -> Medium | AA10: =IF(X10="","",IF(AND(X10>=$C$4,Y10>=$C$4),"Quick win",IF(X10>=$C$4,"Strategic bet",IF(Y10>=$C$4,"Fill-in","Deprioritise")))) -> Quick win | AB10: =IF(X10="","",ROUND(X10*Y10*IF(Z10="High",0.85,1)*IF(W10="Redesign / standardise first",0.8,1),2)) -> 16.2 | AC10: =IF(AB10="","",RANK(AB10,$AB$8:$AB$57)+COUNTIF($AB$7:AB9,AB10)) -> 6 | AD10: =IF(AH10="","",INDEX(Lists!$AV$2:$AV$5,AH10)) -> H1 - Now (0-6 months) | AE10: =IF(AB10="","",ROUND(G10*12*INDEX(Lists!$F$2:$F$11,MATCH(R10,Lists!$B$2:$B$11,0)),0)) -> 720 | AF10: =IF(OR(B10="",R10=""),"",IF(O10="Custom",INDEX(Lists!$I$2:$I$11,MATCH(R10,Lists!$B$2:$B$11,0)),INDEX('2. Use-Case Library'!$H$5:$H$244,MATCH($O10,'2. Use-Case Library'!$A$5:$A$244,0)))) -> IDP of confirmation responses with automatic agreement to records. | AG10: =IF(OR(B10="",O10="Custom"),"",INDEX('2. Use-Case Library'!$K$5:$K$244,MATCH($O10,'2. Use-Case Library'!$A$5:$A$244,0))) -> ISA 505 evidence requirements. | AH10: =IF(AB10="","",IF(AA10="Deprioritise",4,IF(W10="AI later - close data gap first",3,IF(OR(W10="Redesign / standardise first",W10="Stretch - partner or later stage",AA10="Strategic bet",Z10="High",S10=5),2,1)))) -> 1 | AI10: =IF(AC10="","",AH10*100+AC10) -> 106 | AJ10: =IF(B10="","",IF(O10="Custom",B10,INDEX('2. Use-Case Library'!$D$5:$D$244,MATCH($O10,'2. Use-Case Library'!$A$5:$A$244,0)))) -> Audit - bank & external confirmations
A11: 4 | B11: PRO-04 | Tax research & technical Q&A | F11: Medium (100 - 1,000 a month) | G11: 160 | H11: Partly - common steps, some variation | I11: Digital history available | J11: 4 | K11: 4 | L11: No | M11: No | N11: Assist - AI suggests, a person does the work | O11: =IF(B11="","",IFERROR(INDEX('2. Use-Case Library'!$A$5:$A$244,MATCH(B11,'2. Use-Case Library'!$M$5:$M$244,0)),"Custom")) -> PRO-04 | P11: =IF(B11="","",IF(O11="Custom",IF(E11="","(select function in E)",E11),INDEX('2. Use-Case Library'!$C$5:$C$244,MATCH($O11,'2. Use-Case Library'!$A$5:$A$244,0)))) -> Core operations & service delivery | Q11: =IF(B11="","",IF(D11<>"",D11,IF(O11="Custom","",INDEX('2. Use-Case Library'!$F$5:$F$244,MATCH($O11,'2. Use-Case Library'!$A$5:$A$244,0))))) -> Answer questions from internal knowledge, policies or past work | R11: =IF(Q11="","",INDEX(Lists!$B$2:$B$11,MATCH(Q11,Lists!$A$2:$A$11,0))) -> GenAI knowledge assistant (RAG on own content) | S11: =IF(R11="","",INDEX(Lists!$C$2:$C$11,MATCH(R11,Lists!$B$2:$B$11,0))) -> 4 | T11: =IF(R11="","",INDEX(Lists!$D$2:$D$11,MATCH(R11,Lists!$B$2:$B$11,0))) -> Yes | U11: =IF(OR(R11="",I11=""),"",IF(INDEX(Lists!$N$2:$N$5,MATCH(I11,Lists!$M$2:$M$5,0))>=INDEX(Lists!$E$2:$E$11,MATCH(R11,Lists!$B$2:$B$11,0)),"Data ready","Data gap")) -> Data ready | V11: =IF(R11="","",IF(S11<=IF('1. AI Position'!$C$30="",5,INDEX(Lists!$AI$2:$AI$5,'1. AI Position'!$C$30)),"Within current position","Beyond current position")) -> Within current position | W11: =IF(B11="","",IF(OR(COUNTA(F11:N11)<9,Q11=""),"Complete inputs",IF(H11="No - varies by person / team","Redesign / standardise first",IF(T11="No","Automate - AI not needed",IF(U11="Data gap","AI later - close data gap first",IF(V11="Beyond current position","Stretch - partner or later stage","AI fit now")))))) -> AI fit now | X11: =IF(OR(W11="",W11="Complete inputs"),"",ROUND(0.3*INDEX(Lists!$N$8:$N$10,MATCH(F11,Lists!$M$8:$M$10,0))+0.25*IF(G11<20,1,IF(G11<80,2,IF(G11<160,3,IF(G11<480,4,5))))+0.25*J11+0.2*K11,2)) -> 3.7 | Y11: =IF(X11="","",ROUND(0.3*IF(U11="Data ready",5,IF(INDEX(Lists!$N$2:$N$5,MATCH(I11,Lists!$M$2:$M$5,0))=INDEX(Lists!$E$2:$E$11,MATCH(R11,Lists!$B$2:$B$11,0))-1,3,1))+0.25*INDEX(Lists!$N$13:$N$15,MATCH(H11,Lists!$M$13:$M$15,0))+0.25*(6-S11)+0.2*IF(V11="Within current position",5,2),2)) -> 3.75 | Z11: =IF(X11="","",CHOOSE(MAX(IF(T11="No",IF(L11="Yes",2,1),IF(IF(L11="Yes",2,0)+IF(M11="Yes",1,0)+INDEX(Lists!$N$18:$N$20,MATCH(N11,Lists!$M$18:$M$20,0))+IF(K11=5,2,IF(K11>=4,1,0))>=4,3,IF(IF(L11="Yes",2,0)+IF(M11="Yes",1,0)+INDEX(Lists!$N$18:$N$20,MATCH(N11,Lists!$M$18:$M$20,0))+IF(K11=5,2,IF(K11>=4,1,0))>=2,2,1))),IF($O11="Custom",1,MATCH(INDEX('2. Use-Case Library'!$L$5:$L$244,MATCH($O11,'2. Use-Case Library'!$A$5:$A$244,0)),{"Low","Medium","High"},0))),"Low","Medium","High")) -> Low | AA11: =IF(X11="","",IF(AND(X11>=$C$4,Y11>=$C$4),"Quick win",IF(X11>=$C$4,"Strategic bet",IF(Y11>=$C$4,"Fill-in","Deprioritise")))) -> Quick win | AB11: =IF(X11="","",ROUND(X11*Y11*IF(Z11="High",0.85,1)*IF(W11="Redesign / standardise first",0.8,1),2)) -> 13.88 | AC11: =IF(AB11="","",RANK(AB11,$AB$8:$AB$57)+COUNTIF($AB$7:AB10,AB11)) -> 9 | AD11: =IF(AH11="","",INDEX(Lists!$AV$2:$AV$5,AH11)) -> H1 - Now (0-6 months) | AE11: =IF(AB11="","",ROUND(G11*12*INDEX(Lists!$F$2:$F$11,MATCH(R11,Lists!$B$2:$B$11,0)),0)) -> 480 | AF11: =IF(OR(B11="",R11=""),"",IF(O11="Custom",INDEX(Lists!$I$2:$I$11,MATCH(R11,Lists!$B$2:$B$11,0)),INDEX('2. Use-Case Library'!$H$5:$H$244,MATCH($O11,'2. Use-Case Library'!$A$5:$A$244,0)))) -> Grounded tax assistant over Bahrain / GCC tax law, NBR guidance and approved internal positions with citations. | AG11: =IF(OR(B11="",O11="Custom"),"",INDEX('2. Use-Case Library'!$K$5:$K$244,MATCH($O11,'2. Use-Case Library'!$A$5:$A$244,0))) -> Partner review of advice; verify citations. | AH11: =IF(AB11="","",IF(AA11="Deprioritise",4,IF(W11="AI later - close data gap first",3,IF(OR(W11="Redesign / standardise first",W11="Stretch - partner or later stage",AA11="Strategic bet",Z11="High",S11=5),2,1)))) -> 1 | AI11: =IF(AC11="","",AH11*100+AC11) -> 109 | AJ11: =IF(B11="","",IF(O11="Custom",B11,INDEX('2. Use-Case Library'!$D$5:$D$244,MATCH($O11,'2. Use-Case Library'!$A$5:$A$244,0)))) -> Tax research & technical Q&A
A12: 5 | B12: PRO-05 | Tax - VAT / tax return data preparation | F12: High (more than 1,000 a month) | G12: 200 | H12: Yes - documented and consistent | I12: Digital history available | J12: 3 | K12: 4 | L12: No | M12: Yes | N12: Human approves each AI output | O12: =IF(B12="","",IFERROR(INDEX('2. Use-Case Library'!$A$5:$A$244,MATCH(B12,'2. Use-Case Library'!$M$5:$M$244,0)),"Custom")) -> PRO-05 | P12: =IF(B12="","",IF(O12="Custom",IF(E12="","(select function in E)",E12),INDEX('2. Use-Case Library'!$C$5:$C$244,MATCH($O12,'2. Use-Case Library'!$A$5:$A$244,0)))) -> Core operations & service delivery | Q12: =IF(B12="","",IF(D12<>"",D12,IF(O12="Custom","",INDEX('2. Use-Case Library'!$F$5:$F$244,MATCH($O12,'2. Use-Case Library'!$A$5:$A$244,0))))) -> Move or re-key data between systems following fixed rules | R12: =IF(Q12="","",INDEX(Lists!$B$2:$B$11,MATCH(Q12,Lists!$A$2:$A$11,0))) -> Workflow automation / RPA | S12: =IF(R12="","",INDEX(Lists!$C$2:$C$11,MATCH(R12,Lists!$B$2:$B$11,0))) -> 2 | T12: =IF(R12="","",INDEX(Lists!$D$2:$D$11,MATCH(R12,Lists!$B$2:$B$11,0))) -> No | U12: =IF(OR(R12="",I12=""),"",IF(INDEX(Lists!$N$2:$N$5,MATCH(I12,Lists!$M$2:$M$5,0))>=INDEX(Lists!$E$2:$E$11,MATCH(R12,Lists!$B$2:$B$11,0)),"Data ready","Data gap")) -> Data ready | V12: =IF(R12="","",IF(S12<=IF('1. AI Position'!$C$30="",5,INDEX(Lists!$AI$2:$AI$5,'1. AI Position'!$C$30)),"Within current position","Beyond current position")) -> Within current position | W12: =IF(B12="","",IF(OR(COUNTA(F12:N12)<9,Q12=""),"Complete inputs",IF(H12="No - varies by person / team","Redesign / standardise first",IF(T12="No","Automate - AI not needed",IF(U12="Data gap","AI later - close data gap first",IF(V12="Beyond current position","Stretch - partner or later stage","AI fit now")))))) -> Automate - AI not needed | X12: =IF(OR(W12="",W12="Complete inputs"),"",ROUND(0.3*INDEX(Lists!$N$8:$N$10,MATCH(F12,Lists!$M$8:$M$10,0))+0.25*IF(G12<20,1,IF(G12<80,2,IF(G12<160,3,IF(G12<480,4,5))))+0.25*J12+0.2*K12,2)) -> 4.05 | Y12: =IF(X12="","",ROUND(0.3*IF(U12="Data ready",5,IF(INDEX(Lists!$N$2:$N$5,MATCH(I12,Lists!$M$2:$M$5,0))=INDEX(Lists!$E$2:$E$11,MATCH(R12,Lists!$B$2:$B$11,0))-1,3,1))+0.25*INDEX(Lists!$N$13:$N$15,MATCH(H12,Lists!$M$13:$M$15,0))+0.25*(6-S12)+0.2*IF(V12="Within current position",5,2),2)) -> 4.75 | Z12: =IF(X12="","",CHOOSE(MAX(IF(T12="No",IF(L12="Yes",2,1),IF(IF(L12="Yes",2,0)+IF(M12="Yes",1,0)+INDEX(Lists!$N$18:$N$20,MATCH(N12,Lists!$M$18:$M$20,0))+IF(K12=5,2,IF(K12>=4,1,0))>=4,3,IF(IF(L12="Yes",2,0)+IF(M12="Yes",1,0)+INDEX(Lists!$N$18:$N$20,MATCH(N12,Lists!$M$18:$M$20,0))+IF(K12=5,2,IF(K12>=4,1,0))>=2,2,1))),IF($O12="Custom",1,MATCH(INDEX('2. Use-Case Library'!$L$5:$L$244,MATCH($O12,'2. Use-Case Library'!$A$5:$A$244,0)),{"Low","Medium","High"},0))),"Low","Medium","High")) -> Low | AA12: =IF(X12="","",IF(AND(X12>=$C$4,Y12>=$C$4),"Quick win",IF(X12>=$C$4,"Strategic bet",IF(Y12>=$C$4,"Fill-in","Deprioritise")))) -> Quick win | AB12: =IF(X12="","",ROUND(X12*Y12*IF(Z12="High",0.85,1)*IF(W12="Redesign / standardise first",0.8,1),2)) -> 19.24 | AC12: =IF(AB12="","",RANK(AB12,$AB$8:$AB$57)+COUNTIF($AB$7:AB11,AB12)) -> 1 | AD12: =IF(AH12="","",INDEX(Lists!$AV$2:$AV$5,AH12)) -> H1 - Now (0-6 months) | AE12: =IF(AB12="","",ROUND(G12*12*INDEX(Lists!$F$2:$F$11,MATCH(R12,Lists!$B$2:$B$11,0)),0)) -> 1440 | AF12: =IF(OR(B12="",R12=""),"",IF(O12="Custom",INDEX(Lists!$I$2:$I$11,MATCH(R12,Lists!$B$2:$B$11,0)),INDEX('2. Use-Case Library'!$H$5:$H$244,MATCH($O12,'2. Use-Case Library'!$A$5:$A$244,0)))) -> Automated extraction, mapping and validation of client data into returns. | AG12: =IF(OR(B12="",O12="Custom"),"",INDEX('2. Use-Case Library'!$K$5:$K$244,MATCH($O12,'2. Use-Case Library'!$A$5:$A$244,0))) -> Maker-checker; client sign-off. | AH12: =IF(AB12="","",IF(AA12="Deprioritise",4,IF(W12="AI later - close data gap first",3,IF(OR(W12="Redesign / standardise first",W12="Stretch - partner or later stage",AA12="Strategic bet",Z12="High",S12=5),2,1)))) -> 1 | AI12: =IF(AC12="","",AH12*100+AC12) -> 101 | AJ12: =IF(B12="","",IF(O12="Custom",B12,INDEX('2. Use-Case Library'!$D$5:$D$244,MATCH($O12,'2. Use-Case Library'!$A$5:$A$244,0)))) -> Tax - VAT / tax return data preparation
A13: 6 | B13: PRO-06 | Predictive tax scenario modelling | F13: Low (fewer than 100 a month) | G13: 80 | H13: Partly - common steps, some variation | I13: Digital history available | J13: 4 | K13: 4 | L13: No | M13: Yes | N13: Assist - AI suggests, a person does the work | O13: =IF(B13="","",IFERROR(INDEX('2. Use-Case Library'!$A$5:$A$244,MATCH(B13,'2. Use-Case Library'!$M$5:$M$244,0)),"Custom")) -> PRO-06 | P13: =IF(B13="","",IF(O13="Custom",IF(E13="","(select function in E)",E13),INDEX('2. Use-Case Library'!$C$5:$C$244,MATCH($O13,'2. Use-Case Library'!$A$5:$A$244,0)))) -> Core operations & service delivery | Q13: =IF(B13="","",IF(D13<>"",D13,IF(O13="Custom","",INDEX('2. Use-Case Library'!$F$5:$F$244,MATCH($O13,'2. Use-Case Library'!$A$5:$A$244,0))))) -> Forecast, score, classify or detect anomalies from historical data | R13: =IF(Q13="","",INDEX(Lists!$B$2:$B$11,MATCH(Q13,Lists!$A$2:$A$11,0))) -> Predictive analytics / machine learning | S13: =IF(R13="","",INDEX(Lists!$C$2:$C$11,MATCH(R13,Lists!$B$2:$B$11,0))) -> 5 | T13: =IF(R13="","",INDEX(Lists!$D$2:$D$11,MATCH(R13,Lists!$B$2:$B$11,0))) -> Yes | U13: =IF(OR(R13="",I13=""),"",IF(INDEX(Lists!$N$2:$N$5,MATCH(I13,Lists!$M$2:$M$5,0))>=INDEX(Lists!$E$2:$E$11,MATCH(R13,Lists!$B$2:$B$11,0)),"Data ready","Data gap")) -> Data ready | V13: =IF(R13="","",IF(S13<=IF('1. AI Position'!$C$30="",5,INDEX(Lists!$AI$2:$AI$5,'1. AI Position'!$C$30)),"Within current position","Beyond current position")) -> Beyond current position | W13: =IF(B13="","",IF(OR(COUNTA(F13:N13)<9,Q13=""),"Complete inputs",IF(H13="No - varies by person / team","Redesign / standardise first",IF(T13="No","Automate - AI not needed",IF(U13="Data gap","AI later - close data gap first",IF(V13="Beyond current position","Stretch - partner or later stage","AI fit now")))))) -> Stretch - partner or later stage | X13: =IF(OR(W13="",W13="Complete inputs"),"",ROUND(0.3*INDEX(Lists!$N$8:$N$10,MATCH(F13,Lists!$M$8:$M$10,0))+0.25*IF(G13<20,1,IF(G13<80,2,IF(G13<160,3,IF(G13<480,4,5))))+0.25*J13+0.2*K13,2)) -> 2.85 | Y13: =IF(X13="","",ROUND(0.3*IF(U13="Data ready",5,IF(INDEX(Lists!$N$2:$N$5,MATCH(I13,Lists!$M$2:$M$5,0))=INDEX(Lists!$E$2:$E$11,MATCH(R13,Lists!$B$2:$B$11,0))-1,3,1))+0.25*INDEX(Lists!$N$13:$N$15,MATCH(H13,Lists!$M$13:$M$15,0))+0.25*(6-S13)+0.2*IF(V13="Within current position",5,2),2)) -> 2.9 | Z13: =IF(X13="","",CHOOSE(MAX(IF(T13="No",IF(L13="Yes",2,1),IF(IF(L13="Yes",2,0)+IF(M13="Yes",1,0)+INDEX(Lists!$N$18:$N$20,MATCH(N13,Lists!$M$18:$M$20,0))+IF(K13=5,2,IF(K13>=4,1,0))>=4,3,IF(IF(L13="Yes",2,0)+IF(M13="Yes",1,0)+INDEX(Lists!$N$18:$N$20,MATCH(N13,Lists!$M$18:$M$20,0))+IF(K13=5,2,IF(K13>=4,1,0))>=2,2,1))),IF($O13="Custom",1,MATCH(INDEX('2. Use-Case Library'!$L$5:$L$244,MATCH($O13,'2. Use-Case Library'!$A$5:$A$244,0)),{"Low","Medium","High"},0))),"Low","Medium","High")) -> Medium | AA13: =IF(X13="","",IF(AND(X13>=$C$4,Y13>=$C$4),"Quick win",IF(X13>=$C$4,"Strategic bet",IF(Y13>=$C$4,"Fill-in","Deprioritise")))) -> Deprioritise | AB13: =IF(X13="","",ROUND(X13*Y13*IF(Z13="High",0.85,1)*IF(W13="Redesign / standardise first",0.8,1),2)) -> 8.27 | AC13: =IF(AB13="","",RANK(AB13,$AB$8:$AB$57)+COUNTIF($AB$7:AB12,AB13)) -> 20 | AD13: =IF(AH13="","",INDEX(Lists!$AV$2:$AV$5,AH13)) -> Backlog / not prioritised | AE13: =IF(AB13="","",ROUND(G13*12*INDEX(Lists!$F$2:$F$11,MATCH(R13,Lists!$B$2:$B$11,0)),0)) -> 192 | AF13: =IF(OR(B13="",R13=""),"",IF(O13="Custom",INDEX(Lists!$I$2:$I$11,MATCH(R13,Lists!$B$2:$B$11,0)),INDEX('2. Use-Case Library'!$H$5:$H$244,MATCH($O13,'2. Use-Case Library'!$A$5:$A$244,0)))) -> Scenario models of tax outcomes for planning decisions (e.g., Pillar Two, CIT). | AG13: =IF(OR(B13="",O13="Custom"),"",INDEX('2. Use-Case Library'!$K$5:$K$244,MATCH($O13,'2. Use-Case Library'!$A$5:$A$244,0))) -> Assumptions documented; partner review. | AH13: =IF(AB13="","",IF(AA13="Deprioritise",4,IF(W13="AI later - close data gap first",3,IF(OR(W13="Redesign / standardise first",W13="Stretch - partner or later stage",AA13="Strategic bet",Z13="High",S13=5),2,1)))) -> 4 | AI13: =IF(AC13="","",AH13*100+AC13) -> 420 | AJ13: =IF(B13="","",IF(O13="Custom",B13,INDEX('2. Use-Case Library'!$D$5:$D$244,MATCH($O13,'2. Use-Case Library'!$A$5:$A$244,0)))) -> Predictive tax scenario modelling
A14: 7 | B14: XI-26 | Proposal, quotation & tender responses | F14: Medium (100 - 1,000 a month) | G14: 350 | H14: Partly - common steps, some variation | I14: Digital history available | J14: 4 | K14: 4 | L14: No | M14: No | N14: Assist - AI suggests, a person does the work | O14: =IF(B14="","",IFERROR(INDEX('2. Use-Case Library'!$A$5:$A$244,MATCH(B14,'2. Use-Case Library'!$M$5:$M$244,0)),"Custom")) -> XI-26 | P14: =IF(B14="","",IF(O14="Custom",IF(E14="","(select function in E)",E14),INDEX('2. Use-Case Library'!$C$5:$C$244,MATCH($O14,'2. Use-Case Library'!$A$5:$A$244,0)))) -> Sales & marketing | Q14: =IF(B14="","",IF(D14<>"",D14,IF(O14="Custom","",INDEX('2. Use-Case Library'!$F$5:$F$244,MATCH($O14,'2. Use-Case Library'!$A$5:$A$244,0))))) -> Answer questions from internal knowledge, policies or past work | R14: =IF(Q14="","",INDEX(Lists!$B$2:$B$11,MATCH(Q14,Lists!$A$2:$A$11,0))) -> GenAI knowledge assistant (RAG on own content) | S14: =IF(R14="","",INDEX(Lists!$C$2:$C$11,MATCH(R14,Lists!$B$2:$B$11,0))) -> 4 | T14: =IF(R14="","",INDEX(Lists!$D$2:$D$11,MATCH(R14,Lists!$B$2:$B$11,0))) -> Yes | U14: =IF(OR(R14="",I14=""),"",IF(INDEX(Lists!$N$2:$N$5,MATCH(I14,Lists!$M$2:$M$5,0))>=INDEX(Lists!$E$2:$E$11,MATCH(R14,Lists!$B$2:$B$11,0)),"Data ready","Data gap")) -> Data ready | V14: =IF(R14="","",IF(S14<=IF('1. AI Position'!$C$30="",5,INDEX(Lists!$AI$2:$AI$5,'1. AI Position'!$C$30)),"Within current position","Beyond current position")) -> Within current position | W14: =IF(B14="","",IF(OR(COUNTA(F14:N14)<9,Q14=""),"Complete inputs",IF(H14="No - varies by person / team","Redesign / standardise first",IF(T14="No","Automate - AI not needed",IF(U14="Data gap","AI later - close data gap first",IF(V14="Beyond current position","Stretch - partner or later stage","AI fit now")))))) -> AI fit now | X14: =IF(OR(W14="",W14="Complete inputs"),"",ROUND(0.3*INDEX(Lists!$N$8:$N$10,MATCH(F14,Lists!$M$8:$M$10,0))+0.25*IF(G14<20,1,IF(G14<80,2,IF(G14<160,3,IF(G14<480,4,5))))+0.25*J14+0.2*K14,2)) -> 3.7 | Y14: =IF(X14="","",ROUND(0.3*IF(U14="Data ready",5,IF(INDEX(Lists!$N$2:$N$5,MATCH(I14,Lists!$M$2:$M$5,0))=INDEX(Lists!$E$2:$E$11,MATCH(R14,Lists!$B$2:$B$11,0))-1,3,1))+0.25*INDEX(Lists!$N$13:$N$15,MATCH(H14,Lists!$M$13:$M$15,0))+0.25*(6-S14)+0.2*IF(V14="Within current position",5,2),2)) -> 3.75 | Z14: =IF(X14="","",CHOOSE(MAX(IF(T14="No",IF(L14="Yes",2,1),IF(IF(L14="Yes",2,0)+IF(M14="Yes",1,0)+INDEX(Lists!$N$18:$N$20,MATCH(N14,Lists!$M$18:$M$20,0))+IF(K14=5,2,IF(K14>=4,1,0))>=4,3,IF(IF(L14="Yes",2,0)+IF(M14="Yes",1,0)+INDEX(Lists!$N$18:$N$20,MATCH(N14,Lists!$M$18:$M$20,0))+IF(K14=5,2,IF(K14>=4,1,0))>=2,2,1))),IF($O14="Custom",1,MATCH(INDEX('2. Use-Case Library'!$L$5:$L$244,MATCH($O14,'2. Use-Case Library'!$A$5:$A$244,0)),{"Low","Medium","High"},0))),"Low","Medium","High")) -> Low | AA14: =IF(X14="","",IF(AND(X14>=$C$4,Y14>=$C$4),"Quick win",IF(X14>=$C$4,"Strategic bet",IF(Y14>=$C$4,"Fill-in","Deprioritise")))) -> Quick win | AB14: =IF(X14="","",ROUND(X14*Y14*IF(Z14="High",0.85,1)*IF(W14="Redesign / standardise first",0.8,1),2)) -> 13.88 | AC14: =IF(AB14="","",RANK(AB14,$AB$8:$AB$57)+COUNTIF($AB$7:AB13,AB14)) -> 10 | AD14: =IF(AH14="","",INDEX(Lists!$AV$2:$AV$5,AH14)) -> H1 - Now (0-6 months) | AE14: =IF(AB14="","",ROUND(G14*12*INDEX(Lists!$F$2:$F$11,MATCH(R14,Lists!$B$2:$B$11,0)),0)) -> 1050 | AF14: =IF(OR(B14="",R14=""),"",IF(O14="Custom",INDEX(Lists!$I$2:$I$11,MATCH(R14,Lists!$B$2:$B$11,0)),INDEX('2. Use-Case Library'!$H$5:$H$244,MATCH($O14,'2. Use-Case Library'!$A$5:$A$244,0)))) -> Knowledge assistant over approved credentials, CVs and past proposals to draft responses; bid manager review. | AG14: =IF(OR(B14="",O14="Custom"),"",INDEX('2. Use-Case Library'!$K$5:$K$244,MATCH($O14,'2. Use-Case Library'!$A$5:$A$244,0))) -> Client confidentiality - sanitise past work; human review. | AH14: =IF(AB14="","",IF(AA14="Deprioritise",4,IF(W14="AI later - close data gap first",3,IF(OR(W14="Redesign / standardise first",W14="Stretch - partner or later stage",AA14="Strategic bet",Z14="High",S14=5),2,1)))) -> 1 | AI14: =IF(AC14="","",AH14*100+AC14) -> 110 | AJ14: =IF(B14="","",IF(O14="Custom",B14,INDEX('2. Use-Case Library'!$D$5:$D$244,MATCH($O14,'2. Use-Case Library'!$A$5:$A$244,0)))) -> Proposal, quotation & tender responses
A15: 8 | B15: PRO-07 | Advisory - due-diligence data-room review | F15: Medium (100 - 1,000 a month) | G15: 220 | H15: Partly - common steps, some variation | I15: Digital history available | J15: 4 | K15: 4 | L15: No | M15: Yes | N15: Human approves each AI output | O15: =IF(B15="","",IFERROR(INDEX('2. Use-Case Library'!$A$5:$A$244,MATCH(B15,'2. Use-Case Library'!$M$5:$M$244,0)),"Custom")) -> PRO-07 | P15: =IF(B15="","",IF(O15="Custom",IF(E15="","(select function in E)",E15),INDEX('2. Use-Case Library'!$C$5:$C$244,MATCH($O15,'2. Use-Case Library'!$A$5:$A$244,0)))) -> Core operations & service delivery | Q15: =IF(B15="","",IF(D15<>"",D15,IF(O15="Custom","",INDEX('2. Use-Case Library'!$F$5:$F$244,MATCH($O15,'2. Use-Case Library'!$A$5:$A$244,0))))) -> Draft, summarise, translate or review text | R15: =IF(Q15="","",INDEX(Lists!$B$2:$B$11,MATCH(Q15,Lists!$A$2:$A$11,0))) -> Generative AI assistant (off-the-shelf) | S15: =IF(R15="","",INDEX(Lists!$C$2:$C$11,MATCH(R15,Lists!$B$2:$B$11,0))) -> 3 | T15: =IF(R15="","",INDEX(Lists!$D$2:$D$11,MATCH(R15,Lists!$B$2:$B$11,0))) -> Yes | U15: =IF(OR(R15="",I15=""),"",IF(INDEX(Lists!$N$2:$N$5,MATCH(I15,Lists!$M$2:$M$5,0))>=INDEX(Lists!$E$2:$E$11,MATCH(R15,Lists!$B$2:$B$11,0)),"Data ready","Data gap")) -> Data ready | V15: =IF(R15="","",IF(S15<=IF('1. AI Position'!$C$30="",5,INDEX(Lists!$AI$2:$AI$5,'1. AI Position'!$C$30)),"Within current position","Beyond current position")) -> Within current position | W15: =IF(B15="","",IF(OR(COUNTA(F15:N15)<9,Q15=""),"Complete inputs",IF(H15="No - varies by person / team","Redesign / standardise first",IF(T15="No","Automate - AI not needed",IF(U15="Data gap","AI later - close data gap first",IF(V15="Beyond current position","Stretch - partner or later stage","AI fit now")))))) -> AI fit now | X15: =IF(OR(W15="",W15="Complete inputs"),"",ROUND(0.3*INDEX(Lists!$N$8:$N$10,MATCH(F15,Lists!$M$8:$M$10,0))+0.25*IF(G15<20,1,IF(G15<80,2,IF(G15<160,3,IF(G15<480,4,5))))+0.25*J15+0.2*K15,2)) -> 3.7 | Y15: =IF(X15="","",ROUND(0.3*IF(U15="Data ready",5,IF(INDEX(Lists!$N$2:$N$5,MATCH(I15,Lists!$M$2:$M$5,0))=INDEX(Lists!$E$2:$E$11,MATCH(R15,Lists!$B$2:$B$11,0))-1,3,1))+0.25*INDEX(Lists!$N$13:$N$15,MATCH(H15,Lists!$M$13:$M$15,0))+0.25*(6-S15)+0.2*IF(V15="Within current position",5,2),2)) -> 4 | Z15: =IF(X15="","",CHOOSE(MAX(IF(T15="No",IF(L15="Yes",2,1),IF(IF(L15="Yes",2,0)+IF(M15="Yes",1,0)+INDEX(Lists!$N$18:$N$20,MATCH(N15,Lists!$M$18:$M$20,0))+IF(K15=5,2,IF(K15>=4,1,0))>=4,3,IF(IF(L15="Yes",2,0)+IF(M15="Yes",1,0)+INDEX(Lists!$N$18:$N$20,MATCH(N15,Lists!$M$18:$M$20,0))+IF(K15=5,2,IF(K15>=4,1,0))>=2,2,1))),IF($O15="Custom",1,MATCH(INDEX('2. Use-Case Library'!$L$5:$L$244,MATCH($O15,'2. Use-Case Library'!$A$5:$A$244,0)),{"Low","Medium","High"},0))),"Low","Medium","High")) -> Medium | AA15: =IF(X15="","",IF(AND(X15>=$C$4,Y15>=$C$4),"Quick win",IF(X15>=$C$4,"Strategic bet",IF(Y15>=$C$4,"Fill-in","Deprioritise")))) -> Quick win | AB15: =IF(X15="","",ROUND(X15*Y15*IF(Z15="High",0.85,1)*IF(W15="Redesign / standardise first",0.8,1),2)) -> 14.8 | AC15: =IF(AB15="","",RANK(AB15,$AB$8:$AB$57)+COUNTIF($AB$7:AB14,AB15)) -> 8 | AD15: =IF(AH15="","",INDEX(Lists!$AV$2:$AV$5,AH15)) -> H1 - Now (0-6 months) | AE15: =IF(AB15="","",ROUND(G15*12*INDEX(Lists!$F$2:$F$11,MATCH(R15,Lists!$B$2:$B$11,0)),0)) -> 792 | AF15: =IF(OR(B15="",R15=""),"",IF(O15="Custom",INDEX(Lists!$I$2:$I$11,MATCH(R15,Lists!$B$2:$B$11,0)),INDEX('2. Use-Case Library'!$H$5:$H$244,MATCH($O15,'2. Use-Case Library'!$A$5:$A$244,0)))) -> GenAI review of data-room documents against DD checklists with red-flag summaries. | AG15: =IF(OR(B15="",O15="Custom"),"",INDEX('2. Use-Case Library'!$K$5:$K$244,MATCH($O15,'2. Use-Case Library'!$A$5:$A$244,0))) -> Confidentiality; NDA terms; verify findings. | AH15: =IF(AB15="","",IF(AA15="Deprioritise",4,IF(W15="AI later - close data gap first",3,IF(OR(W15="Redesign / standardise first",W15="Stretch - partner or later stage",AA15="Strategic bet",Z15="High",S15=5),2,1)))) -> 1 | AI15: =IF(AC15="","",AH15*100+AC15) -> 108 | AJ15: =IF(B15="","",IF(O15="Custom",B15,INDEX('2. Use-Case Library'!$D$5:$D$244,MATCH($O15,'2. Use-Case Library'!$A$5:$A$244,0)))) -> Advisory - due-diligence data-room review
