Workbook

Sheet Summary
A1: GT AI SECURITY & AGENT AUDIT CHECKLIST v2.0
A2: Consolidates the AI Security Audit Checklist v1.0 (85 items, numbering retained), ISACA 'Cybersecurity Recommendations for Securing AI Agents' (2026) and ISO/IEC 42001 AIMS checks. Every item maps to GT AI RCM v2.1 controls. One pass per AI system.
A4: AI system name
A5: System owner
A6: Audit lead
A7: Audit date
A8: Audit type (Initial / Annual / Triggered / Pre-deployment)
A9: Agentic system? (Yes / No)
A10: Previous audit date
A11: Previous audit score
A14: Section | B14: Items | C14: Pass | D14: Fail | E14: N/A | F14: Not assessed | G14: Score | H14: Rating
A15: 3. Infrastructure Security | B15: =COUNTA(Checklist!A5:A21) -> 17 | C15: =COUNTIF(Checklist!E5:E21,"Pass") -> 0 | D15: =COUNTIF(Checklist!E5:E21,"Fail") -> 0 | E15: =COUNTIF(Checklist!E5:E21,"N/A") -> 0 | F15: =B15-C15-D15-E15 -> 17 | G15: =IF(C15+D15=0,"-",C15/(C15+D15)) -> - | H15: =IF(G15="-","-",IF(G15>=0.9,"Low Risk",IF(G15>=0.75,"Moderate Risk",IF(G15>=0.6,"High Risk","Critical Risk")))) -> -
A16: 4. Data Security | B16: =COUNTA(Checklist!A23:A37) -> 15 | C16: =COUNTIF(Checklist!E23:E37,"Pass") -> 0 | D16: =COUNTIF(Checklist!E23:E37,"Fail") -> 0 | E16: =COUNTIF(Checklist!E23:E37,"N/A") -> 0 | F16: =B16-C16-D16-E16 -> 15 | G16: =IF(C16+D16=0,"-",C16/(C16+D16)) -> - | H16: =IF(G16="-","-",IF(G16>=0.9,"Low Risk",IF(G16>=0.75,"Moderate Risk",IF(G16>=0.6,"High Risk","Critical Risk")))) -> -
A17: 5. Model Security | B17: =COUNTA(Checklist!A39:A56) -> 18 | C17: =COUNTIF(Checklist!E39:E56,"Pass") -> 0 | D17: =COUNTIF(Checklist!E39:E56,"Fail") -> 0 | E17: =COUNTIF(Checklist!E39:E56,"N/A") -> 0 | F17: =B17-C17-D17-E17 -> 18 | G17: =IF(C17+D17=0,"-",C17/(C17+D17)) -> - | H17: =IF(G17="-","-",IF(G17>=0.9,"Low Risk",IF(G17>=0.75,"Moderate Risk",IF(G17>=0.6,"High Risk","Critical Risk")))) -> -
A18: 6. Access Control | B18: =COUNTA(Checklist!A58:A65) -> 8 | C18: =COUNTIF(Checklist!E58:E65,"Pass") -> 0 | D18: =COUNTIF(Checklist!E58:E65,"Fail") -> 0 | E18: =COUNTIF(Checklist!E58:E65,"N/A") -> 0 | F18: =B18-C18-D18-E18 -> 8 | G18: =IF(C18+D18=0,"-",C18/(C18+D18)) -> - | H18: =IF(G18="-","-",IF(G18>=0.9,"Low Risk",IF(G18>=0.75,"Moderate Risk",IF(G18>=0.6,"High Risk","Critical Risk")))) -> -
A19: 7. Logging, Monitoring & Incident Response | B19: =COUNTA(Checklist!A67:A81) -> 15 | C19: =COUNTIF(Checklist!E67:E81,"Pass") -> 0 | D19: =COUNTIF(Checklist!E67:E81,"Fail") -> 0 | E19: =COUNTIF(Checklist!E67:E81,"N/A") -> 0 | F19: =B19-C19-D19-E19 -> 15 | G19: =IF(C19+D19=0,"-",C19/(C19+D19)) -> - | H19: =IF(G19="-","-",IF(G19>=0.9,"Low Risk",IF(G19>=0.75,"Moderate Risk",IF(G19>=0.6,"High Risk","Critical Risk")))) -> -
A20: 8. Supply Chain Security | B20: =COUNTA(Checklist!A83:A88) -> 6 | C20: =COUNTIF(Checklist!E83:E88,"Pass") -> 0 | D20: =COUNTIF(Checklist!E83:E88,"Fail") -> 0 | E20: =COUNTIF(Checklist!E83:E88,"N/A") -> 0 | F20: =B20-C20-D20-E20 -> 6 | G20: =IF(C20+D20=0,"-",C20/(C20+D20)) -> - | H20: =IF(G20="-","-",IF(G20>=0.9,"Low Risk",IF(G20>=0.75,"Moderate Risk",IF(G20>=0.6,"High Risk","Critical Risk")))) -> -
A21: 9. Compliance & Governance | B21: =COUNTA(Checklist!A90:A95) -> 6 | C21: =COUNTIF(Checklist!E90:E95,"Pass") -> 0 | D21: =COUNTIF(Checklist!E90:E95,"Fail") -> 0 | E21: =COUNTIF(Checklist!E90:E95,"N/A") -> 0 | F21: =B21-C21-D21-E21 -> 6 | G21: =IF(C21+D21=0,"-",C21/(C21+D21)) -> - | H21: =IF(G21="-","-",IF(G21>=0.9,"Low Risk",IF(G21>=0.75,"Moderate Risk",IF(G21>=0.6,"High Risk","Critical Risk")))) -> -
A22: 10. AI Agent Security (ISACA 2026) | B22: =COUNTA(Checklist!A97:A119) -> 23 | C22: =COUNTIF(Checklist!E97:E119,"Pass") -> 0 | D22: =COUNTIF(Checklist!E97:E119,"Fail") -> 0 | E22: =COUNTIF(Checklist!E97:E119,"N/A") -> 0 | F22: =B22-C22-D22-E22 -> 23 | G22: =IF(C22+D22=0,"-",C22/(C22+D22)) -> - | H22: =IF(G22="-","-",IF(G22>=0.9,"Low Risk",IF(G22>=0.75,"Moderate Risk",IF(G22>=0.6,"High Risk","Critical Risk")))) -> -
A23: 11. AI Management System (ISO/IEC 42001) | B23: =COUNTA(Checklist!A121:A137) -> 17 | C23: =COUNTIF(Checklist!E121:E137,"Pass") -> 0 | D23: =COUNTIF(Checklist!E121:E137,"Fail") -> 0 | E23: =COUNTIF(Checklist!E121:E137,"N/A") -> 0 | F23: =B23-C23-D23-E23 -> 17 | G23: =IF(C23+D23=0,"-",C23/(C23+D23)) -> - | H23: =IF(G23="-","-",IF(G23>=0.9,"Low Risk",IF(G23>=0.75,"Moderate Risk",IF(G23>=0.6,"High Risk","Critical Risk")))) -> -
A24: OVERALL | B24: =SUM(B15:B23) -> 125 | C24: =SUM(C15:C23) -> 0 | D24: =SUM(D15:D23) -> 0 | E24: =SUM(E15:E23) -> 0 | F24: =SUM(F15:F23) -> 125 | G24: =IF(C24+D24=0,"-",C24/(C24+D24)) -> - | H24: =IF(G24="-","-",IF(G24>=0.9,"Low Risk",IF(G24>=0.75,"Moderate Risk",IF(G24>=0.6,"High Risk","Critical Risk")))) -> -
A25: Critical-risk items failed | B25: =COUNTIFS(Checklist!E5:E137,"Fail",Checklist!F5:F137,"Critical") -> 0 | C25: =IF(B25>0,"Any failed Critical item escalates the overall rating to Critical Risk regardless of score.","")
A26: FINAL RATING | B26: =IF(B25>0,"Critical Risk",H24) -> -
A28: Score | B28: Rating | C28: Required action
A29: 90-100% | B29: Low Risk | C29: Annual re-audit
A30: 75-89% | B30: Moderate Risk | C30: Remediation within 90 days
A31: 60-74% | B31: High Risk | C31: Remediation within 30 days
A32: Below 60% | B32: Critical Risk | C32: Immediate remediation; consider suspending the AI system
A34: Score = Pass / (Pass + Fail); N/A excluded. Section 10 applies to agentic AI systems (mark N/A otherwise). Section 11 applies where the organisation operates or plans an ISO/IEC 42001 AI management system. Rating bands per AI Security Audit Checklist v1.0.

Sheet Checklist
A1: AUDIT CHECKLIST - select Status (Pass / Fail / N/A) and Risk for every item
A3: # | B3: Control / check | C3: Source | D3: GT AI RCM v2.1 | E3: Status | F3: Risk if failed | G3: Evidence reviewed | H3: Notes / finding
A4: 3. Infrastructure Security
A5: 3.1.1 | B5: AI systems are segmented from the general network | C5: Audit Checklist v1.0 | D5: SE-9, SE-5 | K5: =IF(E5="Fail",COUNTIF($E$5:E5,"Fail"),"") | L5: 3. Infrastructure Security
A6: 3.1.2 | B6: Firewall rules restrict AI system access | C6: Audit Checklist v1.0 | D6: SE-5 | K6: =IF(E6="Fail",COUNTIF($E$5:E6,"Fail"),"") | L6: 3. Infrastructure Security
A7: 3.1.3 | B7: API endpoints are behind a WAF / API gateway | C7: Audit Checklist v1.0 | D7: SE-10 | K7: =IF(E7="Fail",COUNTIF($E$5:E7,"Fail"),"") | L7: 3. Infrastructure Security
A8: 3.1.4 | B8: Internal AI services are not exposed to the internet | C8: Audit Checklist v1.0 | D8: SE-5, SE-9 | K8: =IF(E8="Fail",COUNTIF($E$5:E8,"Fail"),"") | L8: 3. Infrastructure Security
A9: 3.1.5 | B9: Network traffic is monitored and logged | C9: Audit Checklist v1.0 | D9: SE-5, OM-2 | K9: =IF(E9="Fail",COUNTIF($E$5:E9,"Fail"),"") | L9: 3. Infrastructure Security
A10: 3.1.6 | B10: DDoS protection is in place for AI endpoints | C10: Audit Checklist v1.0 | D10: SE-5, OM-4 | K10: =IF(E10="Fail",COUNTIF($E$5:E10,"Fail"),"") | L10: 3. Infrastructure Security
A11: 3.2.1 | B11: GPU/TPU instances are hardened | C11: Audit Checklist v1.0 | D11: SE-1, SE-9 | K11: =IF(E11="Fail",COUNTIF($E$5:E11,"Fail"),"") | L11: 3. Infrastructure Security
A12: 3.2.2 | B12: Container images are scanned for vulnerabilities | C12: Audit Checklist v1.0 | D12: SE-3, SE-7 | K12: =IF(E12="Fail",COUNTIF($E$5:E12,"Fail"),"") | L12: 3. Infrastructure Security
A13: 3.2.3 | B13: Model-serving infrastructure is patched | C13: Audit Checklist v1.0 | D13: SE-3 | K13: =IF(E13="Fail",COUNTIF($E$5:E13,"Fail"),"") | L13: 3. Infrastructure Security
A14: 3.2.4 | B14: Kubernetes / orchestration security is configured | C14: Audit Checklist v1.0 | D14: SE-9 | K14: =IF(E14="Fail",COUNTIF($E$5:E14,"Fail"),"") | L14: 3. Infrastructure Security
A15: 3.2.5 | B15: Secrets management in place (no hard-coded credentials) | C15: Audit Checklist v1.0 | D15: SE-8 | K15: =IF(E15="Fail",COUNTIF($E$5:E15,"Fail"),"") | L15: 3. Infrastructure Security
A16: 3.2.6 | B16: Resource limits prevent abuse (CPU, memory, GPU) | C16: Audit Checklist v1.0 | D16: OM-4, SE-9 | K16: =IF(E16="Fail",COUNTIF($E$5:E16,"Fail"),"") | L16: 3. Infrastructure Security
... A21: 3.3.5 | B21: Cloud security posture management is active | C21: Audit Checklist v1.0 | D21: SE-1 | K21: =IF(E21="Fail",COUNTIF($E$5:E21,"Fail"),"") | L21: 3. Infrastructure Security
A22: 4. Data Security | K22: =IF(E22="Fail",COUNTIF($E$5:E22,"Fail"),"")
A23: 4.1.1 | B23: Training data encrypted at rest (AES-256) | C23: Audit Checklist v1.0 | D23: SE-4 | K23: =IF(E23="Fail",COUNTIF($E$5:E23,"Fail"),"") | L23: 4. Data Security
A24: 4.1.2 | B24: Model weights / artefacts encrypted at rest | C24: Audit Checklist v1.0 | D24: SE-4, LC-13 | K24: =IF(E24="Fail",COUNTIF($E$5:E24,"Fail"),"") | L24: 4. Data Security
A25: 4.1.3 | B25: Inference logs encrypted at rest | C25: Audit Checklist v1.0 | D25: SE-4, OM-2 | K25: =IF(E25="Fail",COUNTIF($E$5:E25,"Fail"),"") | L25: 4. Data Security
A26: 4.1.4 | B26: Encryption keys properly managed (KMS / HSM) | C26: Audit Checklist v1.0 | D26: SE-4, SE-8 | K26: =IF(E26="Fail",COUNTIF($E$5:E26,"Fail"),"") | L26: 4. Data Security
A27: 4.1.5 | B27: Backup data encrypted | C27: Audit Checklist v1.0 | D27: SE-4 | K27: =IF(E27="Fail",COUNTIF($E$5:E27,"Fail"),"") | L27: 4. Data Security
A28: 4.2.1 | B28: TLS 1.2+ for all AI API communications | C28: Audit Checklist v1.0 | D28: SE-5 | K28: =IF(E28="Fail",COUNTIF($E$5:E28,"Fail"),"") | L28: 4. Data Security
A29: 4.2.2 | B29: Certificate management automated | C29: Audit Checklist v1.0 | D29: SE-5 | K29: =IF(E29="Fail",COUNTIF($E$5:E29,"Fail"),"") | L29: 4. Data Security
A30: 4.2.3 | B30: Internal service-to-service encryption (mTLS) | C30: Audit Checklist v1.0 | D30: SE-5 | K30: =IF(E30="Fail",COUNTIF($E$5:E30,"Fail"),"") | L30: 4. Data Security
A31: 4.2.4 | B31: Data transfers to / from vendors encrypted | C31: Audit Checklist v1.0 | D31: SE-4, TP-3 | K31: =IF(E31="Fail",COUNTIF($E$5:E31,"Fail"),"") | L31: 4. Data Security
A32: 4.3.1 | B32: Data classification applied to AI datasets | C32: Audit Checklist v1.0 | D32: LC-1, SE-4 | K32: =IF(E32="Fail",COUNTIF($E$5:E32,"Fail"),"") | L32: 4. Data Security
A33: 4.3.2 | B33: Data retention policies enforced (incl. prompts, outputs, AI logs) | C33: Audit Checklist v1.0 | D33: PR-7 | K33: =IF(E33="Fail",COUNTIF($E$5:E33,"Fail"),"") | L33: 4. Data Security
A34: 4.3.3 | B34: Secure data deletion procedures followed | C34: Audit Checklist v1.0 | D34: PR-2, LC-10 | K34: =IF(E34="Fail",COUNTIF($E$5:E34,"Fail"),"") | L34: 4. Data Security
... A37: 4.3.6 | B37: Data anonymisation / pseudonymisation verified | C37: Audit Checklist v1.0 | D37: PR-4 | K37: =IF(E37="Fail",COUNTIF($E$5:E37,"Fail"),"") | L37: 4. Data Security
A38: 5. Model Security | K38: =IF(E38="Fail",COUNTIF($E$5:E38,"Fail"),"")
A39: 5.1.1 | B39: Model artefacts stored in a secure registry | C39: Audit Checklist v1.0 | D39: LC-13 | K39: =IF(E39="Fail",COUNTIF($E$5:E39,"Fail"),"") | L39: 5. Model Security
A40: 5.1.2 | B40: Model versioning with integrity checksums | C40: Audit Checklist v1.0 | D40: LC-13 | K40: =IF(E40="Fail",COUNTIF($E$5:E40,"Fail"),"") | L40: 5. Model Security
A41: 5.1.3 | B41: Model signing / verification implemented | C41: Audit Checklist v1.0 | D41: LC-13, SE-7 | K41: =IF(E41="Fail",COUNTIF($E$5:E41,"Fail"),"") | L41: 5. Model Security
A42: 5.1.4 | B42: Unauthorised model modifications are detectable | C42: Audit Checklist v1.0 | D42: LC-13, LC-5 | K42: =IF(E42="Fail",COUNTIF($E$5:E42,"Fail"),"") | L42: 5. Model Security
A43: 5.1.5 | B43: Model rollback capability tested | C43: Audit Checklist v1.0 | D43: LC-13, OM-4 | K43: =IF(E43="Fail",COUNTIF($E$5:E43,"Fail"),"") | L43: 5. Model Security
A44: 5.2.1 | B44: Prompt-injection testing conducted | C44: Audit Checklist v1.0 | D44: SE-6, AA-3 | K44: =IF(E44="Fail",COUNTIF($E$5:E44,"Fail"),"") | L44: 5. Model Security
A45: 5.2.2 | B45: Jailbreak resistance verified | C45: Audit Checklist v1.0 | D45: SE-6 | K45: =IF(E45="Fail",COUNTIF($E$5:E45,"Fail"),"") | L45: 5. Model Security
A46: 5.2.3 | B46: Data-poisoning defences in place | C46: Audit Checklist v1.0 | D46: SE-6, LC-1 | K46: =IF(E46="Fail",COUNTIF($E$5:E46,"Fail"),"") | L46: 5. Model Security
A47: 5.2.4 | B47: Model-extraction attack resistance tested | C47: Audit Checklist v1.0 | D47: SE-6 | K47: =IF(E47="Fail",COUNTIF($E$5:E47,"Fail"),"") | L47: 5. Model Security
...

Sheet Findings & Remediation
A1: FINDINGS & REMEDIATION PLAN - failed items are listed automatically; complete remediation, owner, due date, status
A3: # | B3: Item | C3: Finding (failed check) | D3: Severity | E3: Section | F3: GT AI RCM v2.1 | G3: Remediation | H3: Owner | I3: Due date | J3: Status
A4: 1 | B4: =IFERROR(INDEX(Checklist!$A$5:$A$137,MATCH(1,Checklist!$K$5:$K$137,0)),"") | C4: =IFERROR(INDEX(Checklist!$B$5:$B$137,MATCH(1,Checklist!$K$5:$K$137,0)),"") | D4: =IFERROR(INDEX(Checklist!$F$5:$F$137,MATCH(1,Checklist!$K$5:$K$137,0))&"","") | E4: =IFERROR(INDEX(Checklist!$L$5:$L$137,MATCH(1,Checklist!$K$5:$K$137,0)),"") | F4: =IFERROR(INDEX(Checklist!$D$5:$D$137,MATCH(1,Checklist!$K$5:$K$137,0)),"")
A5: 2 | B5: =IFERROR(INDEX(Checklist!$A$5:$A$137,MATCH(2,Checklist!$K$5:$K$137,0)),"") | C5: =IFERROR(INDEX(Checklist!$B$5:$B$137,MATCH(2,Checklist!$K$5:$K$137,0)),"") | D5: =IFERROR(INDEX(Checklist!$F$5:$F$137,MATCH(2,Checklist!$K$5:$K$137,0))&"","") | E5: =IFERROR(INDEX(Checklist!$L$5:$L$137,MATCH(2,Checklist!$K$5:$K$137,0)),"") | F5: =IFERROR(INDEX(Checklist!$D$5:$D$137,MATCH(2,Checklist!$K$5:$K$137,0)),"")
A6: 3 | B6: =IFERROR(INDEX(Checklist!$A$5:$A$137,MATCH(3,Checklist!$K$5:$K$137,0)),"") | C6: =IFERROR(INDEX(Checklist!$B$5:$B$137,MATCH(3,Checklist!$K$5:$K$137,0)),"") | D6: =IFERROR(INDEX(Checklist!$F$5:$F$137,MATCH(3,Checklist!$K$5:$K$137,0))&"","") | E6: =IFERROR(INDEX(Checklist!$L$5:$L$137,MATCH(3,Checklist!$K$5:$K$137,0)),"") | F6: =IFERROR(INDEX(Checklist!$D$5:$D$137,MATCH(3,Checklist!$K$5:$K$137,0)),"")
A7: 4 | B7: =IFERROR(INDEX(Checklist!$A$5:$A$137,MATCH(4,Checklist!$K$5:$K$137,0)),"") | C7: =IFERROR(INDEX(Checklist!$B$5:$B$137,MATCH(4,Checklist!$K$5:$K$137,0)),"") | D7: =IFERROR(INDEX(Checklist!$F$5:$F$137,MATCH(4,Checklist!$K$5:$K$137,0))&"","") | E7: =IFERROR(INDEX(Checklist!$L$5:$L$137,MATCH(4,Checklist!$K$5:$K$137,0)),"") | F7: =IFERROR(INDEX(Checklist!$D$5:$D$137,MATCH(4,Checklist!$K$5:$K$137,0)),"")
A8: 5 | B8: =IFERROR(INDEX(Checklist!$A$5:$A$137,MATCH(5,Checklist!$K$5:$K$137,0)),"") | C8: =IFERROR(INDEX(Checklist!$B$5:$B$137,MATCH(5,Checklist!$K$5:$K$137,0)),"") | D8: =IFERROR(INDEX(Checklist!$F$5:$F$137,MATCH(5,Checklist!$K$5:$K$137,0))&"","") | E8: =IFERROR(INDEX(Checklist!$L$5:$L$137,MATCH(5,Checklist!$K$5:$K$137,0)),"") | F8: =IFERROR(INDEX(Checklist!$D$5:$D$137,MATCH(5,Checklist!$K$5:$K$137,0)),"")
A9: 6 | B9: =IFERROR(INDEX(Checklist!$A$5:$A$137,MATCH(6,Checklist!$K$5:$K$137,0)),"") | C9: =IFERROR(INDEX(Checklist!$B$5:$B$137,MATCH(6,Checklist!$K$5:$K$137,0)),"") | D9: =IFERROR(INDEX(Checklist!$F$5:$F$137,MATCH(6,Checklist!$K$5:$K$137,0))&"","") | E9: =IFERROR(INDEX(Checklist!$L$5:$L$137,MATCH(6,Checklist!$K$5:$K$137,0)),"") | F9: =IFERROR(INDEX(Checklist!$D$5:$D$137,MATCH(6,Checklist!$K$5:$K$137,0)),"")
A10: 7 | B10: =IFERROR(INDEX(Checklist!$A$5:$A$137,MATCH(7,Checklist!$K$5:$K$137,0)),"") | C10: =IFERROR(INDEX(Checklist!$B$5:$B$137,MATCH(7,Checklist!$K$5:$K$137,0)),"") | D10: =IFERROR(INDEX(Checklist!$F$5:$F$137,MATCH(7,Checklist!$K$5:$K$137,0))&"","") | E10: =IFERROR(INDEX(Checklist!$L$5:$L$137,MATCH(7,Checklist!$K$5:$K$137,0)),"") | F10: =IFERROR(INDEX(Checklist!$D$5:$D$137,MATCH(7,Checklist!$K$5:$K$137,0)),"")
A11: 8 | B11: =IFERROR(INDEX(Checklist!$A$5:$A$137,MATCH(8,Checklist!$K$5:$K$137,0)),"") | C11: =IFERROR(INDEX(Checklist!$B$5:$B$137,MATCH(8,Checklist!$K$5:$K$137,0)),"") | D11: =IFERROR(INDEX(Checklist!$F$5:$F$137,MATCH(8,Checklist!$K$5:$K$137,0))&"","") | E11: =IFERROR(INDEX(Checklist!$L$5:$L$137,MATCH(8,Checklist!$K$5:$K$137,0)),"") | F11: =IFERROR(INDEX(Checklist!$D$5:$D$137,MATCH(8,Checklist!$K$5:$K$137,0)),"")
A12: 9 | B12: =IFERROR(INDEX(Checklist!$A$5:$A$137,MATCH(9,Checklist!$K$5:$K$137,0)),"") | C12: =IFERROR(INDEX(Checklist!$B$5:$B$137,MATCH(9,Checklist!$K$5:$K$137,0)),"") | D12: =IFERROR(INDEX(Checklist!$F$5:$F$137,MATCH(9,Checklist!$K$5:$K$137,0))&"","") | E12: =IFERROR(INDEX(Checklist!$L$5:$L$137,MATCH(9,Checklist!$K$5:$K$137,0)),"") | F12: =IFERROR(INDEX(Checklist!$D$5:$D$137,MATCH(9,Checklist!$K$5:$K$137,0)),"")
A13: 10 | B13: =IFERROR(INDEX(Checklist!$A$5:$A$137,MATCH(10,Checklist!$K$5:$K$137,0)),"") | C13: =IFERROR(INDEX(Checklist!$B$5:$B$137,MATCH(10,Checklist!$K$5:$K$137,0)),"") | D13: =IFERROR(INDEX(Checklist!$F$5:$F$137,MATCH(10,Checklist!$K$5:$K$137,0))&"","") | E13: =IFERROR(INDEX(Checklist!$L$5:$L$137,MATCH(10,Checklist!$K$5:$K$137,0)),"") | F13: =IFERROR(INDEX(Checklist!$D$5:$D$137,MATCH(10,Checklist!$K$5:$K$137,0)),"")
A14: 11 | B14: =IFERROR(INDEX(Checklist!$A$5:$A$137,MATCH(11,Checklist!$K$5:$K$137,0)),"") | C14: =IFERROR(INDEX(Checklist!$B$5:$B$137,MATCH(11,Checklist!$K$5:$K$137,0)),"") | D14: =IFERROR(INDEX(Checklist!$F$5:$F$137,MATCH(11,Checklist!$K$5:$K$137,0))&"","") | E14: =IFERROR(INDEX(Checklist!$L$5:$L$137,MATCH(11,Checklist!$K$5:$K$137,0)),"") | F14: =IFERROR(INDEX(Checklist!$D$5:$D$137,MATCH(11,Checklist!$K$5:$K$137,0)),"")
A15: 12 | B15: =IFERROR(INDEX(Checklist!$A$5:$A$137,MATCH(12,Checklist!$K$5:$K$137,0)),"") | C15: =IFERROR(INDEX(Checklist!$B$5:$B$137,MATCH(12,Checklist!$K$5:$K$137,0)),"") | D15: =IFERROR(INDEX(Checklist!$F$5:$F$137,MATCH(12,Checklist!$K$5:$K$137,0))&"","") | E15: =IFERROR(INDEX(Checklist!$L$5:$L$137,MATCH(12,Checklist!$K$5:$K$137,0)),"") | F15: =IFERROR(INDEX(Checklist!$D$5:$D$137,MATCH(12,Checklist!$K$5:$K$137,0)),"")
A16: 13 | B16: =IFERROR(INDEX(Checklist!$A$5:$A$137,MATCH(13,Checklist!$K$5:$K$137,0)),"") | C16: =IFERROR(INDEX(Checklist!$B$5:$B$137,MATCH(13,Checklist!$K$5:$K$137,0)),"") | D16: =IFERROR(INDEX(Checklist!$F$5:$F$137,MATCH(13,Checklist!$K$5:$K$137,0))&"","") | E16: =IFERROR(INDEX(Checklist!$L$5:$L$137,MATCH(13,Checklist!$K$5:$K$137,0)),"") | F16: =IFERROR(INDEX(Checklist!$D$5:$D$137,MATCH(13,Checklist!$K$5:$K$137,0)),"")
A17: 14 | B17: =IFERROR(INDEX(Checklist!$A$5:$A$137,MATCH(14,Checklist!$K$5:$K$137,0)),"") | C17: =IFERROR(INDEX(Checklist!$B$5:$B$137,MATCH(14,Checklist!$K$5:$K$137,0)),"") | D17: =IFERROR(INDEX(Checklist!$F$5:$F$137,MATCH(14,Checklist!$K$5:$K$137,0))&"","") | E17: =IFERROR(INDEX(Checklist!$L$5:$L$137,MATCH(14,Checklist!$K$5:$K$137,0)),"") | F17: =IFERROR(INDEX(Checklist!$D$5:$D$137,MATCH(14,Checklist!$K$5:$K$137,0)),"")
A18: 15 | B18: =IFERROR(INDEX(Checklist!$A$5:$A$137,MATCH(15,Checklist!$K$5:$K$137,0)),"") | C18: =IFERROR(INDEX(Checklist!$B$5:$B$137,MATCH(15,Checklist!$K$5:$K$137,0)),"") | D18: =IFERROR(INDEX(Checklist!$F$5:$F$137,MATCH(15,Checklist!$K$5:$K$137,0))&"","") | E18: =IFERROR(INDEX(Checklist!$L$5:$L$137,MATCH(15,Checklist!$K$5:$K$137,0)),"") | F18: =IFERROR(INDEX(Checklist!$D$5:$D$137,MATCH(15,Checklist!$K$5:$K$137,0)),"")
A19: 16 | B19: =IFERROR(INDEX(Checklist!$A$5:$A$137,MATCH(16,Checklist!$K$5:$K$137,0)),"") | C19: =IFERROR(INDEX(Checklist!$B$5:$B$137,MATCH(16,Checklist!$K$5:$K$137,0)),"") | D19: =IFERROR(INDEX(Checklist!$F$5:$F$137,MATCH(16,Checklist!$K$5:$K$137,0))&"","") | E19: =IFERROR(INDEX(Checklist!$L$5:$L$137,MATCH(16,Checklist!$K$5:$K$137,0)),"") | F19: =IFERROR(INDEX(Checklist!$D$5:$D$137,MATCH(16,Checklist!$K$5:$K$137,0)),"")
A20: 17 | B20: =IFERROR(INDEX(Checklist!$A$5:$A$137,MATCH(17,Checklist!$K$5:$K$137,0)),"") | C20: =IFERROR(INDEX(Checklist!$B$5:$B$137,MATCH(17,Checklist!$K$5:$K$137,0)),"") | D20: =IFERROR(INDEX(Checklist!$F$5:$F$137,MATCH(17,Checklist!$K$5:$K$137,0))&"","") | E20: =IFERROR(INDEX(Checklist!$L$5:$L$137,MATCH(17,Checklist!$K$5:$K$137,0)),"") | F20: =IFERROR(INDEX(Checklist!$D$5:$D$137,MATCH(17,Checklist!$K$5:$K$137,0)),"")
A21: 18 | B21: =IFERROR(INDEX(Checklist!$A$5:$A$137,MATCH(18,Checklist!$K$5:$K$137,0)),"") | C21: =IFERROR(INDEX(Checklist!$B$5:$B$137,MATCH(18,Checklist!$K$5:$K$137,0)),"") | D21: =IFERROR(INDEX(Checklist!$F$5:$F$137,MATCH(18,Checklist!$K$5:$K$137,0))&"","") | E21: =IFERROR(INDEX(Checklist!$L$5:$L$137,MATCH(18,Checklist!$K$5:$K$137,0)),"") | F21: =IFERROR(INDEX(Checklist!$D$5:$D$137,MATCH(18,Checklist!$K$5:$K$137,0)),"")
A22: 19 | B22: =IFERROR(INDEX(Checklist!$A$5:$A$137,MATCH(19,Checklist!$K$5:$K$137,0)),"") | C22: =IFERROR(INDEX(Checklist!$B$5:$B$137,MATCH(19,Checklist!$K$5:$K$137,0)),"") | D22: =IFERROR(INDEX(Checklist!$F$5:$F$137,MATCH(19,Checklist!$K$5:$K$137,0))&"","") | E22: =IFERROR(INDEX(Checklist!$L$5:$L$137,MATCH(19,Checklist!$K$5:$K$137,0)),"") | F22: =IFERROR(INDEX(Checklist!$D$5:$D$137,MATCH(19,Checklist!$K$5:$K$137,0)),"")
A23: 20 | B23: =IFERROR(INDEX(Checklist!$A$5:$A$137,MATCH(20,Checklist!$K$5:$K$137,0)),"") | C23: =IFERROR(INDEX(Checklist!$B$5:$B$137,MATCH(20,Checklist!$K$5:$K$137,0)),"") | D23: =IFERROR(INDEX(Checklist!$F$5:$F$137,MATCH(20,Checklist!$K$5:$K$137,0))&"","") | E23: =IFERROR(INDEX(Checklist!$L$5:$L$137,MATCH(20,Checklist!$K$5:$K$137,0)),"") | F23: =IFERROR(INDEX(Checklist!$D$5:$D$137,MATCH(20,Checklist!$K$5:$K$137,0)),"")
A24: 21 | B24: =IFERROR(INDEX(Checklist!$A$5:$A$137,MATCH(21,Checklist!$K$5:$K$137,0)),"") | C24: =IFERROR(INDEX(Checklist!$B$5:$B$137,MATCH(21,Checklist!$K$5:$K$137,0)),"") | D24: =IFERROR(INDEX(Checklist!$F$5:$F$137,MATCH(21,Checklist!$K$5:$K$137,0))&"","") | E24: =IFERROR(INDEX(Checklist!$L$5:$L$137,MATCH(21,Checklist!$K$5:$K$137,0)),"") | F24: =IFERROR(INDEX(Checklist!$D$5:$D$137,MATCH(21,Checklist!$K$5:$K$137,0)),"")
A25: 22 | B25: =IFERROR(INDEX(Checklist!$A$5:$A$137,MATCH(22,Checklist!$K$5:$K$137,0)),"") | C25: =IFERROR(INDEX(Checklist!$B$5:$B$137,MATCH(22,Checklist!$K$5:$K$137,0)),"") | D25: =IFERROR(INDEX(Checklist!$F$5:$F$137,MATCH(22,Checklist!$K$5:$K$137,0))&"","") | E25: =IFERROR(INDEX(Checklist!$L$5:$L$137,MATCH(22,Checklist!$K$5:$K$137,0)),"") | F25: =IFERROR(INDEX(Checklist!$D$5:$D$137,MATCH(22,Checklist!$K$5:$K$137,0)),"")
A26: 23 | B26: =IFERROR(INDEX(Checklist!$A$5:$A$137,MATCH(23,Checklist!$K$5:$K$137,0)),"") | C26: =IFERROR(INDEX(Checklist!$B$5:$B$137,MATCH(23,Checklist!$K$5:$K$137,0)),"") | D26: =IFERROR(INDEX(Checklist!$F$5:$F$137,MATCH(23,Checklist!$K$5:$K$137,0))&"","") | E26: =IFERROR(INDEX(Checklist!$L$5:$L$137,MATCH(23,Checklist!$K$5:$K$137,0)),"") | F26: =IFERROR(INDEX(Checklist!$D$5:$D$137,MATCH(23,Checklist!$K$5:$K$137,0)),"")
A27: 24 | B27: =IFERROR(INDEX(Checklist!$A$5:$A$137,MATCH(24,Checklist!$K$5:$K$137,0)),"") | C27: =IFERROR(INDEX(Checklist!$B$5:$B$137,MATCH(24,Checklist!$K$5:$K$137,0)),"") | D27: =IFERROR(INDEX(Checklist!$F$5:$F$137,MATCH(24,Checklist!$K$5:$K$137,0))&"","") | E27: =IFERROR(INDEX(Checklist!$L$5:$L$137,MATCH(24,Checklist!$K$5:$K$137,0)),"") | F27: =IFERROR(INDEX(Checklist!$D$5:$D$137,MATCH(24,Checklist!$K$5:$K$137,0)),"")
A28: 25 | B28: =IFERROR(INDEX(Checklist!$A$5:$A$137,MATCH(25,Checklist!$K$5:$K$137,0)),"") | C28: =IFERROR(INDEX(Checklist!$B$5:$B$137,MATCH(25,Checklist!$K$5:$K$137,0)),"") | D28: =IFERROR(INDEX(Checklist!$F$5:$F$137,MATCH(25,Checklist!$K$5:$K$137,0))&"","") | E28: =IFERROR(INDEX(Checklist!$L$5:$L$137,MATCH(25,Checklist!$K$5:$K$137,0)),"") | F28: =IFERROR(INDEX(Checklist!$D$5:$D$137,MATCH(25,Checklist!$K$5:$K$137,0)),"")
A29: 26 | B29: =IFERROR(INDEX(Checklist!$A$5:$A$137,MATCH(26,Checklist!$K$5:$K$137,0)),"") | C29: =IFERROR(INDEX(Checklist!$B$5:$B$137,MATCH(26,Checklist!$K$5:$K$137,0)),"") | D29: =IFERROR(INDEX(Checklist!$F$5:$F$137,MATCH(26,Checklist!$K$5:$K$137,0))&"","") | E29: =IFERROR(INDEX(Checklist!$L$5:$L$137,MATCH(26,Checklist!$K$5:$K$137,0)),"") | F29: =IFERROR(INDEX(Checklist!$D$5:$D$137,MATCH(26,Checklist!$K$5:$K$137,0)),"")
A30: 27 | B30: =IFERROR(INDEX(Checklist!$A$5:$A$137,MATCH(27,Checklist!$K$5:$K$137,0)),"") | C30: =IFERROR(INDEX(Checklist!$B$5:$B$137,MATCH(27,Checklist!$K$5:$K$137,0)),"") | D30: =IFERROR(INDEX(Checklist!$F$5:$F$137,MATCH(27,Checklist!$K$5:$K$137,0))&"","") | E30: =IFERROR(INDEX(Checklist!$L$5:$L$137,MATCH(27,Checklist!$K$5:$K$137,0)),"") | F30: =IFERROR(INDEX(Checklist!$D$5:$D$137,MATCH(27,Checklist!$K$5:$K$137,0)),"")
A31: 28 | B31: =IFERROR(INDEX(Checklist!$A$5:$A$137,MATCH(28,Checklist!$K$5:$K$137,0)),"") | C31: =IFERROR(INDEX(Checklist!$B$5:$B$137,MATCH(28,Checklist!$K$5:$K$137,0)),"") | D31: =IFERROR(INDEX(Checklist!$F$5:$F$137,MATCH(28,Checklist!$K$5:$K$137,0))&"","") | E31: =IFERROR(INDEX(Checklist!$L$5:$L$137,MATCH(28,Checklist!$K$5:$K$137,0)),"") | F31: =IFERROR(INDEX(Checklist!$D$5:$D$137,MATCH(28,Checklist!$K$5:$K$137,0)),"")
A32: 29 | B32: =IFERROR(INDEX(Checklist!$A$5:$A$137,MATCH(29,Checklist!$K$5:$K$137,0)),"") | C32: =IFERROR(INDEX(Checklist!$B$5:$B$137,MATCH(29,Checklist!$K$5:$K$137,0)),"") | D32: =IFERROR(INDEX(Checklist!$F$5:$F$137,MATCH(29,Checklist!$K$5:$K$137,0))&"","") | E32: =IFERROR(INDEX(Checklist!$L$5:$L$137,MATCH(29,Checklist!$K$5:$K$137,0)),"") | F32: =IFERROR(INDEX(Checklist!$D$5:$D$137,MATCH(29,Checklist!$K$5:$K$137,0)),"")
A33: 30 | B33: =IFERROR(INDEX(Checklist!$A$5:$A$137,MATCH(30,Checklist!$K$5:$K$137,0)),"") | C33: =IFERROR(INDEX(Checklist!$B$5:$B$137,MATCH(30,Checklist!$K$5:$K$137,0)),"") | D33: =IFERROR(INDEX(Checklist!$F$5:$F$137,MATCH(30,Checklist!$K$5:$K$137,0))&"","") | E33: =IFERROR(INDEX(Checklist!$L$5:$L$137,MATCH(30,Checklist!$K$5:$K$137,0)),"") | F33: =IFERROR(INDEX(Checklist!$D$5:$D$137,MATCH(30,Checklist!$K$5:$K$137,0)),"")
A34: 31 | B34: =IFERROR(INDEX(Checklist!$A$5:$A$137,MATCH(31,Checklist!$K$5:$K$137,0)),"") | C34: =IFERROR(INDEX(Checklist!$B$5:$B$137,MATCH(31,Checklist!$K$5:$K$137,0)),"") | D34: =IFERROR(INDEX(Checklist!$F$5:$F$137,MATCH(31,Checklist!$K$5:$K$137,0))&"","") | E34: =IFERROR(INDEX(Checklist!$L$5:$L$137,MATCH(31,Checklist!$K$5:$K$137,0)),"") | F34: =IFERROR(INDEX(Checklist!$D$5:$D$137,MATCH(31,Checklist!$K$5:$K$137,0)),"")
A35: 32 | B35: =IFERROR(INDEX(Checklist!$A$5:$A$137,MATCH(32,Checklist!$K$5:$K$137,0)),"") | C35: =IFERROR(INDEX(Checklist!$B$5:$B$137,MATCH(32,Checklist!$K$5:$K$137,0)),"") | D35: =IFERROR(INDEX(Checklist!$F$5:$F$137,MATCH(32,Checklist!$K$5:$K$137,0))&"","") | E35: =IFERROR(INDEX(Checklist!$L$5:$L$137,MATCH(32,Checklist!$K$5:$K$137,0)),"") | F35: =IFERROR(INDEX(Checklist!$D$5:$D$137,MATCH(32,Checklist!$K$5:$K$137,0)),"")
A36: 33 | B36: =IFERROR(INDEX(Checklist!$A$5:$A$137,MATCH(33,Checklist!$K$5:$K$137,0)),"") | C36: =IFERROR(INDEX(Checklist!$B$5:$B$137,MATCH(33,Checklist!$K$5:$K$137,0)),"") | D36: =IFERROR(INDEX(Checklist!$F$5:$F$137,MATCH(33,Checklist!$K$5:$K$137,0))&"","") | E36: =IFERROR(INDEX(Checklist!$L$5:$L$137,MATCH(33,Checklist!$K$5:$K$137,0)),"") | F36: =IFERROR(INDEX(Checklist!$D$5:$D$137,MATCH(33,Checklist!$K$5:$K$137,0)),"")
A37: 34 | B37: =IFERROR(INDEX(Checklist!$A$5:$A$137,MATCH(34,Checklist!$K$5:$K$137,0)),"") | C37: =IFERROR(INDEX(Checklist!$B$5:$B$137,MATCH(34,Checklist!$K$5:$K$137,0)),"") | D37: =IFERROR(INDEX(Checklist!$F$5:$F$137,MATCH(34,Checklist!$K$5:$K$137,0))&"","") | E37: =IFERROR(INDEX(Checklist!$L$5:$L$137,MATCH(34,Checklist!$K$5:$K$137,0)),"") | F37: =IFERROR(INDEX(Checklist!$D$5:$D$137,MATCH(34,Checklist!$K$5:$K$137,0)),"")
A38: 35 | B38: =IFERROR(INDEX(Checklist!$A$5:$A$137,MATCH(35,Checklist!$K$5:$K$137,0)),"") | C38: =IFERROR(INDEX(Checklist!$B$5:$B$137,MATCH(35,Checklist!$K$5:$K$137,0)),"") | D38: =IFERROR(INDEX(Checklist!$F$5:$F$137,MATCH(35,Checklist!$K$5:$K$137,0))&"","") | E38: =IFERROR(INDEX(Checklist!$L$5:$L$137,MATCH(35,Checklist!$K$5:$K$137,0)),"") | F38: =IFERROR(INDEX(Checklist!$D$5:$D$137,MATCH(35,Checklist!$K$5:$K$137,0)),"")
A39: 36 | B39: =IFERROR(INDEX(Checklist!$A$5:$A$137,MATCH(36,Checklist!$K$5:$K$137,0)),"") | C39: =IFERROR(INDEX(Checklist!$B$5:$B$137,MATCH(36,Checklist!$K$5:$K$137,0)),"") | D39: =IFERROR(INDEX(Checklist!$F$5:$F$137,MATCH(36,Checklist!$K$5:$K$137,0))&"","") | E39: =IFERROR(INDEX(Checklist!$L$5:$L$137,MATCH(36,Checklist!$K$5:$K$137,0)),"") | F39: =IFERROR(INDEX(Checklist!$D$5:$D$137,MATCH(36,Checklist!$K$5:$K$137,0)),"")
A40: 37 | B40: =IFERROR(INDEX(Checklist!$A$5:$A$137,MATCH(37,Checklist!$K$5:$K$137,0)),"") | C40: =IFERROR(INDEX(Checklist!$B$5:$B$137,MATCH(37,Checklist!$K$5:$K$137,0)),"") | D40: =IFERROR(INDEX(Checklist!$F$5:$F$137,MATCH(37,Checklist!$K$5:$K$137,0))&"","") | E40: =IFERROR(INDEX(Checklist!$L$5:$L$137,MATCH(37,Checklist!$K$5:$K$137,0)),"") | F40: =IFERROR(INDEX(Checklist!$D$5:$D$137,MATCH(37,Checklist!$K$5:$K$137,0)),"")
A41: 38 | B41: =IFERROR(INDEX(Checklist!$A$5:$A$137,MATCH(38,Checklist!$K$5:$K$137,0)),"") | C41: =IFERROR(INDEX(Checklist!$B$5:$B$137,MATCH(38,Checklist!$K$5:$K$137,0)),"") | D41: =IFERROR(INDEX(Checklist!$F$5:$F$137,MATCH(38,Checklist!$K$5:$K$137,0))&"","") | E41: =IFERROR(INDEX(Checklist!$L$5:$L$137,MATCH(38,Checklist!$K$5:$K$137,0)),"") | F41: =IFERROR(INDEX(Checklist!$D$5:$D$137,MATCH(38,Checklist!$K$5:$K$137,0)),"")
...

Sheet Sign-Off
A1: SIGN-OFF
A3: Role | B3: Name | C3: Signature | D3: Date
A4: Audit Lead
A5: System Owner
A6: CISO
A7: AI Governance Lead
