Workbook

Sheet Guide
A1: GT AI Risk Assessment Toolkit
A2: Companion to the GT AI Risk Assessment Framework (v1.1, 2026). Grant Thornton Bahrain - AI Governance, Risk & Compliance.
B4: Step 1 - Use Case Profile | C4: Document context: purpose, owners, lifecycle stage, organisation's role, stakeholders, data, vendors and applicable regulation (ISO 31000 cl.6.3; ISO/IEC 42005 cl.6).
B5: Step 2 - Prohibited Screen | C5: Screen against prohibited practices. Any 'Yes' stops the assessment and requires Legal review.
B6: Step 3 - Risk Tiering | C6: Rate 10 inherent-risk factors. The weighted score plus override rules produce the tier (Low / Medium / High / Critical), which determines assessment depth, approval authority and review frequency.
B7: Step 4 - Risk Register | C7: Work through the 52 taxonomy risks: mark applicability, tailor scenarios, rate likelihood & impact, evaluate existing control effectiveness (mapped to RCM v2.1 controls) and plan treatment. Add bespoke risks in rows BSP-01..10.
B8: Step 5 - Heat Map & Summary | C8: Review the inherent heat map, residual profile, top-10 residual risks and obtain sign-off from the approval authority required by the tier.
B9: Monitor & review | C9: Re-assess at the review frequency for the tier or on material change (model/provider change, new data, new purpose, expanded user base, incidents). Track KRIs listed per risk.
B10: Colour legend | C10: Yellow = input cell | Purple header = calculated / reference | Green/Amber/Orange/Red = Low / Medium / High / Critical
B11: Scoring logic | C11: Inherent score = Likelihood (1-5) x Impact (1-5). Residual score = Inherent score x control-effectiveness factor (Strong 0.4, Satisfactory 0.6, Needs improvement 0.8, Weak/None 1.0). Bands: Low 1-4, Medium 5-9, High 10-16, Critical 17-25. Residual Low/Medium = within appetite (default; calibrate to the organisation's approved AI risk appetite - RCM RM-6).

Sheet 1. Use Case Profile
A1: 1. AI Use Case Profile
A2: Establish the context (ISO 31000 cl.6.3 / ISO/IEC 23894 cl.6.3). Yellow cells are inputs.
B4: Organisation
B5: AI use case name
B6: Use case ID (AI register ref.)
B7: Business owner
B8: Technical owner
B9: Description & intended purpose
B10: Out-of-scope / prohibited uses
B11: AI system type
B12: Lifecycle stage
B13: Organisation's role (EU AI Act terminology)
B14: Affected stakeholders
B15: Data used (sources & categories)
... B19: Assessor(s)

Sheet 2. Prohibited Screen
A1: 2. Prohibited Practice Screening
A2: Answer every question. Any 'Yes' means the use case must not proceed without Legal review (EU AI Act Art. 5 - applicable since 2 Feb 2025; aligned with GCC AI Ethics Manual and Bahrain PDPL principles).
A4: # | B4: Does the AI system... | C4: Answer | D4: Reference
A5: 1 | B5: deploy subliminal, manipulative or deceptive techniques that materially distort behaviour and cause significant harm? | D5: EU AI Act Art. 5(1)(a)
A6: 2 | B6: exploit vulnerabilities due to age, disability or social/economic situation to distort behaviour causing significant harm? | D6: EU AI Act Art. 5(1)(b)
A7: 3 | B7: evaluate or classify people based on social behaviour or personal traits leading to detrimental or disproportionate treatment (social scoring)? | D7: EU AI Act Art. 5(1)(c)
A8: 4 | B8: assess the risk of a person committing a criminal offence based solely on profiling or personality traits? | D8: EU AI Act Art. 5(1)(d)
A9: 5 | B9: create or expand facial-recognition databases through untargeted scraping of images from the internet or CCTV? | D9: EU AI Act Art. 5(1)(e)
A10: 6 | B10: infer emotions of natural persons in the workplace or education institutions (except for medical or safety reasons)? | D10: EU AI Act Art. 5(1)(f)
A11: 7 | B11: categorise people by biometric data to infer race, political opinions, trade-union membership, religious beliefs, sex life or sexual orientation? | D11: EU AI Act Art. 5(1)(g)
A12: 8 | B12: perform real-time remote biometric identification in publicly accessible spaces for law-enforcement purposes? | D12: EU AI Act Art. 5(1)(h)
B14: Screening result | C14: =IF(COUNTA(C5:C12)<8,"Incomplete",IF(COUNTIF(C5:C12,"Yes")>0,"PROHIBITED","Pass")) -> Incomplete

Sheet 3. Risk Tiering
A1: 3. Inherent Risk Tiering
A2: Select the statement that best describes the use case for each factor. The weighted score (0-100) and override rules determine the inherent risk tier, which sets assessment depth, approval authority and review frequency (see Scales).
A4: # | B4: Factor | C4: Selected description (choose from list) | D4: Level (0-4) | E4: Weight | F4: Weighted
A5: T1 | B5: Impact of decisions on individuals | D5: =IF(C5="","",MATCH(C5,Lists!$L$1:$L$5,0)-1) | E5: 3 | F5: =IF(D5="","",D5*E5)
A6: T2 | B6: Autonomy & human oversight | D6: =IF(C6="","",MATCH(C6,Lists!$M$1:$M$5,0)-1) | E6: 3 | F6: =IF(D6="","",D6*E6)
A7: T3 | B7: Data sensitivity | D7: =IF(C7="","",MATCH(C7,Lists!$N$1:$N$5,0)-1) | E7: 2 | F7: =IF(D7="","",D7*E7)
A8: T4 | B8: Scale & reach | D8: =IF(C8="","",MATCH(C8,Lists!$O$1:$O$5,0)-1) | E8: 1 | F8: =IF(D8="","",D8*E8)
A9: T5 | B9: Reversibility of outcomes | D9: =IF(C9="","",MATCH(C9,Lists!$P$1:$P$5,0)-1) | E9: 2 | F9: =IF(D9="","",D9*E9)
A10: T6 | B10: Vulnerable groups affected | D10: =IF(C10="","",MATCH(C10,Lists!$Q$1:$Q$5,0)-1) | E10: 2 | F10: =IF(D10="","",D10*E10)
A11: T7 | B11: Regulatory classification & sector criticality | D11: =IF(C11="","",MATCH(C11,Lists!$R$1:$R$5,0)-1) | E11: 2 | F11: =IF(D11="","",D11*E11)
A12: T8 | B12: Technology novelty & opacity | D12: =IF(C12="","",MATCH(C12,Lists!$S$1:$S$5,0)-1) | E12: 1 | F12: =IF(D12="","",D12*E12)
A13: T9 | B13: External exposure | D13: =IF(C13="","",MATCH(C13,Lists!$T$1:$T$5,0)-1) | E13: 1 | F13: =IF(D13="","",D13*E13)
A14: T10 | B14: Third-party dependence | D14: =IF(C14="","",MATCH(C14,Lists!$U$1:$U$5,0)-1) | E14: 1 | F14: =IF(D14="","",D14*E14)
B16: Factors answered | C16: =COUNT(D5:D14)&" of 10" -> 0 of 10
B17: Weighted score (0-100) | C17: =IF(COUNT(D5:D14)<10,"",ROUND(SUM(F5:F14)/(4*SUM(E5:E14))*100,0))
B18: Score-based tier | C18: =IF(C17="","",IF(C17>=75,"Critical",IF(C17>=50,"High",IF(C17>=25,"Medium","Low"))))
B19: Override triggered | C19: =IF(C17="","",IF(AND(D5=4,D6=4),"Critical - significant decisions made autonomously",IF(OR(D5=4,D11=4),"Min. High - significant-effect decisions or high-risk classification",IF(AND(D5>=3,D6>=3),"Min. High - material decisions with limited oversight",IF(D7=4,"Min. Medium - sensitive data","None")))))
B20: Prohibited-practice screen | C20: ='2. Prohibited Screen'!C14 -> Incomplete
B21: FINAL INHERENT RISK TIER | C21: =IF(C20="PROHIBITED","Prohibited",IF(C17="","Incomplete",IF(LEFT(C19,8)="Critical","Critical",IF(AND(LEFT(C19,9)="Min. High",C18<>"Critical"),"High",IF(AND(LEFT(C19,11)="Min. Medium",C18="Low"),"Medium",C18))))) -> Incomplete
B22: Assessment requirements | C22: =IFERROR(VLOOKUP(C21,Scales!$A$36:$H$39,3,FALSE),IF(C21="Prohibited","Do not proceed. Refer to Legal and AI Committee.",""))
B23: Approval authority | C23: =IFERROR(VLOOKUP(C21,Scales!$A$36:$H$39,6,FALSE),IF(C21="Prohibited","Legal + Executive Committee",""))
B24: Review frequency | C24: =IFERROR(VLOOKUP(C21,Scales!$A$36:$H$39,8,FALSE),"")

Sheet 4. Risk Register
A1: 4. AI Risk Register
A2: Mark each taxonomy risk as applicable (Yes/No), tailor the scenario, rate inherent likelihood & impact, assess existing control effectiveness and define treatment. Scores, ratings and heat map update automatically. Add bespoke risks in the blank rows at the bottom.
A4: Applicable? | B4: Risk ID | C4: Category | D4: Risk | E4: Scenario (tailor to use case) | F4: Likelihood | G4: Impact | H4: Inherent score | I4: Inherent rating | J4: Existing / required controls (RCM v2.1) | K4: Control effectiveness | L4: Residual score | M4: Residual rating | N4: Within appetite? | O4: Treatment | P4: Treatment actions | Q4: Risk owner | R4: Due date | S4: Status | T4: KRI
B5: GOV-01 | C5: Governance & Accountability | D5: Unclear accountability for AI outcomes | E5: No named business or technical owner for an AI system; decisions and incidents cannot be attributed or escalated. | H5: =IF(OR($A5<>"Yes",F5="",G5=""),"",MATCH(F5,Lists!$B$1:$B$5,0)*MATCH(G5,Lists!$C$1:$C$5,0)) | I5: =IF(H5="","",IF(H5>=17,"Critical",IF(H5>=10,"High",IF(H5>=5,"Medium","Low")))) | J5: GL-1, GL-2, GL-8 | L5: =IF(OR(H5="",K5=""),"",ROUND(H5*VLOOKUP(K5,Scales!$A$22:$B$25,2,FALSE),1)) | M5: =IF(L5="","",IF(L5>=17,"Critical",IF(L5>=10,"High",IF(L5>=5,"Medium","Low")))) | N5: =IF(M5="","",IF(OR(M5="Low",M5="Medium"),"Yes","No")) | T5: % AI systems in register without named owner | V5: =IF(L5="","",L5+ROW()/100000)
B6: GOV-02 | C6: Governance & Accountability | D6: Shadow / unsanctioned AI use | E6: Staff use unapproved AI tools, bypassing risk assessment and exposing confidential data. | H6: =IF(OR($A6<>"Yes",F6="",G6=""),"",MATCH(F6,Lists!$B$1:$B$5,0)*MATCH(G6,Lists!$C$1:$C$5,0)) | I6: =IF(H6="","",IF(H6>=17,"Critical",IF(H6>=10,"High",IF(H6>=5,"Medium","Low")))) | J6: GL-5, GL-8 | L6: =IF(OR(H6="",K6=""),"",ROUND(H6*VLOOKUP(K6,Scales!$A$22:$B$25,2,FALSE),1)) | M6: =IF(L6="","",IF(L6>=17,"Critical",IF(L6>=10,"High",IF(L6>=5,"Medium","Low")))) | N6: =IF(M6="","",IF(OR(M6="Low",M6="Medium"),"Yes","No")) | T6: Unsanctioned AI services detected per month | V6: =IF(L6="","",L6+ROW()/100000)
B7: GOV-03 | C7: Governance & Accountability | D7: AI deployed without adequate risk assessment | E7: Use case moves to production without tiering, impact assessment or approval proportionate to risk. | H7: =IF(OR($A7<>"Yes",F7="",G7=""),"",MATCH(F7,Lists!$B$1:$B$5,0)*MATCH(G7,Lists!$C$1:$C$5,0)) | I7: =IF(H7="","",IF(H7>=17,"Critical",IF(H7>=10,"High",IF(H7>=5,"Medium","Low")))) | J7: RM-2, RM-5, GL-7 | L7: =IF(OR(H7="",K7=""),"",ROUND(H7*VLOOKUP(K7,Scales!$A$22:$B$25,2,FALSE),1)) | M7: =IF(L7="","",IF(L7>=17,"Critical",IF(L7>=10,"High",IF(L7>=5,"Medium","Low")))) | N7: =IF(M7="","",IF(OR(M7="Low",M7="Medium"),"Yes","No")) | T7: % production AI systems with current assessment | V7: =IF(L7="","",L7+ROW()/100000)
B8: GOV-04 | C8: Governance & Accountability | D8: Misaligned or low-value AI investment | E8: AI initiatives lack defined benefits, leading to wasted spend and continued investment in ineffective or risky solutions. | H8: =IF(OR($A8<>"Yes",F8="",G8=""),"",MATCH(F8,Lists!$B$1:$B$5,0)*MATCH(G8,Lists!$C$1:$C$5,0)) | I8: =IF(H8="","",IF(H8>=17,"Critical",IF(H8>=10,"High",IF(H8>=5,"Medium","Low")))) | J8: GL-3, GL-6 | L8: =IF(OR(H8="",K8=""),"",ROUND(H8*VLOOKUP(K8,Scales!$A$22:$B$25,2,FALSE),1)) | M8: =IF(L8="","",IF(L8>=17,"Critical",IF(L8>=10,"High",IF(L8>=5,"Medium","Low")))) | N8: =IF(M8="","",IF(OR(M8="Low",M8="Medium"),"Yes","No")) | T8: % AI initiatives meeting benefit KPIs | V8: =IF(L8="","",L8+ROW()/100000)
B9: LEG-01 | C9: Legal, Regulatory & Compliance | D9: Use of a prohibited AI practice | E9: AI system falls within a prohibited category (e.g., manipulative techniques, social scoring, workplace emotion recognition). | H9: =IF(OR($A9<>"Yes",F9="",G9=""),"",MATCH(F9,Lists!$B$1:$B$5,0)*MATCH(G9,Lists!$C$1:$C$5,0)) | I9: =IF(H9="","",IF(H9>=17,"Critical",IF(H9>=10,"High",IF(H9>=5,"Medium","Low")))) | J9: RM-5, RS-2 | L9: =IF(OR(H9="",K9=""),"",ROUND(H9*VLOOKUP(K9,Scales!$A$22:$B$25,2,FALSE),1)) | M9: =IF(L9="","",IF(L9>=17,"Critical",IF(L9>=10,"High",IF(L9>=5,"Medium","Low")))) | N9: =IF(M9="","",IF(OR(M9="Low",M9="Medium"),"Yes","No")) | T9: Number of use cases failing prohibited-practice screen | V9: =IF(L9="","",L9+ROW()/100000)
B10: LEG-02 | C10: Legal, Regulatory & Compliance | D10: Non-compliance with high-risk AI obligations | E10: Provider or deployer duties (risk management, data governance, logging, oversight, FRIA, registration) not met for a high-risk system. | H10: =IF(OR($A10<>"Yes",F10="",G10=""),"",MATCH(F10,Lists!$B$1:$B$5,0)*MATCH(G10,Lists!$C$1:$C$5,0)) | I10: =IF(H10="","",IF(H10>=17,"Critical",IF(H10>=10,"High",IF(H10>=5,"Medium","Low")))) | J10: RO-1, RO-6, RM-5 | L10: =IF(OR(H10="",K10=""),"",ROUND(H10*VLOOKUP(K10,Scales!$A$22:$B$25,2,FALSE),1)) | M10: =IF(L10="","",IF(L10>=17,"Critical",IF(L10>=10,"High",IF(L10>=5,"Medium","Low")))) | N10: =IF(M10="","",IF(OR(M10="Low",M10="Medium"),"Yes","No")) | T10: Open compliance gaps on high-risk systems | V10: =IF(L10="","",L10+ROW()/100000)
B11: LEG-03 | C11: Legal, Regulatory & Compliance | D11: Breach of sector or local regulation | E11: AI use breaches Bahrain PDPL, CBB Rulebook, iGA policy or other applicable regimes (incl. KSA/UAE where operating). | H11: =IF(OR($A11<>"Yes",F11="",G11=""),"",MATCH(F11,Lists!$B$1:$B$5,0)*MATCH(G11,Lists!$C$1:$C$5,0)) | I11: =IF(H11="","",IF(H11>=17,"Critical",IF(H11>=10,"High",IF(H11>=5,"Medium","Low")))) | J11: RO-5, PR-1, TP-3 | L11: =IF(OR(H11="",K11=""),"",ROUND(H11*VLOOKUP(K11,Scales!$A$22:$B$25,2,FALSE),1)) | M11: =IF(L11="","",IF(L11>=17,"Critical",IF(L11>=10,"High",IF(L11>=5,"Medium","Low")))) | N11: =IF(M11="","",IF(OR(M11="Low",M11="Medium"),"Yes","No")) | T11: Regulatory findings related to AI | V11: =IF(L11="","",L11+ROW()/100000)
B12: LEG-04 | C12: Legal, Regulatory & Compliance | D12: Intellectual property / copyright infringement | E12: Training data, prompts or outputs infringe third-party IP, licence terms or client confidentiality. | H12: =IF(OR($A12<>"Yes",F12="",G12=""),"",MATCH(F12,Lists!$B$1:$B$5,0)*MATCH(G12,Lists!$C$1:$C$5,0)) | I12: =IF(H12="","",IF(H12>=17,"Critical",IF(H12>=10,"High",IF(H12>=5,"Medium","Low")))) | J12: LC-11, LC-6 | L12: =IF(OR(H12="",K12=""),"",ROUND(H12*VLOOKUP(K12,Scales!$A$22:$B$25,2,FALSE),1)) | M12: =IF(L12="","",IF(L12>=17,"Critical",IF(L12>=10,"High",IF(L12>=5,"Medium","Low")))) | N12: =IF(M12="","",IF(OR(M12="Low",M12="Medium"),"Yes","No")) | T12: IP complaints / takedown requests | V12: =IF(L12="","",L12+ROW()/100000)
B13: LEG-05 | C13: Legal, Regulatory & Compliance | D13: Liability for AI-caused harm | E13: Organisation is liable for damage caused by AI outputs or actions (contractual, tort or product liability). | H13: =IF(OR($A13<>"Yes",F13="",G13=""),"",MATCH(F13,Lists!$B$1:$B$5,0)*MATCH(G13,Lists!$C$1:$C$5,0)) | I13: =IF(H13="","",IF(H13>=17,"Critical",IF(H13>=10,"High",IF(H13>=5,"Medium","Low")))) | J13: TP-3, CO-3, IM-2 | L13: =IF(OR(H13="",K13=""),"",ROUND(H13*VLOOKUP(K13,Scales!$A$22:$B$25,2,FALSE),1)) | M13: =IF(L13="","",IF(L13>=17,"Critical",IF(L13>=10,"High",IF(L13>=5,"Medium","Low")))) | N13: =IF(M13="","",IF(OR(M13="Low",M13="Medium"),"Yes","No")) | T13: Claims / complaints attributed to AI | V13: =IF(L13="","",L13+ROW()/100000)
B14: FAI-01 | C14: Fairness, Bias & Human Rights | D14: Discriminatory or biased outcomes | E14: Model produces systematically different outcomes for protected or vulnerable groups (e.g., gender, nationality, age). | H14: =IF(OR($A14<>"Yes",F14="",G14=""),"",MATCH(F14,Lists!$B$1:$B$5,0)*MATCH(G14,Lists!$C$1:$C$5,0)) | I14: =IF(H14="","",IF(H14>=17,"Critical",IF(H14>=10,"High",IF(H14>=5,"Medium","Low")))) | J14: RS-5, LC-1 | L14: =IF(OR(H14="",K14=""),"",ROUND(H14*VLOOKUP(K14,Scales!$A$22:$B$25,2,FALSE),1)) | M14: =IF(L14="","",IF(L14>=17,"Critical",IF(L14>=10,"High",IF(L14>=5,"Medium","Low")))) | N14: =IF(M14="","",IF(OR(M14="Low",M14="Medium"),"Yes","No")) | T14: Disparate impact ratio across cohorts | V14: =IF(L14="","",L14+ROW()/100000)
B15: FAI-02 | C15: Fairness, Bias & Human Rights | D15: Unrepresentative training or evaluation data | E15: Data does not reflect the population or context of use (e.g., Arabic dialects, local customer segments). | H15: =IF(OR($A15<>"Yes",F15="",G15=""),"",MATCH(F15,Lists!$B$1:$B$5,0)*MATCH(G15,Lists!$C$1:$C$5,0)) | I15: =IF(H15="","",IF(H15>=17,"Critical",IF(H15>=10,"High",IF(H15>=5,"Medium","Low")))) | J15: LC-1, RS-7 | L15: =IF(OR(H15="",K15=""),"",ROUND(H15*VLOOKUP(K15,Scales!$A$22:$B$25,2,FALSE),1)) | M15: =IF(L15="","",IF(L15>=17,"Critical",IF(L15>=10,"High",IF(L15>=5,"Medium","Low")))) | N15: =IF(M15="","",IF(OR(M15="Low",M15="Medium"),"Yes","No")) | T15: Coverage gaps by segment in evaluation set | V15: =IF(L15="","",L15+ROW()/100000)
B16: FAI-03 | C16: Fairness, Bias & Human Rights | D16: Infringement of fundamental rights / dignity | E16: AI use undermines autonomy, dignity, freedom of expression or access to essential services. | H16: =IF(OR($A16<>"Yes",F16="",G16=""),"",MATCH(F16,Lists!$B$1:$B$5,0)*MATCH(G16,Lists!$C$1:$C$5,0)) | I16: =IF(H16="","",IF(H16>=17,"Critical",IF(H16>=10,"High",IF(H16>=5,"Medium","Low")))) | J16: RM-2, RO-6 | L16: =IF(OR(H16="",K16=""),"",ROUND(H16*VLOOKUP(K16,Scales!$A$22:$B$25,2,FALSE),1)) | M16: =IF(L16="","",IF(L16>=17,"Critical",IF(L16>=10,"High",IF(L16>=5,"Medium","Low")))) | N16: =IF(M16="","",IF(OR(M16="Low",M16="Medium"),"Yes","No")) | T16: FRIAs outstanding for in-scope systems | V16: =IF(L16="","",L16+ROW()/100000)
... B56: SOC-04 | C56: Societal, Reputational & AI-Enabled Threats | D56: AI-accelerated cyber attacks | E56: Adversaries use AI for automated discovery, exploit chaining and scaled social engineering, outpacing defences. | H56: =IF(OR($A56<>"Yes",F56="",G56=""),"",MATCH(F56,Lists!$B$1:$B$5,0)*MATCH(G56,Lists!$C$1:$C$5,0)) | I56: =IF(H56="","",IF(H56>=17,"Critical",IF(H56>=10,"High",IF(H56>=5,"Medium","Low")))) | J56: AT-1, AT-2, AT-4 | L56: =IF(OR(H56="",K56=""),"",ROUND(H56*VLOOKUP(K56,Scales!$A$22:$B$25,2,FALSE),1)) | M56: =IF(L56="","",IF(L56>=17,"Critical",IF(L56>=10,"High",IF(L56>=5,"Medium","Low")))) | N56: =IF(M56="","",IF(OR(M56="Low",M56="Medium"),"Yes","No")) | T56: Mean time to remediate critical vulnerabilities | V56: =IF(L56="","",L56+ROW()/100000)
B57: BSP-01 | H57: =IF(OR($A57<>"Yes",F57="",G57=""),"",MATCH(F57,Lists!$B$1:$B$5,0)*MATCH(G57,Lists!$C$1:$C$5,0)) | I57: =IF(H57="","",IF(H57>=17,"Critical",IF(H57>=10,"High",IF(H57>=5,"Medium","Low")))) | L57: =IF(OR(H57="",K57=""),"",ROUND(H57*VLOOKUP(K57,Scales!$A$22:$B$25,2,FALSE),1)) | M57: =IF(L57="","",IF(L57>=17,"Critical",IF(L57>=10,"High",IF(L57>=5,"Medium","Low")))) | N57: =IF(M57="","",IF(OR(M57="Low",M57="Medium"),"Yes","No")) | V57: =IF(L57="","",L57+ROW()/100000)
B58: BSP-02 | H58: =IF(OR($A58<>"Yes",F58="",G58=""),"",MATCH(F58,Lists!$B$1:$B$5,0)*MATCH(G58,Lists!$C$1:$C$5,0)) | I58: =IF(H58="","",IF(H58>=17,"Critical",IF(H58>=10,"High",IF(H58>=5,"Medium","Low")))) | L58: =IF(OR(H58="",K58=""),"",ROUND(H58*VLOOKUP(K58,Scales!$A$22:$B$25,2,FALSE),1)) | M58: =IF(L58="","",IF(L58>=17,"Critical",IF(L58>=10,"High",IF(L58>=5,"Medium","Low")))) | N58: =IF(M58="","",IF(OR(M58="Low",M58="Medium"),"Yes","No")) | V58: =IF(L58="","",L58+ROW()/100000)
B59: BSP-03 | H59: =IF(OR($A59<>"Yes",F59="",G59=""),"",MATCH(F59,Lists!$B$1:$B$5,0)*MATCH(G59,Lists!$C$1:$C$5,0)) | I59: =IF(H59="","",IF(H59>=17,"Critical",IF(H59>=10,"High",IF(H59>=5,"Medium","Low")))) | L59: =IF(OR(H59="",K59=""),"",ROUND(H59*VLOOKUP(K59,Scales!$A$22:$B$25,2,FALSE),1)) | M59: =IF(L59="","",IF(L59>=17,"Critical",IF(L59>=10,"High",IF(L59>=5,"Medium","Low")))) | N59: =IF(M59="","",IF(OR(M59="Low",M59="Medium"),"Yes","No")) | V59: =IF(L59="","",L59+ROW()/100000)
B60: BSP-04 | H60: =IF(OR($A60<>"Yes",F60="",G60=""),"",MATCH(F60,Lists!$B$1:$B$5,0)*MATCH(G60,Lists!$C$1:$C$5,0)) | I60: =IF(H60="","",IF(H60>=17,"Critical",IF(H60>=10,"High",IF(H60>=5,"Medium","Low")))) | L60: =IF(OR(H60="",K60=""),"",ROUND(H60*VLOOKUP(K60,Scales!$A$22:$B$25,2,FALSE),1)) | M60: =IF(L60="","",IF(L60>=17,"Critical",IF(L60>=10,"High",IF(L60>=5,"Medium","Low")))) | N60: =IF(M60="","",IF(OR(M60="Low",M60="Medium"),"Yes","No")) | V60: =IF(L60="","",L60+ROW()/100000)
B61: BSP-05 | H61: =IF(OR($A61<>"Yes",F61="",G61=""),"",MATCH(F61,Lists!$B$1:$B$5,0)*MATCH(G61,Lists!$C$1:$C$5,0)) | I61: =IF(H61="","",IF(H61>=17,"Critical",IF(H61>=10,"High",IF(H61>=5,"Medium","Low")))) | L61: =IF(OR(H61="",K61=""),"",ROUND(H61*VLOOKUP(K61,Scales!$A$22:$B$25,2,FALSE),1)) | M61: =IF(L61="","",IF(L61>=17,"Critical",IF(L61>=10,"High",IF(L61>=5,"Medium","Low")))) | N61: =IF(M61="","",IF(OR(M61="Low",M61="Medium"),"Yes","No")) | V61: =IF(L61="","",L61+ROW()/100000)
B62: BSP-06 | H62: =IF(OR($A62<>"Yes",F62="",G62=""),"",MATCH(F62,Lists!$B$1:$B$5,0)*MATCH(G62,Lists!$C$1:$C$5,0)) | I62: =IF(H62="","",IF(H62>=17,"Critical",IF(H62>=10,"High",IF(H62>=5,"Medium","Low")))) | L62: =IF(OR(H62="",K62=""),"",ROUND(H62*VLOOKUP(K62,Scales!$A$22:$B$25,2,FALSE),1)) | M62: =IF(L62="","",IF(L62>=17,"Critical",IF(L62>=10,"High",IF(L62>=5,"Medium","Low")))) | N62: =IF(M62="","",IF(OR(M62="Low",M62="Medium"),"Yes","No")) | V62: =IF(L62="","",L62+ROW()/100000)
B63: BSP-07 | H63: =IF(OR($A63<>"Yes",F63="",G63=""),"",MATCH(F63,Lists!$B$1:$B$5,0)*MATCH(G63,Lists!$C$1:$C$5,0)) | I63: =IF(H63="","",IF(H63>=17,"Critical",IF(H63>=10,"High",IF(H63>=5,"Medium","Low")))) | L63: =IF(OR(H63="",K63=""),"",ROUND(H63*VLOOKUP(K63,Scales!$A$22:$B$25,2,FALSE),1)) | M63: =IF(L63="","",IF(L63>=17,"Critical",IF(L63>=10,"High",IF(L63>=5,"Medium","Low")))) | N63: =IF(M63="","",IF(OR(M63="Low",M63="Medium"),"Yes","No")) | V63: =IF(L63="","",L63+ROW()/100000)
B64: BSP-08 | H64: =IF(OR($A64<>"Yes",F64="",G64=""),"",MATCH(F64,Lists!$B$1:$B$5,0)*MATCH(G64,Lists!$C$1:$C$5,0)) | I64: =IF(H64="","",IF(H64>=17,"Critical",IF(H64>=10,"High",IF(H64>=5,"Medium","Low")))) | L64: =IF(OR(H64="",K64=""),"",ROUND(H64*VLOOKUP(K64,Scales!$A$22:$B$25,2,FALSE),1)) | M64: =IF(L64="","",IF(L64>=17,"Critical",IF(L64>=10,"High",IF(L64>=5,"Medium","Low")))) | N64: =IF(M64="","",IF(OR(M64="Low",M64="Medium"),"Yes","No")) | V64: =IF(L64="","",L64+ROW()/100000)
B65: BSP-09 | H65: =IF(OR($A65<>"Yes",F65="",G65=""),"",MATCH(F65,Lists!$B$1:$B$5,0)*MATCH(G65,Lists!$C$1:$C$5,0)) | I65: =IF(H65="","",IF(H65>=17,"Critical",IF(H65>=10,"High",IF(H65>=5,"Medium","Low")))) | L65: =IF(OR(H65="",K65=""),"",ROUND(H65*VLOOKUP(K65,Scales!$A$22:$B$25,2,FALSE),1)) | M65: =IF(L65="","",IF(L65>=17,"Critical",IF(L65>=10,"High",IF(L65>=5,"Medium","Low")))) | N65: =IF(M65="","",IF(OR(M65="Low",M65="Medium"),"Yes","No")) | V65: =IF(L65="","",L65+ROW()/100000)
B66: BSP-10 | H66: =IF(OR($A66<>"Yes",F66="",G66=""),"",MATCH(F66,Lists!$B$1:$B$5,0)*MATCH(G66,Lists!$C$1:$C$5,0)) | I66: =IF(H66="","",IF(H66>=17,"Critical",IF(H66>=10,"High",IF(H66>=5,"Medium","Low")))) | L66: =IF(OR(H66="",K66=""),"",ROUND(H66*VLOOKUP(K66,Scales!$A$22:$B$25,2,FALSE),1)) | M66: =IF(L66="","",IF(L66>=17,"Critical",IF(L66>=10,"High",IF(L66>=5,"Medium","Low")))) | N66: =IF(M66="","",IF(OR(M66="Low",M66="Medium"),"Yes","No")) | V66: =IF(L66="","",L66+ROW()/100000)

Sheet 5. Heat Map & Summary
A1: 5. Risk Profile - Heat Map & Summary
A2: ="Use case: "&IF('1. Use Case Profile'!$C$5="","(not specified)",'1. Use Case Profile'!$C$5)&" | Inherent tier: "&'3. Risk Tiering'!$C$21&" | Tiering score: "&'3. Risk Tiering'!$C$17 -> Use case: (not specified) | Inherent tier: Incomplete | Tiering score:
A4: Inherent risk heat map (number of applicable risks) | H4: Risk count by rating
B5: Insignificant | C5: Minor | D5: Moderate | E5: Major | F5: Severe | H5: Rating | I5: Inherent | J5: Residual
A6: Almost certain | B6: =COUNTIFS('4. Risk Register'!$A$5:$A$66,"Yes",'4. Risk Register'!$F$5:$F$66,"Almost certain",'4. Risk Register'!$G$5:$G$66,"Insignificant") -> 0 | C6: =COUNTIFS('4. Risk Register'!$A$5:$A$66,"Yes",'4. Risk Register'!$F$5:$F$66,"Almost certain",'4. Risk Register'!$G$5:$G$66,"Minor") -> 0 | D6: =COUNTIFS('4. Risk Register'!$A$5:$A$66,"Yes",'4. Risk Register'!$F$5:$F$66,"Almost certain",'4. Risk Register'!$G$5:$G$66,"Moderate") -> 0 | E6: =COUNTIFS('4. Risk Register'!$A$5:$A$66,"Yes",'4. Risk Register'!$F$5:$F$66,"Almost certain",'4. Risk Register'!$G$5:$G$66,"Major") -> 0 | F6: =COUNTIFS('4. Risk Register'!$A$5:$A$66,"Yes",'4. Risk Register'!$F$5:$F$66,"Almost certain",'4. Risk Register'!$G$5:$G$66,"Severe") -> 0 | H6: Critical | I6: =COUNTIF('4. Risk Register'!$I$5:$I$66,"Critical") -> 0 | J6: =COUNTIF('4. Risk Register'!$M$5:$M$66,"Critical") -> 0
A7: Likely | B7: =COUNTIFS('4. Risk Register'!$A$5:$A$66,"Yes",'4. Risk Register'!$F$5:$F$66,"Likely",'4. Risk Register'!$G$5:$G$66,"Insignificant") -> 0 | C7: =COUNTIFS('4. Risk Register'!$A$5:$A$66,"Yes",'4. Risk Register'!$F$5:$F$66,"Likely",'4. Risk Register'!$G$5:$G$66,"Minor") -> 0 | D7: =COUNTIFS('4. Risk Register'!$A$5:$A$66,"Yes",'4. Risk Register'!$F$5:$F$66,"Likely",'4. Risk Register'!$G$5:$G$66,"Moderate") -> 0 | E7: =COUNTIFS('4. Risk Register'!$A$5:$A$66,"Yes",'4. Risk Register'!$F$5:$F$66,"Likely",'4. Risk Register'!$G$5:$G$66,"Major") -> 0 | F7: =COUNTIFS('4. Risk Register'!$A$5:$A$66,"Yes",'4. Risk Register'!$F$5:$F$66,"Likely",'4. Risk Register'!$G$5:$G$66,"Severe") -> 0 | H7: High | I7: =COUNTIF('4. Risk Register'!$I$5:$I$66,"High") -> 0 | J7: =COUNTIF('4. Risk Register'!$M$5:$M$66,"High") -> 0
A8: Possible | B8: =COUNTIFS('4. Risk Register'!$A$5:$A$66,"Yes",'4. Risk Register'!$F$5:$F$66,"Possible",'4. Risk Register'!$G$5:$G$66,"Insignificant") -> 0 | C8: =COUNTIFS('4. Risk Register'!$A$5:$A$66,"Yes",'4. Risk Register'!$F$5:$F$66,"Possible",'4. Risk Register'!$G$5:$G$66,"Minor") -> 0 | D8: =COUNTIFS('4. Risk Register'!$A$5:$A$66,"Yes",'4. Risk Register'!$F$5:$F$66,"Possible",'4. Risk Register'!$G$5:$G$66,"Moderate") -> 0 | E8: =COUNTIFS('4. Risk Register'!$A$5:$A$66,"Yes",'4. Risk Register'!$F$5:$F$66,"Possible",'4. Risk Register'!$G$5:$G$66,"Major") -> 0 | F8: =COUNTIFS('4. Risk Register'!$A$5:$A$66,"Yes",'4. Risk Register'!$F$5:$F$66,"Possible",'4. Risk Register'!$G$5:$G$66,"Severe") -> 0 | H8: Medium | I8: =COUNTIF('4. Risk Register'!$I$5:$I$66,"Medium") -> 0 | J8: =COUNTIF('4. Risk Register'!$M$5:$M$66,"Medium") -> 0
A9: Unlikely | B9: =COUNTIFS('4. Risk Register'!$A$5:$A$66,"Yes",'4. Risk Register'!$F$5:$F$66,"Unlikely",'4. Risk Register'!$G$5:$G$66,"Insignificant") -> 0 | C9: =COUNTIFS('4. Risk Register'!$A$5:$A$66,"Yes",'4. Risk Register'!$F$5:$F$66,"Unlikely",'4. Risk Register'!$G$5:$G$66,"Minor") -> 0 | D9: =COUNTIFS('4. Risk Register'!$A$5:$A$66,"Yes",'4. Risk Register'!$F$5:$F$66,"Unlikely",'4. Risk Register'!$G$5:$G$66,"Moderate") -> 0 | E9: =COUNTIFS('4. Risk Register'!$A$5:$A$66,"Yes",'4. Risk Register'!$F$5:$F$66,"Unlikely",'4. Risk Register'!$G$5:$G$66,"Major") -> 0 | F9: =COUNTIFS('4. Risk Register'!$A$5:$A$66,"Yes",'4. Risk Register'!$F$5:$F$66,"Unlikely",'4. Risk Register'!$G$5:$G$66,"Severe") -> 0 | H9: Low | I9: =COUNTIF('4. Risk Register'!$I$5:$I$66,"Low") -> 0 | J9: =COUNTIF('4. Risk Register'!$M$5:$M$66,"Low") -> 0
A10: Rare | B10: =COUNTIFS('4. Risk Register'!$A$5:$A$66,"Yes",'4. Risk Register'!$F$5:$F$66,"Rare",'4. Risk Register'!$G$5:$G$66,"Insignificant") -> 0 | C10: =COUNTIFS('4. Risk Register'!$A$5:$A$66,"Yes",'4. Risk Register'!$F$5:$F$66,"Rare",'4. Risk Register'!$G$5:$G$66,"Minor") -> 0 | D10: =COUNTIFS('4. Risk Register'!$A$5:$A$66,"Yes",'4. Risk Register'!$F$5:$F$66,"Rare",'4. Risk Register'!$G$5:$G$66,"Moderate") -> 0 | E10: =COUNTIFS('4. Risk Register'!$A$5:$A$66,"Yes",'4. Risk Register'!$F$5:$F$66,"Rare",'4. Risk Register'!$G$5:$G$66,"Major") -> 0 | F10: =COUNTIFS('4. Risk Register'!$A$5:$A$66,"Yes",'4. Risk Register'!$F$5:$F$66,"Rare",'4. Risk Register'!$G$5:$G$66,"Severe") -> 0 | H10: Total rated | I10: =SUM(I6:I9) -> 0 | J10: =SUM(J6:J9) -> 0
A11: Likelihood / Impact | H11: Outside appetite (residual High/Critical) | J11: =J6+J7 -> 0
A14: Residual risk by category
A15: Category | D15: Applicable | E15: Critical | F15: High | G15: Medium | H15: Low | I15: Avg residual
A16: Governance & Accountability | D16: =COUNTIFS('4. Risk Register'!$C$5:$C$66,"Governance & Accountability",'4. Risk Register'!$A$5:$A$66,"Yes") -> 0 | E16: =COUNTIFS('4. Risk Register'!$C$5:$C$66,"Governance & Accountability",'4. Risk Register'!$M$5:$M$66,"Critical") -> 0 | F16: =COUNTIFS('4. Risk Register'!$C$5:$C$66,"Governance & Accountability",'4. Risk Register'!$M$5:$M$66,"High") -> 0 | G16: =COUNTIFS('4. Risk Register'!$C$5:$C$66,"Governance & Accountability",'4. Risk Register'!$M$5:$M$66,"Medium") -> 0 | H16: =COUNTIFS('4. Risk Register'!$C$5:$C$66,"Governance & Accountability",'4. Risk Register'!$M$5:$M$66,"Low") -> 0 | I16: =IFERROR(ROUND(AVERAGEIFS('4. Risk Register'!$L$5:$L$66,'4. Risk Register'!$C$5:$C$66,"Governance & Accountability",'4. Risk Register'!$A$5:$A$66,"Yes"),1),"-") -> -
A17: Legal, Regulatory & Compliance | D17: =COUNTIFS('4. Risk Register'!$C$5:$C$66,"Legal, Regulatory & Compliance",'4. Risk Register'!$A$5:$A$66,"Yes") -> 0 | E17: =COUNTIFS('4. Risk Register'!$C$5:$C$66,"Legal, Regulatory & Compliance",'4. Risk Register'!$M$5:$M$66,"Critical") -> 0 | F17: =COUNTIFS('4. Risk Register'!$C$5:$C$66,"Legal, Regulatory & Compliance",'4. Risk Register'!$M$5:$M$66,"High") -> 0 | G17: =COUNTIFS('4. Risk Register'!$C$5:$C$66,"Legal, Regulatory & Compliance",'4. Risk Register'!$M$5:$M$66,"Medium") -> 0 | H17: =COUNTIFS('4. Risk Register'!$C$5:$C$66,"Legal, Regulatory & Compliance",'4. Risk Register'!$M$5:$M$66,"Low") -> 0 | I17: =IFERROR(ROUND(AVERAGEIFS('4. Risk Register'!$L$5:$L$66,'4. Risk Register'!$C$5:$C$66,"Legal, Regulatory & Compliance",'4. Risk Register'!$A$5:$A$66,"Yes"),1),"-") -> -
A18: Fairness, Bias & Human Rights | D18: =COUNTIFS('4. Risk Register'!$C$5:$C$66,"Fairness, Bias & Human Rights",'4. Risk Register'!$A$5:$A$66,"Yes") -> 0 | E18: =COUNTIFS('4. Risk Register'!$C$5:$C$66,"Fairness, Bias & Human Rights",'4. Risk Register'!$M$5:$M$66,"Critical") -> 0 | F18: =COUNTIFS('4. Risk Register'!$C$5:$C$66,"Fairness, Bias & Human Rights",'4. Risk Register'!$M$5:$M$66,"High") -> 0 | G18: =COUNTIFS('4. Risk Register'!$C$5:$C$66,"Fairness, Bias & Human Rights",'4. Risk Register'!$M$5:$M$66,"Medium") -> 0 | H18: =COUNTIFS('4. Risk Register'!$C$5:$C$66,"Fairness, Bias & Human Rights",'4. Risk Register'!$M$5:$M$66,"Low") -> 0 | I18: =IFERROR(ROUND(AVERAGEIFS('4. Risk Register'!$L$5:$L$66,'4. Risk Register'!$C$5:$C$66,"Fairness, Bias & Human Rights",'4. Risk Register'!$A$5:$A$66,"Yes"),1),"-") -> -
A19: Privacy & Data Protection | D19: =COUNTIFS('4. Risk Register'!$C$5:$C$66,"Privacy & Data Protection",'4. Risk Register'!$A$5:$A$66,"Yes") -> 0 | E19: =COUNTIFS('4. Risk Register'!$C$5:$C$66,"Privacy & Data Protection",'4. Risk Register'!$M$5:$M$66,"Critical") -> 0 | F19: =COUNTIFS('4. Risk Register'!$C$5:$C$66,"Privacy & Data Protection",'4. Risk Register'!$M$5:$M$66,"High") -> 0 | G19: =COUNTIFS('4. Risk Register'!$C$5:$C$66,"Privacy & Data Protection",'4. Risk Register'!$M$5:$M$66,"Medium") -> 0 | H19: =COUNTIFS('4. Risk Register'!$C$5:$C$66,"Privacy & Data Protection",'4. Risk Register'!$M$5:$M$66,"Low") -> 0 | I19: =IFERROR(ROUND(AVERAGEIFS('4. Risk Register'!$L$5:$L$66,'4. Risk Register'!$C$5:$C$66,"Privacy & Data Protection",'4. Risk Register'!$A$5:$A$66,"Yes"),1),"-") -> -
A20: Data Quality & Integrity | D20: =COUNTIFS('4. Risk Register'!$C$5:$C$66,"Data Quality & Integrity",'4. Risk Register'!$A$5:$A$66,"Yes") -> 0 | E20: =COUNTIFS('4. Risk Register'!$C$5:$C$66,"Data Quality & Integrity",'4. Risk Register'!$M$5:$M$66,"Critical") -> 0 | F20: =COUNTIFS('4. Risk Register'!$C$5:$C$66,"Data Quality & Integrity",'4. Risk Register'!$M$5:$M$66,"High") -> 0 | G20: =COUNTIFS('4. Risk Register'!$C$5:$C$66,"Data Quality & Integrity",'4. Risk Register'!$M$5:$M$66,"Medium") -> 0 | H20: =COUNTIFS('4. Risk Register'!$C$5:$C$66,"Data Quality & Integrity",'4. Risk Register'!$M$5:$M$66,"Low") -> 0 | I20: =IFERROR(ROUND(AVERAGEIFS('4. Risk Register'!$L$5:$L$66,'4. Risk Register'!$C$5:$C$66,"Data Quality & Integrity",'4. Risk Register'!$A$5:$A$66,"Yes"),1),"-") -> -
A21: Model Performance, Reliability & Robustness | D21: =COUNTIFS('4. Risk Register'!$C$5:$C$66,"Model Performance, Reliability & Robustness",'4. Risk Register'!$A$5:$A$66,"Yes") -> 0 | E21: =COUNTIFS('4. Risk Register'!$C$5:$C$66,"Model Performance, Reliability & Robustness",'4. Risk Register'!$M$5:$M$66,"Critical") -> 0 | F21: =COUNTIFS('4. Risk Register'!$C$5:$C$66,"Model Performance, Reliability & Robustness",'4. Risk Register'!$M$5:$M$66,"High") -> 0 | G21: =COUNTIFS('4. Risk Register'!$C$5:$C$66,"Model Performance, Reliability & Robustness",'4. Risk Register'!$M$5:$M$66,"Medium") -> 0 | H21: =COUNTIFS('4. Risk Register'!$C$5:$C$66,"Model Performance, Reliability & Robustness",'4. Risk Register'!$M$5:$M$66,"Low") -> 0 | I21: =IFERROR(ROUND(AVERAGEIFS('4. Risk Register'!$L$5:$L$66,'4. Risk Register'!$C$5:$C$66,"Model Performance, Reliability & Robustness",'4. Risk Register'!$A$5:$A$66,"Yes"),1),"-") -> -
A22: Transparency, Explainability & Contestability | D22: =COUNTIFS('4. Risk Register'!$C$5:$C$66,"Transparency, Explainability & Contestability",'4. Risk Register'!$A$5:$A$66,"Yes") -> 0 | E22: =COUNTIFS('4. Risk Register'!$C$5:$C$66,"Transparency, Explainability & Contestability",'4. Risk Register'!$M$5:$M$66,"Critical") -> 0 | F22: =COUNTIFS('4. Risk Register'!$C$5:$C$66,"Transparency, Explainability & Contestability",'4. Risk Register'!$M$5:$M$66,"High") -> 0 | G22: =COUNTIFS('4. Risk Register'!$C$5:$C$66,"Transparency, Explainability & Contestability",'4. Risk Register'!$M$5:$M$66,"Medium") -> 0 | H22: =COUNTIFS('4. Risk Register'!$C$5:$C$66,"Transparency, Explainability & Contestability",'4. Risk Register'!$M$5:$M$66,"Low") -> 0 | I22: =IFERROR(ROUND(AVERAGEIFS('4. Risk Register'!$L$5:$L$66,'4. Risk Register'!$C$5:$C$66,"Transparency, Explainability & Contestability",'4. Risk Register'!$A$5:$A$66,"Yes"),1),"-") -> -
A23: Security of AI Systems | D23: =COUNTIFS('4. Risk Register'!$C$5:$C$66,"Security of AI Systems",'4. Risk Register'!$A$5:$A$66,"Yes") -> 0 | E23: =COUNTIFS('4. Risk Register'!$C$5:$C$66,"Security of AI Systems",'4. Risk Register'!$M$5:$M$66,"Critical") -> 0 | F23: =COUNTIFS('4. Risk Register'!$C$5:$C$66,"Security of AI Systems",'4. Risk Register'!$M$5:$M$66,"High") -> 0 | G23: =COUNTIFS('4. Risk Register'!$C$5:$C$66,"Security of AI Systems",'4. Risk Register'!$M$5:$M$66,"Medium") -> 0 | H23: =COUNTIFS('4. Risk Register'!$C$5:$C$66,"Security of AI Systems",'4. Risk Register'!$M$5:$M$66,"Low") -> 0 | I23: =IFERROR(ROUND(AVERAGEIFS('4. Risk Register'!$L$5:$L$66,'4. Risk Register'!$C$5:$C$66,"Security of AI Systems",'4. Risk Register'!$A$5:$A$66,"Yes"),1),"-") -> -
A24: Human Oversight & Autonomy | D24: =COUNTIFS('4. Risk Register'!$C$5:$C$66,"Human Oversight & Autonomy",'4. Risk Register'!$A$5:$A$66,"Yes") -> 0 | E24: =COUNTIFS('4. Risk Register'!$C$5:$C$66,"Human Oversight & Autonomy",'4. Risk Register'!$M$5:$M$66,"Critical") -> 0 | F24: =COUNTIFS('4. Risk Register'!$C$5:$C$66,"Human Oversight & Autonomy",'4. Risk Register'!$M$5:$M$66,"High") -> 0 | G24: =COUNTIFS('4. Risk Register'!$C$5:$C$66,"Human Oversight & Autonomy",'4. Risk Register'!$M$5:$M$66,"Medium") -> 0 | H24: =COUNTIFS('4. Risk Register'!$C$5:$C$66,"Human Oversight & Autonomy",'4. Risk Register'!$M$5:$M$66,"Low") -> 0 | I24: =IFERROR(ROUND(AVERAGEIFS('4. Risk Register'!$L$5:$L$66,'4. Risk Register'!$C$5:$C$66,"Human Oversight & Autonomy",'4. Risk Register'!$A$5:$A$66,"Yes"),1),"-") -> -
A25: Third-Party & Supply Chain | D25: =COUNTIFS('4. Risk Register'!$C$5:$C$66,"Third-Party & Supply Chain",'4. Risk Register'!$A$5:$A$66,"Yes") -> 0 | E25: =COUNTIFS('4. Risk Register'!$C$5:$C$66,"Third-Party & Supply Chain",'4. Risk Register'!$M$5:$M$66,"Critical") -> 0 | F25: =COUNTIFS('4. Risk Register'!$C$5:$C$66,"Third-Party & Supply Chain",'4. Risk Register'!$M$5:$M$66,"High") -> 0 | G25: =COUNTIFS('4. Risk Register'!$C$5:$C$66,"Third-Party & Supply Chain",'4. Risk Register'!$M$5:$M$66,"Medium") -> 0 | H25: =COUNTIFS('4. Risk Register'!$C$5:$C$66,"Third-Party & Supply Chain",'4. Risk Register'!$M$5:$M$66,"Low") -> 0 | I25: =IFERROR(ROUND(AVERAGEIFS('4. Risk Register'!$L$5:$L$66,'4. Risk Register'!$C$5:$C$66,"Third-Party & Supply Chain",'4. Risk Register'!$A$5:$A$66,"Yes"),1),"-") -> -
A26: Operational, Financial & Sustainability | D26: =COUNTIFS('4. Risk Register'!$C$5:$C$66,"Operational, Financial & Sustainability",'4. Risk Register'!$A$5:$A$66,"Yes") -> 0 | E26: =COUNTIFS('4. Risk Register'!$C$5:$C$66,"Operational, Financial & Sustainability",'4. Risk Register'!$M$5:$M$66,"Critical") -> 0 | F26: =COUNTIFS('4. Risk Register'!$C$5:$C$66,"Operational, Financial & Sustainability",'4. Risk Register'!$M$5:$M$66,"High") -> 0 | G26: =COUNTIFS('4. Risk Register'!$C$5:$C$66,"Operational, Financial & Sustainability",'4. Risk Register'!$M$5:$M$66,"Medium") -> 0 | H26: =COUNTIFS('4. Risk Register'!$C$5:$C$66,"Operational, Financial & Sustainability",'4. Risk Register'!$M$5:$M$66,"Low") -> 0 | I26: =IFERROR(ROUND(AVERAGEIFS('4. Risk Register'!$L$5:$L$66,'4. Risk Register'!$C$5:$C$66,"Operational, Financial & Sustainability",'4. Risk Register'!$A$5:$A$66,"Yes"),1),"-") -> -
A27: Societal, Reputational & AI-Enabled Threats | D27: =COUNTIFS('4. Risk Register'!$C$5:$C$66,"Societal, Reputational & AI-Enabled Threats",'4. Risk Register'!$A$5:$A$66,"Yes") -> 0 | E27: =COUNTIFS('4. Risk Register'!$C$5:$C$66,"Societal, Reputational & AI-Enabled Threats",'4. Risk Register'!$M$5:$M$66,"Critical") -> 0 | F27: =COUNTIFS('4. Risk Register'!$C$5:$C$66,"Societal, Reputational & AI-Enabled Threats",'4. Risk Register'!$M$5:$M$66,"High") -> 0 | G27: =COUNTIFS('4. Risk Register'!$C$5:$C$66,"Societal, Reputational & AI-Enabled Threats",'4. Risk Register'!$M$5:$M$66,"Medium") -> 0 | H27: =COUNTIFS('4. Risk Register'!$C$5:$C$66,"Societal, Reputational & AI-Enabled Threats",'4. Risk Register'!$M$5:$M$66,"Low") -> 0 | I27: =IFERROR(ROUND(AVERAGEIFS('4. Risk Register'!$L$5:$L$66,'4. Risk Register'!$C$5:$C$66,"Societal, Reputational & AI-Enabled Threats",'4. Risk Register'!$A$5:$A$66,"Yes"),1),"-") -> -
A30: Top 10 residual risks (highest residual score)
A31: Rank | B31: Risk ID | C31: Risk | G31: Residual score | H31: Residual rating | I31: Treatment | J31: Owner | K31: Status
A32: 1 | B32: =IFERROR(INDEX('4. Risk Register'!$B$5:$B$66,MATCH(LARGE('4. Risk Register'!$V$5:$V$66,1),'4. Risk Register'!$V$5:$V$66,0)),"") | C32: =IFERROR(INDEX('4. Risk Register'!$D$5:$D$66,MATCH(LARGE('4. Risk Register'!$V$5:$V$66,1),'4. Risk Register'!$V$5:$V$66,0)),"") | G32: =IFERROR(INDEX('4. Risk Register'!$L$5:$L$66,MATCH(LARGE('4. Risk Register'!$V$5:$V$66,1),'4. Risk Register'!$V$5:$V$66,0)),"") | H32: =IFERROR(INDEX('4. Risk Register'!$M$5:$M$66,MATCH(LARGE('4. Risk Register'!$V$5:$V$66,1),'4. Risk Register'!$V$5:$V$66,0)),"") | I32: =IFERROR(INDEX('4. Risk Register'!$O$5:$O$66,MATCH(LARGE('4. Risk Register'!$V$5:$V$66,1),'4. Risk Register'!$V$5:$V$66,0)),"") | J32: =IFERROR(INDEX('4. Risk Register'!$Q$5:$Q$66,MATCH(LARGE('4. Risk Register'!$V$5:$V$66,1),'4. Risk Register'!$V$5:$V$66,0)),"") | K32: =IFERROR(INDEX('4. Risk Register'!$S$5:$S$66,MATCH(LARGE('4. Risk Register'!$V$5:$V$66,1),'4. Risk Register'!$V$5:$V$66,0)),"")
A33: 2 | B33: =IFERROR(INDEX('4. Risk Register'!$B$5:$B$66,MATCH(LARGE('4. Risk Register'!$V$5:$V$66,2),'4. Risk Register'!$V$5:$V$66,0)),"") | C33: =IFERROR(INDEX('4. Risk Register'!$D$5:$D$66,MATCH(LARGE('4. Risk Register'!$V$5:$V$66,2),'4. Risk Register'!$V$5:$V$66,0)),"") | G33: =IFERROR(INDEX('4. Risk Register'!$L$5:$L$66,MATCH(LARGE('4. Risk Register'!$V$5:$V$66,2),'4. Risk Register'!$V$5:$V$66,0)),"") | H33: =IFERROR(INDEX('4. Risk Register'!$M$5:$M$66,MATCH(LARGE('4. Risk Register'!$V$5:$V$66,2),'4. Risk Register'!$V$5:$V$66,0)),"") | I33: =IFERROR(INDEX('4. Risk Register'!$O$5:$O$66,MATCH(LARGE('4. Risk Register'!$V$5:$V$66,2),'4. Risk Register'!$V$5:$V$66,0)),"") | J33: =IFERROR(INDEX('4. Risk Register'!$Q$5:$Q$66,MATCH(LARGE('4. Risk Register'!$V$5:$V$66,2),'4. Risk Register'!$V$5:$V$66,0)),"") | K33: =IFERROR(INDEX('4. Risk Register'!$S$5:$S$66,MATCH(LARGE('4. Risk Register'!$V$5:$V$66,2),'4. Risk Register'!$V$5:$V$66,0)),"")
A34: 3 | B34: =IFERROR(INDEX('4. Risk Register'!$B$5:$B$66,MATCH(LARGE('4. Risk Register'!$V$5:$V$66,3),'4. Risk Register'!$V$5:$V$66,0)),"") | C34: =IFERROR(INDEX('4. Risk Register'!$D$5:$D$66,MATCH(LARGE('4. Risk Register'!$V$5:$V$66,3),'4. Risk Register'!$V$5:$V$66,0)),"") | G34: =IFERROR(INDEX('4. Risk Register'!$L$5:$L$66,MATCH(LARGE('4. Risk Register'!$V$5:$V$66,3),'4. Risk Register'!$V$5:$V$66,0)),"") | H34: =IFERROR(INDEX('4. Risk Register'!$M$5:$M$66,MATCH(LARGE('4. Risk Register'!$V$5:$V$66,3),'4. Risk Register'!$V$5:$V$66,0)),"") | I34: =IFERROR(INDEX('4. Risk Register'!$O$5:$O$66,MATCH(LARGE('4. Risk Register'!$V$5:$V$66,3),'4. Risk Register'!$V$5:$V$66,0)),"") | J34: =IFERROR(INDEX('4. Risk Register'!$Q$5:$Q$66,MATCH(LARGE('4. Risk Register'!$V$5:$V$66,3),'4. Risk Register'!$V$5:$V$66,0)),"") | K34: =IFERROR(INDEX('4. Risk Register'!$S$5:$S$66,MATCH(LARGE('4. Risk Register'!$V$5:$V$66,3),'4. Risk Register'!$V$5:$V$66,0)),"")
A35: 4 | B35: =IFERROR(INDEX('4. Risk Register'!$B$5:$B$66,MATCH(LARGE('4. Risk Register'!$V$5:$V$66,4),'4. Risk Register'!$V$5:$V$66,0)),"") | C35: =IFERROR(INDEX('4. Risk Register'!$D$5:$D$66,MATCH(LARGE('4. Risk Register'!$V$5:$V$66,4),'4. Risk Register'!$V$5:$V$66,0)),"") | G35: =IFERROR(INDEX('4. Risk Register'!$L$5:$L$66,MATCH(LARGE('4. Risk Register'!$V$5:$V$66,4),'4. Risk Register'!$V$5:$V$66,0)),"") | H35: =IFERROR(INDEX('4. Risk Register'!$M$5:$M$66,MATCH(LARGE('4. Risk Register'!$V$5:$V$66,4),'4. Risk Register'!$V$5:$V$66,0)),"") | I35: =IFERROR(INDEX('4. Risk Register'!$O$5:$O$66,MATCH(LARGE('4. Risk Register'!$V$5:$V$66,4),'4. Risk Register'!$V$5:$V$66,0)),"") | J35: =IFERROR(INDEX('4. Risk Register'!$Q$5:$Q$66,MATCH(LARGE('4. Risk Register'!$V$5:$V$66,4),'4. Risk Register'!$V$5:$V$66,0)),"") | K35: =IFERROR(INDEX('4. Risk Register'!$S$5:$S$66,MATCH(LARGE('4. Risk Register'!$V$5:$V$66,4),'4. Risk Register'!$V$5:$V$66,0)),"")
A36: 5 | B36: =IFERROR(INDEX('4. Risk Register'!$B$5:$B$66,MATCH(LARGE('4. Risk Register'!$V$5:$V$66,5),'4. Risk Register'!$V$5:$V$66,0)),"") | C36: =IFERROR(INDEX('4. Risk Register'!$D$5:$D$66,MATCH(LARGE('4. Risk Register'!$V$5:$V$66,5),'4. Risk Register'!$V$5:$V$66,0)),"") | G36: =IFERROR(INDEX('4. Risk Register'!$L$5:$L$66,MATCH(LARGE('4. Risk Register'!$V$5:$V$66,5),'4. Risk Register'!$V$5:$V$66,0)),"") | H36: =IFERROR(INDEX('4. Risk Register'!$M$5:$M$66,MATCH(LARGE('4. Risk Register'!$V$5:$V$66,5),'4. Risk Register'!$V$5:$V$66,0)),"") | I36: =IFERROR(INDEX('4. Risk Register'!$O$5:$O$66,MATCH(LARGE('4. Risk Register'!$V$5:$V$66,5),'4. Risk Register'!$V$5:$V$66,0)),"") | J36: =IFERROR(INDEX('4. Risk Register'!$Q$5:$Q$66,MATCH(LARGE('4. Risk Register'!$V$5:$V$66,5),'4. Risk Register'!$V$5:$V$66,0)),"") | K36: =IFERROR(INDEX('4. Risk Register'!$S$5:$S$66,MATCH(LARGE('4. Risk Register'!$V$5:$V$66,5),'4. Risk Register'!$V$5:$V$66,0)),"")
A37: 6 | B37: =IFERROR(INDEX('4. Risk Register'!$B$5:$B$66,MATCH(LARGE('4. Risk Register'!$V$5:$V$66,6),'4. Risk Register'!$V$5:$V$66,0)),"") | C37: =IFERROR(INDEX('4. Risk Register'!$D$5:$D$66,MATCH(LARGE('4. Risk Register'!$V$5:$V$66,6),'4. Risk Register'!$V$5:$V$66,0)),"") | G37: =IFERROR(INDEX('4. Risk Register'!$L$5:$L$66,MATCH(LARGE('4. Risk Register'!$V$5:$V$66,6),'4. Risk Register'!$V$5:$V$66,0)),"") | H37: =IFERROR(INDEX('4. Risk Register'!$M$5:$M$66,MATCH(LARGE('4. Risk Register'!$V$5:$V$66,6),'4. Risk Register'!$V$5:$V$66,0)),"") | I37: =IFERROR(INDEX('4. Risk Register'!$O$5:$O$66,MATCH(LARGE('4. Risk Register'!$V$5:$V$66,6),'4. Risk Register'!$V$5:$V$66,0)),"") | J37: =IFERROR(INDEX('4. Risk Register'!$Q$5:$Q$66,MATCH(LARGE('4. Risk Register'!$V$5:$V$66,6),'4. Risk Register'!$V$5:$V$66,0)),"") | K37: =IFERROR(INDEX('4. Risk Register'!$S$5:$S$66,MATCH(LARGE('4. Risk Register'!$V$5:$V$66,6),'4. Risk Register'!$V$5:$V$66,0)),"")
A38: 7 | B38: =IFERROR(INDEX('4. Risk Register'!$B$5:$B$66,MATCH(LARGE('4. Risk Register'!$V$5:$V$66,7),'4. Risk Register'!$V$5:$V$66,0)),"") | C38: =IFERROR(INDEX('4. Risk Register'!$D$5:$D$66,MATCH(LARGE('4. Risk Register'!$V$5:$V$66,7),'4. Risk Register'!$V$5:$V$66,0)),"") | G38: =IFERROR(INDEX('4. Risk Register'!$L$5:$L$66,MATCH(LARGE('4. Risk Register'!$V$5:$V$66,7),'4. Risk Register'!$V$5:$V$66,0)),"") | H38: =IFERROR(INDEX('4. Risk Register'!$M$5:$M$66,MATCH(LARGE('4. Risk Register'!$V$5:$V$66,7),'4. Risk Register'!$V$5:$V$66,0)),"") | I38: =IFERROR(INDEX('4. Risk Register'!$O$5:$O$66,MATCH(LARGE('4. Risk Register'!$V$5:$V$66,7),'4. Risk Register'!$V$5:$V$66,0)),"") | J38: =IFERROR(INDEX('4. Risk Register'!$Q$5:$Q$66,MATCH(LARGE('4. Risk Register'!$V$5:$V$66,7),'4. Risk Register'!$V$5:$V$66,0)),"") | K38: =IFERROR(INDEX('4. Risk Register'!$S$5:$S$66,MATCH(LARGE('4. Risk Register'!$V$5:$V$66,7),'4. Risk Register'!$V$5:$V$66,0)),"")
A39: 8 | B39: =IFERROR(INDEX('4. Risk Register'!$B$5:$B$66,MATCH(LARGE('4. Risk Register'!$V$5:$V$66,8),'4. Risk Register'!$V$5:$V$66,0)),"") | C39: =IFERROR(INDEX('4. Risk Register'!$D$5:$D$66,MATCH(LARGE('4. Risk Register'!$V$5:$V$66,8),'4. Risk Register'!$V$5:$V$66,0)),"") | G39: =IFERROR(INDEX('4. Risk Register'!$L$5:$L$66,MATCH(LARGE('4. Risk Register'!$V$5:$V$66,8),'4. Risk Register'!$V$5:$V$66,0)),"") | H39: =IFERROR(INDEX('4. Risk Register'!$M$5:$M$66,MATCH(LARGE('4. Risk Register'!$V$5:$V$66,8),'4. Risk Register'!$V$5:$V$66,0)),"") | I39: =IFERROR(INDEX('4. Risk Register'!$O$5:$O$66,MATCH(LARGE('4. Risk Register'!$V$5:$V$66,8),'4. Risk Register'!$V$5:$V$66,0)),"") | J39: =IFERROR(INDEX('4. Risk Register'!$Q$5:$Q$66,MATCH(LARGE('4. Risk Register'!$V$5:$V$66,8),'4. Risk Register'!$V$5:$V$66,0)),"") | K39: =IFERROR(INDEX('4. Risk Register'!$S$5:$S$66,MATCH(LARGE('4. Risk Register'!$V$5:$V$66,8),'4. Risk Register'!$V$5:$V$66,0)),"")
A40: 9 | B40: =IFERROR(INDEX('4. Risk Register'!$B$5:$B$66,MATCH(LARGE('4. Risk Register'!$V$5:$V$66,9),'4. Risk Register'!$V$5:$V$66,0)),"") | C40: =IFERROR(INDEX('4. Risk Register'!$D$5:$D$66,MATCH(LARGE('4. Risk Register'!$V$5:$V$66,9),'4. Risk Register'!$V$5:$V$66,0)),"") | G40: =IFERROR(INDEX('4. Risk Register'!$L$5:$L$66,MATCH(LARGE('4. Risk Register'!$V$5:$V$66,9),'4. Risk Register'!$V$5:$V$66,0)),"") | H40: =IFERROR(INDEX('4. Risk Register'!$M$5:$M$66,MATCH(LARGE('4. Risk Register'!$V$5:$V$66,9),'4. Risk Register'!$V$5:$V$66,0)),"") | I40: =IFERROR(INDEX('4. Risk Register'!$O$5:$O$66,MATCH(LARGE('4. Risk Register'!$V$5:$V$66,9),'4. Risk Register'!$V$5:$V$66,0)),"") | J40: =IFERROR(INDEX('4. Risk Register'!$Q$5:$Q$66,MATCH(LARGE('4. Risk Register'!$V$5:$V$66,9),'4. Risk Register'!$V$5:$V$66,0)),"") | K40: =IFERROR(INDEX('4. Risk Register'!$S$5:$S$66,MATCH(LARGE('4. Risk Register'!$V$5:$V$66,9),'4. Risk Register'!$V$5:$V$66,0)),"")
A41: 10 | B41: =IFERROR(INDEX('4. Risk Register'!$B$5:$B$66,MATCH(LARGE('4. Risk Register'!$V$5:$V$66,10),'4. Risk Register'!$V$5:$V$66,0)),"") | C41: =IFERROR(INDEX('4. Risk Register'!$D$5:$D$66,MATCH(LARGE('4. Risk Register'!$V$5:$V$66,10),'4. Risk Register'!$V$5:$V$66,0)),"") | G41: =IFERROR(INDEX('4. Risk Register'!$L$5:$L$66,MATCH(LARGE('4. Risk Register'!$V$5:$V$66,10),'4. Risk Register'!$V$5:$V$66,0)),"") | H41: =IFERROR(INDEX('4. Risk Register'!$M$5:$M$66,MATCH(LARGE('4. Risk Register'!$V$5:$V$66,10),'4. Risk Register'!$V$5:$V$66,0)),"") | I41: =IFERROR(INDEX('4. Risk Register'!$O$5:$O$66,MATCH(LARGE('4. Risk Register'!$V$5:$V$66,10),'4. Risk Register'!$V$5:$V$66,0)),"") | J41: =IFERROR(INDEX('4. Risk Register'!$Q$5:$Q$66,MATCH(LARGE('4. Risk Register'!$V$5:$V$66,10),'4. Risk Register'!$V$5:$V$66,0)),"") | K41: =IFERROR(INDEX('4. Risk Register'!$S$5:$S$66,MATCH(LARGE('4. Risk Register'!$V$5:$V$66,10),'4. Risk Register'!$V$5:$V$66,0)),"")
A43: Approval & sign-off
A44: Required approval authority: | D44: ='3. Risk Tiering'!C23
A45: Role | D45: Name | G45: Decision (Approve / Approve with conditions / Reject) | J45: Date
A46: Use-case / business owner
...

Sheet Taxonomy
A1: AI Risk Taxonomy
A2: 52 risks in 12 categories. Sources: NIST AI RMF & AI 600-1, ISO/IEC 23894, EU AI Act, OWASP LLM / Agentic Top 10, MITRE ATLAS, MIT AI Risk Repository, GT AI Ready7. RCM IDs refer to GT AI RCM v2.1; agent risks draw on ISACA Securing AI Agents (2026).
A4: Risk ID | B4: Category | C4: Risk | D4: Description / scenario | E4: Key sources | F4: RCM v2.1 controls | G4: Example KRI
A5: GOV-01 | B5: Governance & Accountability | C5: Unclear accountability for AI outcomes | D5: No named business or technical owner for an AI system; decisions and incidents cannot be attributed or escalated. | E5: ISO/IEC 42001 5.3; NIST AI RMF Govern 2.1 | F5: GL-1, GL-2, GL-8 | G5: % AI systems in register without named owner
A6: GOV-02 | B6: Governance & Accountability | C6: Shadow / unsanctioned AI use | D6: Staff use unapproved AI tools, bypassing risk assessment and exposing confidential data. | E6: AI Ready7 1.2; NSW AIAF | F6: GL-5, GL-8 | G6: Unsanctioned AI services detected per month
A7: GOV-03 | B7: Governance & Accountability | C7: AI deployed without adequate risk assessment | D7: Use case moves to production without tiering, impact assessment or approval proportionate to risk. | E7: ISO/IEC 23894; EU AI Act Art. 9 | F7: RM-2, RM-5, GL-7 | G7: % production AI systems with current assessment
A8: GOV-04 | B8: Governance & Accountability | C8: Misaligned or low-value AI investment | D8: AI initiatives lack defined benefits, leading to wasted spend and continued investment in ineffective or risky solutions. | E8: AI Ready7 1.3; NIST AI RMF Map 3.1 | F8: GL-3, GL-6 | G8: % AI initiatives meeting benefit KPIs
A9: LEG-01 | B9: Legal, Regulatory & Compliance | C9: Use of a prohibited AI practice | D9: AI system falls within a prohibited category (e.g., manipulative techniques, social scoring, workplace emotion recognition). | E9: EU AI Act Art. 5 | F9: RM-5, RS-2 | G9: Number of use cases failing prohibited-practice screen
A10: LEG-02 | B10: Legal, Regulatory & Compliance | C10: Non-compliance with high-risk AI obligations | D10: Provider or deployer duties (risk management, data governance, logging, oversight, FRIA, registration) not met for a high-risk system. | E10: EU AI Act Art. 8-27, 43, 49 | F10: RO-1, RO-6, RM-5 | G10: Open compliance gaps on high-risk systems
A11: LEG-03 | B11: Legal, Regulatory & Compliance | C11: Breach of sector or local regulation | D11: AI use breaches Bahrain PDPL, CBB Rulebook, iGA policy or other applicable regimes (incl. KSA/UAE where operating). | E11: Bahrain PDPL; CBB Rulebook; iGA AI Policy | F11: RO-5, PR-1, TP-3 | G11: Regulatory findings related to AI
A12: LEG-04 | B12: Legal, Regulatory & Compliance | C12: Intellectual property / copyright infringement | D12: Training data, prompts or outputs infringe third-party IP, licence terms or client confidentiality. | E12: EU AI Act Art. 53(1)(c); Bahrain Copyright Law | F12: LC-11, LC-6 | G12: IP complaints / takedown requests
A13: LEG-05 | B13: Legal, Regulatory & Compliance | C13: Liability for AI-caused harm | D13: Organisation is liable for damage caused by AI outputs or actions (contractual, tort or product liability). | E13: EU Product Liability Directive (2024/2853); Bahrain draft AI law | F13: TP-3, CO-3, IM-2 | G13: Claims / complaints attributed to AI
A14: FAI-01 | B14: Fairness, Bias & Human Rights | C14: Discriminatory or biased outcomes | D14: Model produces systematically different outcomes for protected or vulnerable groups (e.g., gender, nationality, age). | E14: ISO/IEC TR 24027; NIST SP 1270; EU AI Act Art. 10 | F14: RS-5, LC-1 | G14: Disparate impact ratio across cohorts
A15: FAI-02 | B15: Fairness, Bias & Human Rights | C15: Unrepresentative training or evaluation data | D15: Data does not reflect the population or context of use (e.g., Arabic dialects, local customer segments). | E15: EU AI Act Art. 10(3)-(4); ISO/IEC 5259 | F15: LC-1, RS-7 | G15: Coverage gaps by segment in evaluation set
... A56: SOC-04 | B56: Societal, Reputational & AI-Enabled Threats | C56: AI-accelerated cyber attacks | D56: Adversaries use AI for automated discovery, exploit chaining and scaled social engineering, outpacing defences. | E56: AI Ready7 7.1-7.5; MITRE ATLAS | F56: AT-1, AT-2, AT-4 | G56: Mean time to remediate critical vulnerabilities

Sheet Scales
A1: Risk Scales & Criteria
A2: Likelihood, impact (by dimension), control effectiveness, rating bands and tier requirements used throughout this toolkit. Aligned to ISO 31000 / ISO/IEC 23894 and the GT AI Risk Assessment Framework.
A4: Likelihood
A5: Score | B5: Level | C5: Description
A6: 1 | B6: Rare | C6: May occur only in exceptional circumstances; < 5% chance within 12 months; no known occurrences in similar systems.
A7: 2 | B7: Unlikely | C7: Could occur but not expected; 5-20% within 12 months; isolated occurrences in industry.
A8: 3 | B8: Possible | C8: Might occur; 20-50% within 12 months; has occurred in comparable organisations.
A9: 4 | B9: Likely | C9: Will probably occur; 50-80% within 12 months; has occurred previously in the organisation.
A10: 5 | B10: Almost certain | C10: Expected to occur; > 80% within 12 months or recurring.
A12: Impact (rate the highest applicable dimension)
A13: Score | B13: Level | C13: Individuals & rights | D13: Financial | E13: Regulatory & legal | F13: Operational | G13: Reputational & client trust | H13: Safety, societal & environmental
A14: 1 | B14: Insignificant | C14: No discernible effect on individuals | D14: < BHD 5,000 | E14: No breach; no regulatory interest | F14: Negligible disruption (< 1 hour) | G14: No external awareness | H14: No harm
A15: 2 | B15: Minor | C15: Minor inconvenience to a few individuals, easily remedied | D15: BHD 5,000 - 50,000 | E15: Minor breach; self-reported; no sanction | F15: Minor disruption (< 1 day); workaround available | G15: Limited local / client awareness | H15: Minor, temporary, contained harm
A16: 3 | B16: Moderate | C16: Adverse effect on a group; rights affected but remediable | D16: BHD 50,000 - 250,000 | E16: Breach resulting in regulatory enquiry or warning | F16: Disruption of key process (1-3 days) | G16: Negative media / client complaints; short-term | H16: Moderate harm; limited environmental impact
A17: 4 | B17: Major | C17: Significant harm or discrimination affecting many individuals | D17: BHD 250,000 - 1,000,000 | E17: Regulatory sanction, fine or enforcement action | F17: Critical service outage (> 3 days) | G17: Sustained national media coverage; loss of key clients | H17: Serious injury / significant societal harm
A18: 5 | B18: Severe | C18: Irreversible harm to individuals' rights, safety or livelihood at scale | D18: > BHD 1,000,000 | E18: Licence suspension / criminal liability / prohibited practice | F18: Prolonged failure of critical operations | G18: Long-term, international reputational damage | H18: Loss of life / widespread irreversible harm
A20: Control effectiveness (residual = inherent score x factor)
A21: Rating | B21: Factor | C21: Description
A22: Strong | B22: 0.4 | C22: Controls designed and operating effectively; tested with no material exceptions; automated where appropriate.
A23: Satisfactory | B23: 0.6 | C23: Controls largely designed and operating; minor exceptions; improvement opportunities identified.
A24: Needs improvement | B24: 0.8 | C24: Controls partly designed or inconsistently operated; material exceptions; reliance limited.
A25: Weak / None | B25: 1 | C25: Controls absent, not designed to address the risk, or not operating.
A27: Risk rating bands (score = likelihood x impact, 1-25)
A28: Rating | B28: Min | C28: Max | D28: Required response
A29: Low | B29: 1 | C29: 4 | D29: Accept; monitor through normal governance.
A30: Medium | B30: 5 | C30: 9 | D30: Treat within normal planning cycle; owner accountable; monitor KRIs.
A31: High | B31: 10 | C31: 16 | D31: Treatment plan within 90 days; AI Committee oversight; consider restricting use.
A32: Critical | B32: 17 | C32: 25 | D32: Outside appetite: immediate action; escalate to Executive / Board; suspend or do not deploy until reduced.
A34: Inherent risk tier requirements
A35: Tier | B35: Score from | C35: Assessment & control requirements | F35: Approval authority | H35: Review frequency
A36: Low | B36: 0 | C36: Self-managed by use-case owner; lightweight assessment; register entry. | F36: Use-case owner | H36: Every 24 months or on material change
A37: Medium | B37: 25 | C37: Standard risk assessment; SME review (privacy, security, data); documented controls. | F37: Head of function + Risk (2nd line) review | H37: Every 12 months or on material change
A38: High | B38: 50 | C38: Full risk & impact assessment (ISO/IEC 42005 / FRIA where required); independent validation; AI Committee approval. | F38: AI Committee / CoE | H38: Every 6 months + continuous KRI monitoring
A39: Critical | B39: 75 | C39: As High plus legal review, executive sign-off, board notification, pre-deployment red teaming and staged rollout. | F39: Executive Committee / Board Risk Committee | H39: Quarterly + continuous KRI monitoring

Sheet Lists
A1: Yes | B1: Rare | C1: Insignificant | D1: Strong | E1: Avoid | F1: Open | G1: Concept / design | H1: Provider (develops / places on market) | I1: Generative AI / LLM assistant | L1: No decisions about individuals (e.g., internal content drafting, code assistance) | M1: AI provides information only; humans make all decisions | N1: Public or synthetic data only | O1: Fewer than 10 internal users; pilot | P1: Outputs are advisory drafts with no direct effect | Q1: No individuals affected | R1: Unregulated, non-critical activity | S1: Rules-based / deterministic automation | T1: Offline / isolated system | U1: Fully in-house model and infrastructure
A2: No | B2: Unlikely | C2: Minor | D2: Satisfactory | E2: Mitigate | F2: Treatment planned | G2: Procurement | H2: Deployer (uses under own authority) | I2: Agentic AI | L2: Minor internal operational decisions; negligible effect on individuals | M2: AI recommends; a human reviews every output before use | N2: Internal, non-confidential business data | O2: Single team / department | P2: Errors easily corrected with no lasting impact | Q2: Staff only, with no vulnerability indicators | R2: General regulatory obligations only (e.g., data protection) | S2: Traditional interpretable ML (e.g., regression, decision trees) | T2: Internal users only, internal data sources | U2: In-house model on third-party cloud
B3: Possible | C3: Moderate | D3: Needs improvement | E3: Transfer | F3: In progress | G3: Development | H3: Provider & deployer | I3: Predictive / classification ML | L3: Influences decisions about individuals with limited, easily reversible effect | M3: AI recommends; humans review samples or exceptions only | N3: Confidential business or client data | O3: Organisation-wide internal use | P3: Errors correctable with moderate effort or inconvenience | Q3: General public / customers | R3: Regulated sector activity (e.g., banking, insurance, telecom, healthcare) | S3: Complex ML (e.g., gradient boosting, deep learning) with explainability tooling | T3: Consumes external content (web, email, documents) or external APIs | U3: Vendor model customised for the organisation
B4: Likely | C4: Major | D4: Weak / None | E4: Accept | F4: Closed | G4: Pilot / validation | H4: Importer / distributor | I4: Computer vision / biometrics | L4: Materially influences decisions affecting individuals' access to services, employment or finances | M4: AI decides or acts automatically; humans can intervene after the fact | N4: Personal data | O4: External customers / public (up to 10,000 people) | P4: Errors difficult to reverse; lasting financial or reputational impact | Q4: Groups with some vulnerability (e.g., elderly, low digital literacy, migrant workers) | R4: Specific AI transparency or sector AI obligations apply (e.g., EU AI Act Art. 50, CBB requirements) | S4: Generative AI / LLM (third-party foundation model) | T4: Directly customer- or public-facing interface | U4: Commercial SaaS AI with limited visibility of model
