Workbook

Sheet Welcome
B1: GT AI READINESS & RISK ASSESSMENT TOOL
B2: Grant Thornton Bahrain | AI Governance, Risk & Compliance | Combines the NSW AI Assessment Framework, GT AI Ready7 and the GT AI Risk & Control Matrix v2.1
B4: WHEN TO USE THIS TOOL | D4: HOW IT WORKS (approx. 15-20 minutes) | F4: WHAT YOU GET
B5: - Before or early in your AI journey, to baseline readiness - Before scaling AI or deploying AI that affects customers or decisions - When AI is discovered in use without assessment (shadow AI) - When risk or context changes: new data, model, vendor, purpose or less human oversight - Annually, to track maturity progress Public GenAI tools used for low-risk drafting may be governed by your Acceptable Use Policy instead (AIAF approach). | D5: 1. PROFILE - organisation details and regulatory context 2. ASSESSMENT - 15 questions Part A: 4 questions on AI use and inherent risk (AIAF) Part B: 11 questions on readiness across the 7 AI Ready7 pillars 3. REPORT - generated automatically, print-ready (A4) 4. ACTION PLAN - assign owners and dates to recommended actions | F5: - Overall AI readiness score and maturity level - Inherent AI risk tier (Low / Medium / High / Critical) - Overall AI risk exposure and recommended oversight pathway - Pillar radar chart and responsible-AI principle coverage - Findings, potential risks and recommendations per area - Top-5 priorities and a phased roadmap - Applicable regulations (Bahrain PDPL, CBB, EU AI Act, GCC) - Printable report you can save as PDF and email
B7: COLOUR LEGEND | D7: REQUIREMENT TYPES (as in the AIAF) | F7: START HERE
B8: Input cell - select or type | D8: ⟳ Compliance Obligation - linked to laws / regulation | F8: Go to '1. Profile' >>
B9: Low / Largely met | D9: ⚠ Mandatory Requirement - baseline control expected for any AI use
B10: Medium / Moderate / Partially met | D10: ⚖ Ethical Consideration - responsible-AI principle | F10: Go to '2. Assessment' >>
B11: High / Minimal | D11: ☆ Recommended - good practice
B12: Critical / Very high / Not met | F12: View '3. Report' >>
B15: This is a self-assessment tool. Results depend on the accuracy of responses and do not constitute an audit, certification or legal advice. Version 1.1 - September 2026.

Sheet 1. Profile
B1: 1. ORGANISATION PROFILE
B2: Complete the yellow cells. The profile personalises the report and determines which regulatory considerations apply. Takes about 2 minutes.
B4: Organisation name | E4: Tip
B5: Sector | E5: Scope the assessment to the whole organisation for a readiness baseline, or to a single AI system to support a use-case decision. For use-case level risk assessment use the GT AI Risk Assessment Toolkit.
B6: Organisation size
B7: Scope of assessment
B8: Scope description (optional)
B9: Completed by
B10: Role / title
B11: Email address (to send yourself the report)
B12: Assessment date (dd/mm/yyyy)
B13: Grant Thornton contact (optional)
B15: REGULATORY CONTEXT
B16: Is the organisation licensed by the Central Bank of Bahrain (CBB)?
B17: Do AI systems process personal data of individuals in Bahrain?
B18: Are AI-enabled products / services offered in the EU, or AI outputs used in the EU?
... B21: Does the organisation develop AI (provider) or only use it (deployer)?

Sheet 2. Assessment
B1: 2. ASSESSMENT - 15 questions | approx. 15 minutes
B2: Select the statement in column E that best describes your current state (choose the lower level if unsure - evidence should exist for the level selected). Part A profiles your AI use and inherent risk (based on the NSW AI Assessment Framework). Part B measures readiness across the 7 GT AI Ready7 pillars, mapped to the GT AI RCM v2.1 controls. Results update live below and in the '3. Report' sheet.
B4: ANSWERED | D4: OVERALL AI READINESS | E4: MATURITY LEVEL (AI Ready7 scale) | F4: INHERENT RISK TIER | H4: AI RISK EXPOSURE -> PATHWAY | I4: YOUR REPORT
B5: =Calc!B20&" / 15" | D5: =IF(Calc!B45="","-",Calc!B45) | E5: =IF(Calc!B46="","-",Calc!B46) | F5: =IF(Calc!C32="","-",Calc!C32) | H5: =IF(Calc!B57="","-",Calc!B57&" -> "&Calc!B58) | I5: =IF(Calc!B21=1,"Ready - see 3. Report","Complete all questions")
B8: # | C8: Area | D8: Question | E8: Your response (select from list) | F8: Score | G8: Status | H8: What this means / recommended next step | I8: Linked controls (GT AI RCM v2.1) | J8: Requirement type
B9: PART A - AI USE & INHERENT RISK PROFILE (AIAF-based: how much could go wrong?)
B10: A1 | C10: AI use profile | D10: Which statement best describes how AI is used in your organisation today (including AI embedded in software and tools used by staff)? Guidance: Consider approved and unapproved tools, vendor software with AI features and AI used by suppliers on your behalf. | F10: =IF(L10="","",INDEX(QBank!$C$2:$C$6,L10)) | G10: =IF(L10="","Not answered",INDEX(QBank!$D$2:$D$6,L10)) | H10: =IF(L10="","",INDEX(QBank!$E$2:$E$6,L10)) | I10: Tiering factor (risk framework T1-T3) | J10: Inherent-risk driver | L10: =IF(E10="","",IFERROR(MATCH(E10,QBank!$B$2:$B$6,0),""))
B11: A2 | C11: Decision impact | D11: What is the most significant type of decision or outcome your AI systems influence? Guidance: Answer for the highest-impact AI use case in scope (AIAF: 'worst credible harm'). | F11: =IF(L11="","",INDEX(QBank!$C$7:$C$11,L11)) | G11: =IF(L11="","Not answered",INDEX(QBank!$D$7:$D$11,L11)) | H11: =IF(L11="","",INDEX(QBank!$E$7:$E$11,L11)) | I11: Tiering factor (risk framework T1-T3) | J11: Inherent-risk driver | L11: =IF(E11="","",IFERROR(MATCH(E11,QBank!$B$7:$B$11,0),""))
B12: A3 | C12: Data sensitivity | D12: What is the most sensitive data processed by your AI systems (including data staff enter into AI tools)? Guidance: Include prompts, uploaded documents, training / fine-tuning data, retrieval sources and logs. | F12: =IF(L12="","",INDEX(QBank!$C$12:$C$16,L12)) | G12: =IF(L12="","Not answered",INDEX(QBank!$D$12:$D$16,L12)) | H12: =IF(L12="","",INDEX(QBank!$E$12:$E$16,L12)) | I12: Tiering factor (risk framework T1-T3) | J12: Inherent-risk driver | L12: =IF(E12="","",IFERROR(MATCH(E12,QBank!$B$12:$B$16,0),""))
B13: A4 | C13: Oversight & reversibility | D13: How much human oversight applies to AI outputs, and how reversible are the outcomes? Guidance: AIAF considers autonomy, human oversight and whether outputs are reversible or correctable. | F13: =IF(L13="","",INDEX(QBank!$C$17:$C$21,L13)) | G13: =IF(L13="","Not answered",INDEX(QBank!$D$17:$D$21,L13)) | H13: =IF(L13="","",INDEX(QBank!$E$17:$E$21,L13)) | I13: Tiering factor (risk framework T1-T3) | J13: Inherent-risk driver | L13: =IF(E13="","",IFERROR(MATCH(E13,QBank!$B$17:$B$21,0),""))
B14: PART B - AI READINESS & CONTROL MATURITY (AI Ready7 pillars + GT AI RCM: how well is it managed?)
B15: Q5 | C15: Business Alignment AI strategy, ownership & risk appetite | D15: Is there executive ownership and an approved AI strategy that defines the ambition, where AI will be used and the organisation's AI risk appetite? Guidance: Evidence: approved AI strategy, named executive sponsor, risk appetite statement, experimentation boundaries. | F15: =IF(L15="","",INDEX(QBank!$C$22:$C$26,L15)) | G15: =IF(L15="","Not answered",INDEX(QBank!$D$22:$D$26,L15)) | H15: =IF(L15="","",INDEX(QBank!$E$22:$E$26,L15)) | I15: GL-1, GL-3, RM-6 | J15: ☆ Recommended | L15: =IF(E15="","",IFERROR(MATCH(E15,QBank!$B$22:$B$26,0),""))
B16: Q6 | C16: Business Alignment Use-case portfolio & value realisation | D16: How are AI use cases identified, prioritised, approved and measured for value? Guidance: Evidence: intake form, prioritisation criteria, business cases, benefit KPIs, portfolio reviews. | F16: =IF(L16="","",INDEX(QBank!$C$27:$C$31,L16)) | G16: =IF(L16="","Not answered",INDEX(QBank!$D$27:$D$31,L16)) | H16: =IF(L16="","",INDEX(QBank!$E$27:$E$31,L16)) | I16: GL-6, GL-5 | J16: ☆ Recommended | L16: =IF(E16="","",IFERROR(MATCH(E16,QBank!$B$27:$B$31,0),""))
B17: Q7 | C17: Governance & Ethics AI policy, acceptable use & regulatory compliance | D17: Do you have an approved AI (acceptable-use) policy and a process to identify and comply with applicable AI-related regulation (e.g., Bahrain PDPL, CBB rules, EU AI Act)? Guidance: Evidence: AI policy, approved-tools list, staff acknowledgements, obligations register, compliance reviews. | F17: =IF(L17="","",INDEX(QBank!$C$32:$C$36,L17)) | G17: =IF(L17="","Not answered",INDEX(QBank!$D$32:$D$36,L17)) | H17: =IF(L17="","",INDEX(QBank!$E$32:$E$36,L17)) | I17: GL-5, RO-1, RO-5 | J17: ⟳ Compliance Obligation | L17: =IF(E17="","",IFERROR(MATCH(E17,QBank!$B$32:$B$36,0),""))
B18: Q8 | C18: Governance & Ethics AI inventory & risk / impact assessment | D18: Do you maintain an inventory of AI systems with named owners, and assess AI risks and impacts (including third-party AI) before and after deployment? Guidance: Evidence: AI register, risk-tiering records, impact assessments, vendor AI due diligence, re-assessment records. | F18: =IF(L18="","",INDEX(QBank!$C$37:$C$41,L18)) | G18: =IF(L18="","Not answered",INDEX(QBank!$D$37:$D$41,L18)) | H18: =IF(L18="","",INDEX(QBank!$E$37:$E$41,L18)) | I18: GL-8, RM-2, RM-5, TP-2 | J18: ⚠ Mandatory Requirement | L18: =IF(E18="","",IFERROR(MATCH(E18,QBank!$B$37:$B$41,0),""))
B19: Q9 | C19: Governance & Ethics Responsible-AI guardrails & human oversight | D19: Are there practical guardrails for fairness, transparency and human oversight, overseen by an AI committee or centre of excellence? Guidance: Evidence: committee / CoE charter, guardrail standards, human-in-charge procedures, bias tests, AI disclosures, appeal routes. | F19: =IF(L19="","",INDEX(QBank!$C$42:$C$46,L19)) | G19: =IF(L19="","Not answered",INDEX(QBank!$D$42:$D$46,L19)) | H19: =IF(L19="","",INDEX(QBank!$E$42:$E$46,L19)) | I19: GL-7, RS-1, RS-4, RS-5, CO-1, CO-3 | J19: ⚖ Ethical Consideration | L19: =IF(E19="","",IFERROR(MATCH(E19,QBank!$B$42:$B$46,0),""))
B20: Q10 | C20: Training & Development AI literacy & capability | D20: Have staff received AI literacy training appropriate to their role, and are specialist AI, governance and security skills being developed? Guidance: Evidence: training curricula, completion records, role-based pathways, deepfake / phishing simulations, workforce plan. | F20: =IF(L20="","",INDEX(QBank!$C$47:$C$51,L20)) | G20: =IF(L20="","Not answered",INDEX(QBank!$D$47:$D$51,L20)) | H20: =IF(L20="","",INDEX(QBank!$E$47:$E$51,L20)) | I20: GL-4, RS-9 | J20: ⟳ Compliance Obligation | L20: =IF(E20="","",IFERROR(MATCH(E20,QBank!$B$47:$B$51,0),""))
B21: Q11 | C21: Data & Quality Data governance, quality & privacy for AI | D21: Is data used by AI classified, quality-assured, traceable and protected in line with privacy requirements (e.g., Bahrain PDPL)? Guidance: Evidence: data classification applied to AI, data-readiness assessments, lineage, DPIAs, redaction / anonymisation, transfer assessments. | F21: =IF(L21="","",INDEX(QBank!$C$52:$C$56,L21)) | G21: =IF(L21="","Not answered",INDEX(QBank!$D$52:$D$56,L21)) | H21: =IF(L21="","",INDEX(QBank!$E$52:$E$56,L21)) | I21: LC-1, SE-4, PR-1, PR-4, PR-5, PR-6 | J21: ⟳ Compliance Obligation | L21: =IF(E21="","",IFERROR(MATCH(E21,QBank!$B$52:$B$56,0),""))
B22: Q12 | C22: Architecture & Technology AI architecture, integration & monitoring | D22: Is there a common AI reference architecture with standard integration patterns, and are AI systems monitored for performance, drift and cost? Guidance: Evidence: reference architecture, approved platforms, integration / agent patterns, monitoring dashboards, cost reports. | F22: =IF(L22="","",INDEX(QBank!$C$57:$C$61,L22)) | G22: =IF(L22="","Not answered",INDEX(QBank!$D$57:$D$61,L22)) | H22: =IF(L22="","",INDEX(QBank!$E$57:$E$61,L22)) | I22: LC-2, LC-3, LC-8, LC-12, OM-1, OM-4, RM-6 | J22: ☆ Recommended | L22: =IF(E22="","",IFERROR(MATCH(E22,QBank!$B$57:$B$61,0),""))
B23: Q13 | C23: Protect AI Systems Securing AI systems | D23: Are AI systems protected with least-privilege access, secure development and testing (incl. red teaming for prompt injection), and runtime logging? Guidance: Evidence: AI threat models, access reviews (incl. agent identities), AI red-team reports, guardrail and sandbox configurations, audit logs. Detailed test: GT AI Security & Agent Audit Checklist. | F23: =IF(L23="","",INDEX(QBank!$C$62:$C$66,L23)) | G23: =IF(L23="","Not answered",INDEX(QBank!$D$62:$D$66,L23)) | H23: =IF(L23="","",INDEX(QBank!$E$62:$E$66,L23)) | I23: SE-2, SE-3, SE-6 to SE-10, OM-2, AA-3 | J23: ⚠ Mandatory Requirement | L23: =IF(E23="","",IFERROR(MATCH(E23,QBank!$B$62:$B$66,0),""))
B24: Q14 | C24: Protection from AI Threats Defending against AI-enabled threats | D24: Is the organisation prepared for AI-enabled attacks such as deepfake impersonation, AI-crafted phishing and automated exploitation? Guidance: Evidence: AI threat intelligence, out-of-band verification procedures, deepfake simulations, SOC use cases, playbooks, patch metrics. | F24: =IF(L24="","",INDEX(QBank!$C$67:$C$71,L24)) | G24: =IF(L24="","Not answered",INDEX(QBank!$D$67:$D$71,L24)) | H24: =IF(L24="","",INDEX(QBank!$E$67:$E$71,L24)) | I24: AT-1, AT-2, AT-3, AT-4 | J24: ☆ Recommended | L24: =IF(E24="","",IFERROR(MATCH(E24,QBank!$B$67:$B$71,0),""))
B25: Q15 | C25: Governance & Ethics AI incidents, monitoring & assurance | D25: Are AI incidents detected, managed and reported, and is AI governance subject to internal audit or independent assurance? Guidance: Evidence: AI incident categories, notification criteria, incident logs, internal-audit reports, vendor assurance, certification status. | F25: =IF(L25="","",INDEX(QBank!$C$72:$C$76,L25)) | G25: =IF(L25="","Not answered",INDEX(QBank!$D$72:$D$76,L25)) | H25: =IF(L25="","",INDEX(QBank!$E$72:$E$76,L25)) | I25: IM-1, IM-2, IM-3, AA-1, AA-2, RO-4 | J25: ⟳ Compliance Obligation | L25: =IF(E25="","",IFERROR(MATCH(E25,QBank!$B$72:$B$76,0),""))

Sheet 3. Report
B1: AI READINESS & RISK ASSESSMENT - RESULTS REPORT | M1: HOW TO PRINT, SAVE OR EMAIL THIS REPORT
B2: =IF('1. Profile'!$C$4="","Organisation: (not specified)",'1. Profile'!$C$4)&" | "&IF('1. Profile'!$C$5="","",'1. Profile'!$C$5&" | ")&"Assessment date: "&IF('1. Profile'!$C$12="","-",IF(ISNUMBER('1. Profile'!$C$12),TEXT('1. Profile'!$C$12,"dd mmmm yyyy"),'1. Profile'!$C$12)) | M2: SAVE AS PDF (recommended): File > Save As > choose 'PDF' as the file type > Options > 'Active sheet(s)' > Save. Or File > Export > Create PDF/XPS. This uses Excel's built-in PDF engine and does not depend on any printer driver. PRINT: File > Print > 'Print Active Sheets' (A4 portrait, fitted to one page wide, page breaks between sections). Do not choose 'Print Entire Workbook'. IF 'MICROSOFT PRINT TO PDF' SHOWS AN ERROR: the Windows PDF printer driver is failing, not the workbook. Use Save As > PDF above, or select another printer. To repair the driver: Windows 'Turn Windows features on or off' > untick 'Microsoft Print to PDF' > OK > re-tick > OK, then restart Excel. EMAIL: save the PDF, then click the link below to open a pre-filled email with your headline results and attach the PDF. This panel is outside the print area and will not appear on the printed report.
B3: ="Scope: "&IF('1. Profile'!$C$7="","-",'1. Profile'!$C$7)&IF('1. Profile'!$C$8="",""," - "&'1. Profile'!$C$8)&" | Completed by: "&IF('1. Profile'!$C$9="","-",'1. Profile'!$C$9)&IF('1. Profile'!$C$10="",""," ("&'1. Profile'!$C$10&")")
B4: =IF(Calc!B21=1,"Framework basis: NSW AI Assessment Framework (inherent risk) | GT AI Ready7 (7 pillars) | GT AI RCM v2.1 (controls) | ISO/IEC 42001, NIST AI RMF, EU AI Act, Bahrain PDPL","ASSESSMENT INCOMPLETE - "&Calc!B20&" of 15 questions answered. Results below are provisional.")
M5: =IF(Calc!B21=0,"Complete the assessment to enable email",IF('1. Profile'!$C$11="","Enter your email address in 1. Profile to enable the email link",HYPERLINK("mailto:"&'1. Profile'!$C$11&"?subject=AI%20Readiness%20Results&body="&SUBSTITUTE(SUBSTITUTE("AI readiness "&TEXT(Calc!B45,"0%")&" ("&Calc!B46&"); risk tier "&Calc!C32&"; exposure "&Calc!B57&". Report attached.","%","%25")," ","%20"),">> Click to email the results summary to "&'1. Profile'!$C$11)))
B6: 1. EXECUTIVE SUMMARY
B7: OVERALL AI READINESS | E7: MATURITY LEVEL | G7: INHERENT RISK TIER | I7: OVERALL AI RISK EXPOSURE
B8: =IF(Calc!B45="","-",Calc!B45) | E8: =IF(Calc!B46="","-",Calc!B46) | G8: =IF(Calc!C32="","-",Calc!C32) | I8: =IF(Calc!B57="","-",Calc!B57)
B9: ="AI Ready7 scale: <50% Partial | 50-70% Informed | 70-90% Repeatable | 90%+ Adaptive" | E9: =Calc!B70 | G9: =IF(Calc!C30="","",TEXT(Calc!C30,"0%")&" of maximum inherent risk. "&Calc!C33) | I9: ="Combines inherent risk tier and readiness maturity (see Methodology)"
B11: RECOMMENDED PATHWAY | D11: =IF(Calc!B58="","-",Calc!B58)
B12: =Calc!C58
B14: =Calc!B72
B16: 2. READINESS BY AI READY7 PILLAR
B17: Pillar | D17: Score | E17: Maturity | F17: Progress (each block = 5%; target 70% = 14 blocks)
B18: Business Alignment | D18: =IF(Calc!B37="","-",Calc!B37) | E18: =IF(Calc!C37="","-",Calc!C37) | F18: =IF(Calc!B37="","",REPT("■",ROUND(Calc!B37*20,0))&REPT("□",MAX(0,14-ROUND(Calc!B37*20,0))))
B19: Governance & Ethics | D19: =IF(Calc!B38="","-",Calc!B38) | E19: =IF(Calc!C38="","-",Calc!C38) | F19: =IF(Calc!B38="","",REPT("■",ROUND(Calc!B38*20,0))&REPT("□",MAX(0,14-ROUND(Calc!B38*20,0))))
B20: Training & Development | D20: =IF(Calc!B39="","-",Calc!B39) | E20: =IF(Calc!C39="","-",Calc!C39) | F20: =IF(Calc!B39="","",REPT("■",ROUND(Calc!B39*20,0))&REPT("□",MAX(0,14-ROUND(Calc!B39*20,0))))
B21: Data & Quality | D21: =IF(Calc!B40="","-",Calc!B40) | E21: =IF(Calc!C40="","-",Calc!C40) | F21: =IF(Calc!B40="","",REPT("■",ROUND(Calc!B40*20,0))&REPT("□",MAX(0,14-ROUND(Calc!B40*20,0))))
B22: Architecture & Technology | D22: =IF(Calc!B41="","-",Calc!B41) | E22: =IF(Calc!C41="","-",Calc!C41) | F22: =IF(Calc!B41="","",REPT("■",ROUND(Calc!B41*20,0))&REPT("□",MAX(0,14-ROUND(Calc!B41*20,0))))
B23: Protect AI Systems | D23: =IF(Calc!B42="","-",Calc!B42) | E23: =IF(Calc!C42="","-",Calc!C42) | F23: =IF(Calc!B42="","",REPT("■",ROUND(Calc!B42*20,0))&REPT("□",MAX(0,14-ROUND(Calc!B42*20,0))))
B24: Protection from AI Threats | D24: =IF(Calc!B43="","-",Calc!B43) | E24: =IF(Calc!C43="","-",Calc!C43) | F24: =IF(Calc!B43="","",REPT("■",ROUND(Calc!B43*20,0))&REPT("□",MAX(0,14-ROUND(Calc!B43*20,0))))
B25: OVERALL | D25: =IF(Calc!B45="","-",Calc!B45) | E25: =IF(Calc!B46="","-",Calc!B46) | F25: =IF(Calc!B45="","",REPT("■",ROUND(Calc!B45*20,0))&REPT("□",MAX(0,14-ROUND(Calc!B45*20,0))))
B27: Pillar | D27: Potential risk if the pillar is not strengthened (shown where score < 90%)
B28: Business Alignment | D28: =IF(Calc!B37="","",IF(Calc!B37>=0.9,"Adaptive - maintain current practices.",Calc!E37))
B29: Governance & Ethics | D29: =IF(Calc!B38="","",IF(Calc!B38>=0.9,"Adaptive - maintain current practices.",Calc!E38))
B30: Training & Development | D30: =IF(Calc!B39="","",IF(Calc!B39>=0.9,"Adaptive - maintain current practices.",Calc!E39))
B31: Data & Quality | D31: =IF(Calc!B40="","",IF(Calc!B40>=0.9,"Adaptive - maintain current practices.",Calc!E40))
B32: Architecture & Technology | D32: =IF(Calc!B41="","",IF(Calc!B41>=0.9,"Adaptive - maintain current practices.",Calc!E41))
B33: Protect AI Systems | D33: =IF(Calc!B42="","",IF(Calc!B42>=0.9,"Adaptive - maintain current practices.",Calc!E42))
B34: Protection from AI Threats | D34: =IF(Calc!B43="","",IF(Calc!B43>=0.9,"Adaptive - maintain current practices.",Calc!E43))
B36: 3. AI USE & INHERENT RISK PROFILE (AIAF-based)
B37: Factor | D37: Your response | H37: Risk level | I37: Implication
B38: A1 AI use profile | D38: =IF('2. Assessment'!E10="","Not answered",'2. Assessment'!E10) | H38: ='2. Assessment'!G10 | I38: ='2. Assessment'!H10
B39: A2 Decision impact | D39: =IF('2. Assessment'!E11="","Not answered",'2. Assessment'!E11) | H39: ='2. Assessment'!G11 | I39: ='2. Assessment'!H11
B40: A3 Data sensitivity | D40: =IF('2. Assessment'!E12="","Not answered",'2. Assessment'!E12) | H40: ='2. Assessment'!G12 | I40: ='2. Assessment'!H12
B41: A4 Oversight & reversibility | D41: =IF('2. Assessment'!E13="","Not answered",'2. Assessment'!E13) | H41: ='2. Assessment'!G13 | I41: ='2. Assessment'!H13
B42: ="Inherent risk tier: "&IF(Calc!C32="","-",UPPER(Calc!C32))&IF(Calc!C30="",""," ("&TEXT(Calc!C30,"0%")&" weighted inherent-risk score)") | H42: =Calc!C33
B44: 4. RESPONSIBLE-AI PRINCIPLE COVERAGE (NSW AIAF ethics principles)
B45: Principle | E45: Coverage | F45: Assessment | H45: Informed by questions
B46: Fairness | E46: =IF(Calc!B76="","-",Calc!B76) | F46: =Calc!D76 | H46: =Calc!C76
...

Sheet 4. Action Plan
B1: 4. ACTION PLAN & RISK TREATMENT TRACKER
B2: Columns B-H update automatically from the assessment. Assign an owner, target date and status (yellow cells) to track remediation. Priority rank 1 = most urgent.
B4: # | C4: Area | D4: Current score | E4: Priority rank | F4: Timing | G4: Recommended action | H4: Linked controls (RCM v2.1) | I4: Owner | J4: Target date | K4: Status | L4: Notes / evidence
B5: Q5 | C5: AI strategy, ownership & risk appetite (Business Alignment) | D5: =IF(Calc!E7="","-",Calc!E7) | E5: =IFERROR(MATCH(7,Calc!$B$87:$B$97,0),"-") | F5: =Calc!I7 | G5: =Calc!L7 | H5: GL-1, GL-3, RM-6
B6: Q6 | C6: Use-case portfolio & value realisation (Business Alignment) | D6: =IF(Calc!E8="","-",Calc!E8) | E6: =IFERROR(MATCH(8,Calc!$B$87:$B$97,0),"-") | F6: =Calc!I8 | G6: =Calc!L8 | H6: GL-6, GL-5
B7: Q7 | C7: AI policy, acceptable use & regulatory compliance (Governance & Ethics) | D7: =IF(Calc!E9="","-",Calc!E9) | E7: =IFERROR(MATCH(9,Calc!$B$87:$B$97,0),"-") | F7: =Calc!I9 | G7: =Calc!L9 | H7: GL-5, RO-1, RO-5
B8: Q8 | C8: AI inventory & risk / impact assessment (Governance & Ethics) | D8: =IF(Calc!E10="","-",Calc!E10) | E8: =IFERROR(MATCH(10,Calc!$B$87:$B$97,0),"-") | F8: =Calc!I10 | G8: =Calc!L10 | H8: GL-8, RM-2, RM-5, TP-2
B9: Q9 | C9: Responsible-AI guardrails & human oversight (Governance & Ethics) | D9: =IF(Calc!E11="","-",Calc!E11) | E9: =IFERROR(MATCH(11,Calc!$B$87:$B$97,0),"-") | F9: =Calc!I11 | G9: =Calc!L11 | H9: GL-7, RS-1, RS-4, RS-5, CO-1, CO-3
B10: Q10 | C10: AI literacy & capability (Training & Development) | D10: =IF(Calc!E12="","-",Calc!E12) | E10: =IFERROR(MATCH(12,Calc!$B$87:$B$97,0),"-") | F10: =Calc!I12 | G10: =Calc!L12 | H10: GL-4, RS-9
B11: Q11 | C11: Data governance, quality & privacy for AI (Data & Quality) | D11: =IF(Calc!E13="","-",Calc!E13) | E11: =IFERROR(MATCH(13,Calc!$B$87:$B$97,0),"-") | F11: =Calc!I13 | G11: =Calc!L13 | H11: LC-1, SE-4, PR-1, PR-4, PR-5, PR-6
B12: Q12 | C12: AI architecture, integration & monitoring (Architecture & Technology) | D12: =IF(Calc!E14="","-",Calc!E14) | E12: =IFERROR(MATCH(14,Calc!$B$87:$B$97,0),"-") | F12: =Calc!I14 | G12: =Calc!L14 | H12: LC-2, LC-3, LC-8, LC-12, OM-1, OM-4, RM-6
B13: Q13 | C13: Securing AI systems (Protect AI Systems) | D13: =IF(Calc!E15="","-",Calc!E15) | E13: =IFERROR(MATCH(15,Calc!$B$87:$B$97,0),"-") | F13: =Calc!I15 | G13: =Calc!L15 | H13: SE-2, SE-3, SE-6 to SE-10, OM-2, AA-3
B14: Q14 | C14: Defending against AI-enabled threats (Protection from AI Threats) | D14: =IF(Calc!E16="","-",Calc!E16) | E14: =IFERROR(MATCH(16,Calc!$B$87:$B$97,0),"-") | F14: =Calc!I16 | G14: =Calc!L16 | H14: AT-1, AT-2, AT-3, AT-4
B15: Q15 | C15: AI incidents, monitoring & assurance (Governance & Ethics) | D15: =IF(Calc!E17="","-",Calc!E17) | E15: =IFERROR(MATCH(17,Calc!$B$87:$B$97,0),"-") | F15: =Calc!I17 | G15: =Calc!L17 | H15: IM-1, IM-2, IM-3, AA-1, AA-2, RO-4

Sheet Methodology
B1: METHODOLOGY & FRAMEWORK MAPPING
B3: How the tool combines three frameworks
B4: 1) NSW AI Assessment Framework (AIAF, Digital NSW): lifecycle triggers, inherent-risk questions (AI use, decision impact, data, autonomy / reversibility), Low-Critical risk bands, pattern overrides, oversight pathways and the 8 ethics principles. 2) GT AI Ready7: 7 readiness pillars (33 items) and the maturity scale Partial / Informed / Repeatable / Adaptive; findings use AI Ready7 'potential risk' and 'recommended deliverable' language. 3) GT AI RCM v2.1: every readiness question is mapped to the controls that evidence it, so results convert directly into a control-remediation plan.
B6: Scoring - Part A (inherent risk)
B7: Each answer scores 0-4. Weights: A1 AI use x2, A2 decision impact x3, A3 data sensitivity x2, A4 oversight & reversibility x3 (max 40). Weighted % bands: <25% Low, 25-49% Medium, 50-74% High, >=75% Critical. Overrides (AIAF 'pattern risk'): significant-effect decisions (A2=4) -> minimum High; A2=4 with oversight A4>=3 -> Critical; sensitive data (A3=4) -> minimum Medium.
B9: Scoring - Part B (readiness)
B10: Each answer maps to a maturity level 0-4 scored 0%, 25%, 50%, 75%, 100%. Pillar score = average of its questions; overall readiness = equal-weighted average of the 7 pillar scores. Maturity: <50% Partial, 50-69% Informed, 70-89% Repeatable, >=90% Adaptive (AI Ready7 scale).
B12: Exposure & pathway
B13: Exposure = f(inherent tier, maturity) per the matrix below. Pathways mirror the AIAF oversight model: Low -> Proceed (self-managed); Moderate -> Proceed with conditions (SME review, 90-day plan); High -> Remediate before scaling (committee oversight); Critical -> Pause high-impact AI and escalate (board / ExCo).
B15: Prioritisation
B16: Priority = gap (1 - score) x weight. Weight 1.5 for compliance obligations / mandatory requirements, +0.5 for inventory, guardrails and security when the inherent tier is High or Critical. Timing: score <=25% Immediate; 50% on a weighted item Immediate; 50% otherwise Short term; 75% Medium term; 100% Sustain.
B18: Exposure matrix
C19: Inherent tier \ Maturity | D19: Adaptive | E19: Repeatable | F19: Informed | G19: Partial
C20: Low | D20: Low | E20: Low | F20: Moderate | G20: Moderate
C21: Medium | D21: Low | E21: Moderate | F21: Moderate | G21: High
C22: High | D22: Moderate | E22: Moderate | F22: High | G22: Critical
C23: Critical | D23: Moderate | E23: High | F23: Critical | G23: Critical
B25: Question-to-framework mapping
B26: # | C26: Topic | D26: AI Ready7 pillar / items | E26: Type | F26: AIAF principles | G26: GT AI RCM v2.1 controls | H26: Key references
B27: A1 | C27: AI use profile | D27: Inherent risk (Part A) | E27: Inherent-risk driver | F27: All (risk exposure) | G27: RM-5 tiering factor | H27: AIAF Q2, Q5; EU AI Act Art. 3
B28: A2 | C28: Decision impact | D28: Inherent risk (Part A) | E28: Inherent-risk driver | F28: All (risk exposure) | G28: RM-5 tiering factor | H28: AIAF Q7, Q8; EU AI Act Annex III
B29: A3 | C29: Data sensitivity | D29: Inherent risk (Part A) | E29: Inherent-risk driver | F29: All (risk exposure) | G29: RM-5 tiering factor | H29: AIAF Q4; Bahrain PDPL
B30: A4 | C30: Oversight & reversibility | D30: Inherent risk (Part A) | E30: Inherent-risk driver | F30: All (risk exposure) | G30: RM-5 tiering factor | H30: AIAF Q9, Q10, Q13; EU AI Act Art. 14
B31: Q5 | C31: AI strategy, ownership & risk appetite | D31: Business Alignment (1.1) | E31: ☆ Recommended | F31: Accountability | G31: GL-1, GL-3, RM-6 | H31: ISO/IEC 42001 cl.5, 6.2; NIST AI RMF Govern 1
B32: Q6 | C32: Use-case portfolio & value realisation | D32: Business Alignment (1.2, 1.3) | E32: ☆ Recommended | F32: Human, Social & Environmental Wellbeing | G32: GL-6, GL-5 | H32: ISO/IEC 42001 6.2; NIST AI RMF Map 3
B33: Q7 | C33: AI policy, acceptable use & regulatory compliance | D33: Governance & Ethics (2.1, 2.2) | E33: ⟳ Compliance Obligation | F33: Accountability, Privacy & Security | G33: GL-5, RO-1, RO-5 | H33: ISO/IEC 42001 A.2; EU AI Act Art. 5; Bahrain PDPL; CBB
B34: Q8 | C34: AI inventory & risk / impact assessment | D34: Governance & Ethics (2.4, 2.5) | E34: ⚠ Mandatory Requirement | F34: Accountability, Human, Social & Environmental Wellbeing | G34: GL-8, RM-2, RM-5, TP-2 | H34: ISO/IEC 42001 6.1, A.4, A.5; ISO/IEC 42005; EU AI Act Art. 9, 27
B35: Q9 | C35: Responsible-AI guardrails & human oversight | D35: Governance & Ethics (2.3, 5.2) | E35: ⚖ Ethical Consideration | F35: Fairness, Transparency & Explainability, Human-Centred Values, Contestability | G35: GL-7, RS-1, RS-4, RS-5, CO-1, CO-3 | H35: EU AI Act Art. 14, 50, 86; GCC AI Ethics Manual
B36: Q10 | C36: AI literacy & capability | D36: Training & Development (3.1, 3.2, 3.3, 3.4) | E36: ⟳ Compliance Obligation | F36: Human-Centred Values | G36: GL-4, RS-9 | H36: EU AI Act Art. 4; ISO/IEC 42001 7.2
B37: Q11 | C37: Data governance, quality & privacy for AI | D37: Data & Quality (5.1, 5.3, 5.4, 5.5) | E37: ⟳ Compliance Obligation | F37: Privacy & Security, Fairness | G37: LC-1, SE-4, PR-1, PR-4, PR-5, PR-6 | H37: EU AI Act Art. 10; Bahrain PDPL; ISO/IEC 5259
... B41: Q15 | C41: AI incidents, monitoring & assurance | D41: Governance & Ethics (2.2, 7.4) | E41: ⟳ Compliance Obligation | F41: Accountability, Reliability & Safety, Contestability, Transparency & Explainability | G41: IM-1, IM-2, IM-3, AA-1, AA-2, RO-4 | H41: EU AI Act Art. 72-73; ISO/IEC 42001 9-10

Sheet QBank
A1: QID | B1: Option | C1: Value | D1: Status label | E1: Playback / next step | F1: Level
A2: A1 | B2: No AI in use and none planned within 12 months | C2: 0 | D2: Low | E2: Minimal current AI exposure. Readiness still matters: governance is easier to establish before adoption. | F2: Risk level 0 of 4
A3: A1 | B3: Exploratory use of public GenAI tools (e.g., ChatGPT, Copilot web) for internal productivity only | C3: 1 | D3: Low | E3: Main exposures are data leakage into public tools, inaccurate outputs and shadow AI. An acceptable-use policy and literacy training are the first priorities. | F3: Risk level 1 of 4
A4: A1 | B4: Approved enterprise GenAI tools and AI features embedded in business software across teams | C4: 2 | D4: Medium | E4: AI is part of day-to-day work. Exposure spans data protection, output quality, vendor dependence and consistent human review. | F4: Risk level 2 of 4
A5: A1 | B5: Custom or vendor-built AI / ML models supporting core processes or client services | C5: 3 | D5: High | E5: AI influences core outcomes. Model validation, monitoring, data governance and third-party assurance become essential. | F5: Risk level 3 of 4
A6: A1 | B6: AI agents or automated AI decisions acting directly on systems, customers or transactions | C6: 4 | D6: Very high | E6: Highest exposure profile: autonomous actions require execution limits, human approval points, kill-switches and continuous monitoring. | F6: Risk level 4 of 4
A7: A2 | B7: None - AI is used only for drafting, research or personal productivity | C7: 0 | D7: Low | E7: No direct decisions about people; impact limited to quality of internal work products. | F7: Risk level 0 of 4
A8: A2 | B8: Internal operational decisions with minor impact (e.g., scheduling, document triage) | C8: 1 | D8: Low | E8: Errors cause inconvenience but are easily corrected. | F8: Risk level 1 of 4
A9: A2 | B9: Customer- or client-facing outputs with limited individual impact (e.g., FAQ chatbots, marketing content) | C9: 2 | D9: Medium | E9: External stakeholders see AI outputs - disclosure, accuracy and reputational controls apply (e.g., EU AI Act Art. 50 where relevant). | F9: Risk level 2 of 4
A10: A2 | B10: Decisions materially affecting individuals' services, employment or finances, with human review | C10: 3 | D10: High | E10: Fairness, explainability, contestability and effective human oversight are required; impact assessments recommended. | F10: Risk level 3 of 4
A11: A2 | B11: Decisions with legal or similarly significant effects on individuals (credit, hiring, insurance, eligibility, health) made or determined by AI | C11: 4 | D11: Very high | E11: Likely 'high-risk' AI (e.g., EU AI Act Annex III). Full impact assessment, independent validation and committee approval required. | F11: Risk level 4 of 4
A12: A3 | B12: Public or synthetic data only | C12: 0 | D12: Low | E12: Low data-protection exposure. | F12: Risk level 0 of 4
A13: A3 | B13: Internal, non-confidential business information | C13: 1 | D13: Low | E13: Low-moderate exposure; basic data-handling rules apply. | F13: Risk level 1 of 4
... A76: Q15 | B76: Post-incident learning drives improvement; AI management system certified or certification-ready (ISO/IEC 42001); assurance reported to the board | C76: 1 | D76: Fully met | E76: Sustain: maintain certification and report AI assurance results to the board annually. | F76: Level 4 - Optimised

Sheet Calc
A1: Per-question calculations
A2: QID | B2: Topic | C2: Pillar | D2: Answered | E2: Value | F2: Weight/Mult | G2: Gap | H2: Priority | I2: Horizon | J2: Horizon rank | K2: Sort key | L2: Recommendation | M2: RCM | N2: Type | O2: Response | P2: Status | Q2: Risk
A3: A1 | B3: AI use profile | C3: Context | D3: =IF('2. Assessment'!L10="",0,1) | E3: =IF(D3=0,"",'2. Assessment'!F10) | O3: ='2. Assessment'!E10 | P3: ='2. Assessment'!G10
A4: A2 | B4: Decision impact | C4: Context | D4: =IF('2. Assessment'!L11="",0,1) | E4: =IF(D4=0,"",'2. Assessment'!F11) | O4: ='2. Assessment'!E11 | P4: ='2. Assessment'!G11
A5: A3 | B5: Data sensitivity | C5: Context | D5: =IF('2. Assessment'!L12="",0,1) | E5: =IF(D5=0,"",'2. Assessment'!F12) | O5: ='2. Assessment'!E12 | P5: ='2. Assessment'!G12
A6: A4 | B6: Oversight & reversibility | C6: Context | D6: =IF('2. Assessment'!L13="",0,1) | E6: =IF(D6=0,"",'2. Assessment'!F13) | O6: ='2. Assessment'!E13 | P6: ='2. Assessment'!G13
A7: Q5 | B7: AI strategy, ownership & risk appetite | C7: Business Alignment | D7: =IF('2. Assessment'!L15="",0,1) | E7: =IF(D7=0,"",'2. Assessment'!F15) | F7: =1.0+IF(AND(OR(Calc!$C$32="High",Calc!$C$32="Critical"),OR(A7="Q8",A7="Q9",A7="Q13")),0.5,0) | G7: =IF(E7="","",1-E7) | H7: =IF(E7="",-1,G7*F7*100+(15-4)/100) | I7: =IF(E7="","",IF(E7<=0.25,"Immediate (0-3 months)",IF(AND(E7=0.5,F7>=1.5),"Immediate (0-3 months)",IF(E7<=0.5,"Short term (3-6 months)",IF(E7<=0.75,"Medium term (6-12 months)","Sustain"))))) | J7: =IF(I7="",0,IF(LEFT(I7,3)="Imm",4,IF(LEFT(I7,3)="Sho",3,IF(LEFT(I7,3)="Med",2,1)))) | K7: =IF(E7="",-1,J7*1000+H7) | L7: ='2. Assessment'!H15 | M7: GL-1, GL-3, RM-6 | N7: ☆ Recommended | O7: ='2. Assessment'!E15 | P7: ='2. Assessment'!G15 | Q7: Lack of executive direction leads to inconsistent AI use, unmanaged risk-taking, poor-quality outputs and fragmented adoption.
A8: Q6 | B8: Use-case portfolio & value realisation | C8: Business Alignment | D8: =IF('2. Assessment'!L16="",0,1) | E8: =IF(D8=0,"",'2. Assessment'!F16) | F8: =1.0+IF(AND(OR(Calc!$C$32="High",Calc!$C$32="Critical"),OR(A8="Q8",A8="Q9",A8="Q13")),0.5,0) | G8: =IF(E8="","",1-E8) | H8: =IF(E8="",-1,G8*F8*100+(15-5)/100) | I8: =IF(E8="","",IF(E8<=0.25,"Immediate (0-3 months)",IF(AND(E8=0.5,F8>=1.5),"Immediate (0-3 months)",IF(E8<=0.5,"Short term (3-6 months)",IF(E8<=0.75,"Medium term (6-12 months)","Sustain"))))) | J8: =IF(I8="",0,IF(LEFT(I8,3)="Imm",4,IF(LEFT(I8,3)="Sho",3,IF(LEFT(I8,3)="Med",2,1)))) | K8: =IF(E8="",-1,J8*1000+H8) | L8: ='2. Assessment'!H16 | M8: GL-6, GL-5 | N8: ☆ Recommended | O8: ='2. Assessment'!E16 | P8: ='2. Assessment'!G16 | Q8: Duplicated or low-value AI investment, shadow AI and inability to demonstrate return on investment.
A9: Q7 | B9: AI policy, acceptable use & regulatory compliance | C9: Governance & Ethics | D9: =IF('2. Assessment'!L17="",0,1) | E9: =IF(D9=0,"",'2. Assessment'!F17) | F9: =1.5+IF(AND(OR(Calc!$C$32="High",Calc!$C$32="Critical"),OR(A9="Q8",A9="Q9",A9="Q13")),0.5,0) | G9: =IF(E9="","",1-E9) | H9: =IF(E9="",-1,G9*F9*100+(15-6)/100) | I9: =IF(E9="","",IF(E9<=0.25,"Immediate (0-3 months)",IF(AND(E9=0.5,F9>=1.5),"Immediate (0-3 months)",IF(E9<=0.5,"Short term (3-6 months)",IF(E9<=0.75,"Medium term (6-12 months)","Sustain"))))) | J9: =IF(I9="",0,IF(LEFT(I9,3)="Imm",4,IF(LEFT(I9,3)="Sho",3,IF(LEFT(I9,3)="Med",2,1)))) | K9: =IF(E9="",-1,J9*1000+H9) | L9: ='2. Assessment'!H17 | M9: GL-5, RO-1, RO-5 | N9: ⟳ Compliance Obligation | O9: ='2. Assessment'!E17 | P9: ='2. Assessment'!G17 | Q9: Misuse of AI, data leakage and breach of legal or regulatory requirements, with exposure to penalties, licence conditions and reputational harm.
A10: Q8 | B10: AI inventory & risk / impact assessment | C10: Governance & Ethics | D10: =IF('2. Assessment'!L18="",0,1) | E10: =IF(D10=0,"",'2. Assessment'!F18) | F10: =1.5+IF(AND(OR(Calc!$C$32="High",Calc!$C$32="Critical"),OR(A10="Q8",A10="Q9",A10="Q13")),0.5,0) | G10: =IF(E10="","",1-E10) | H10: =IF(E10="",-1,G10*F10*100+(15-7)/100) | I10: =IF(E10="","",IF(E10<=0.25,"Immediate (0-3 months)",IF(AND(E10=0.5,F10>=1.5),"Immediate (0-3 months)",IF(E10<=0.5,"Short term (3-6 months)",IF(E10<=0.75,"Medium term (6-12 months)","Sustain"))))) | J10: =IF(I10="",0,IF(LEFT(I10,3)="Imm",4,IF(LEFT(I10,3)="Sho",3,IF(LEFT(I10,3)="Med",2,1)))) | K10: =IF(E10="",-1,J10*1000+H10) | L10: ='2. Assessment'!H18 | M10: GL-8, RM-2, RM-5, TP-2 | N10: ⚠ Mandatory Requirement | O10: ='2. Assessment'!E18 | P10: ='2. Assessment'!G18 | Q10: Deployment of vulnerable, non-compliant or harmful AI systems and unknown AI exposure across the organisation and its supply chain.
A11: Q9 | B11: Responsible-AI guardrails & human oversight | C11: Governance & Ethics | D11: =IF('2. Assessment'!L19="",0,1) | E11: =IF(D11=0,"",'2. Assessment'!F19) | F11: =1.0+IF(AND(OR(Calc!$C$32="High",Calc!$C$32="Critical"),OR(A11="Q8",A11="Q9",A11="Q13")),0.5,0) | G11: =IF(E11="","",1-E11) | H11: =IF(E11="",-1,G11*F11*100+(15-8)/100) | I11: =IF(E11="","",IF(E11<=0.25,"Immediate (0-3 months)",IF(AND(E11=0.5,F11>=1.5),"Immediate (0-3 months)",IF(E11<=0.5,"Short term (3-6 months)",IF(E11<=0.75,"Medium term (6-12 months)","Sustain"))))) | J11: =IF(I11="",0,IF(LEFT(I11,3)="Imm",4,IF(LEFT(I11,3)="Sho",3,IF(LEFT(I11,3)="Med",2,1)))) | K11: =IF(E11="",-1,J11*1000+H11) | L11: ='2. Assessment'!H19 | M11: GL-7, RS-1, RS-4, RS-5, CO-1, CO-3 | N11: ⚖ Ethical Consideration | O11: ='2. Assessment'!E19 | P11: ='2. Assessment'!G19 | Q11: Biased or harmful outcomes, undisclosed AI use and lack of accountability for AI-supported decisions.
A12: Q10 | B12: AI literacy & capability | C12: Training & Development | D12: =IF('2. Assessment'!L20="",0,1) | E12: =IF(D12=0,"",'2. Assessment'!F20) | F12: =1.5+IF(AND(OR(Calc!$C$32="High",Calc!$C$32="Critical"),OR(A12="Q8",A12="Q9",A12="Q13")),0.5,0) | G12: =IF(E12="","",1-E12) | H12: =IF(E12="",-1,G12*F12*100+(15-9)/100) | I12: =IF(E12="","",IF(E12<=0.25,"Immediate (0-3 months)",IF(AND(E12=0.5,F12>=1.5),"Immediate (0-3 months)",IF(E12<=0.5,"Short term (3-6 months)",IF(E12<=0.75,"Medium term (6-12 months)","Sustain"))))) | J12: =IF(I12="",0,IF(LEFT(I12,3)="Imm",4,IF(LEFT(I12,3)="Sho",3,IF(LEFT(I12,3)="Med",2,1)))) | K12: =IF(E12="",-1,J12*1000+H12) | L12: ='2. Assessment'!H20 | M12: GL-4, RS-9 | N12: ⟳ Compliance Obligation | O12: ='2. Assessment'!E20 | P12: ='2. Assessment'!G20 | Q12: Unsafe use, susceptibility to AI-enabled threats and poor adoption; non-compliance with the EU AI Act Art. 4 AI-literacy duty where applicable.
A13: Q11 | B13: Data governance, quality & privacy for AI | C13: Data & Quality | D13: =IF('2. Assessment'!L21="",0,1) | E13: =IF(D13=0,"",'2. Assessment'!F21) | F13: =1.5+IF(AND(OR(Calc!$C$32="High",Calc!$C$32="Critical"),OR(A13="Q8",A13="Q9",A13="Q13")),0.5,0) | G13: =IF(E13="","",1-E13) | H13: =IF(E13="",-1,G13*F13*100+(15-10)/100) | I13: =IF(E13="","",IF(E13<=0.25,"Immediate (0-3 months)",IF(AND(E13=0.5,F13>=1.5),"Immediate (0-3 months)",IF(E13<=0.5,"Short term (3-6 months)",IF(E13<=0.75,"Medium term (6-12 months)","Sustain"))))) | J13: =IF(I13="",0,IF(LEFT(I13,3)="Imm",4,IF(LEFT(I13,3)="Sho",3,IF(LEFT(I13,3)="Med",2,1)))) | K13: =IF(E13="",-1,J13*1000+H13) | L13: ='2. Assessment'!H21 | M13: LC-1, SE-4, PR-1, PR-4, PR-5, PR-6 | N13: ⟳ Compliance Obligation | O13: ='2. Assessment'!E21 | P13: ='2. Assessment'!G21 | Q13: Data breaches, PDPL non-compliance, and biased or inaccurate outputs from poor-quality or unsuitable data.
A14: Q12 | B14: AI architecture, integration & monitoring | C14: Architecture & Technology | D14: =IF('2. Assessment'!L22="",0,1) | E14: =IF(D14=0,"",'2. Assessment'!F22) | F14: =1.0+IF(AND(OR(Calc!$C$32="High",Calc!$C$32="Critical"),OR(A14="Q8",A14="Q9",A14="Q13")),0.5,0) | G14: =IF(E14="","",1-E14) | H14: =IF(E14="",-1,G14*F14*100+(15-11)/100) | I14: =IF(E14="","",IF(E14<=0.25,"Immediate (0-3 months)",IF(AND(E14=0.5,F14>=1.5),"Immediate (0-3 months)",IF(E14<=0.5,"Short term (3-6 months)",IF(E14<=0.75,"Medium term (6-12 months)","Sustain"))))) | J14: =IF(I14="",0,IF(LEFT(I14,3)="Imm",4,IF(LEFT(I14,3)="Sho",3,IF(LEFT(I14,3)="Med",2,1)))) | K14: =IF(E14="",-1,J14*1000+H14) | L14: ='2. Assessment'!H22 | M14: LC-2, LC-3, LC-8, LC-12, OM-1, OM-4, RM-6 | N14: ☆ Recommended | O14: ='2. Assessment'!E22 | P14: ='2. Assessment'!G22 | Q14: Inconsistent and insecure implementations, undetected model drift or failure, excessive agent privileges and unsustainable AI costs.
A15: Q13 | B15: Securing AI systems | C15: Protect AI Systems | D15: =IF('2. Assessment'!L23="",0,1) | E15: =IF(D15=0,"",'2. Assessment'!F23) | F15: =1.5+IF(AND(OR(Calc!$C$32="High",Calc!$C$32="Critical"),OR(A15="Q8",A15="Q9",A15="Q13")),0.5,0) | G15: =IF(E15="","",1-E15) | H15: =IF(E15="",-1,G15*F15*100+(15-12)/100) | I15: =IF(E15="","",IF(E15<=0.25,"Immediate (0-3 months)",IF(AND(E15=0.5,F15>=1.5),"Immediate (0-3 months)",IF(E15<=0.5,"Short term (3-6 months)",IF(E15<=0.75,"Medium term (6-12 months)","Sustain"))))) | J15: =IF(I15="",0,IF(LEFT(I15,3)="Imm",4,IF(LEFT(I15,3)="Sho",3,IF(LEFT(I15,3)="Med",2,1)))) | K15: =IF(E15="",-1,J15*1000+H15) | L15: ='2. Assessment'!H23 | M15: SE-2, SE-3, SE-6 to SE-10, OM-2, AA-3 | N15: ⚠ Mandatory Requirement | O15: ='2. Assessment'!E23 | P15: ='2. Assessment'!G23 | Q15: Unauthorised access, model compromise, data exfiltration through AI and undetected misuse.
A16: Q14 | B16: Defending against AI-enabled threats | C16: Protection from AI Threats | D16: =IF('2. Assessment'!L24="",0,1) | E16: =IF(D16=0,"",'2. Assessment'!F24) | F16: =1.0+IF(AND(OR(Calc!$C$32="High",Calc!$C$32="Critical"),OR(A16="Q8",A16="Q9",A16="Q13")),0.5,0) | G16: =IF(E16="","",1-E16) | H16: =IF(E16="",-1,G16*F16*100+(15-13)/100) | I16: =IF(E16="","",IF(E16<=0.25,"Immediate (0-3 months)",IF(AND(E16=0.5,F16>=1.5),"Immediate (0-3 months)",IF(E16<=0.5,"Short term (3-6 months)",IF(E16<=0.75,"Medium term (6-12 months)","Sustain"))))) | J16: =IF(I16="",0,IF(LEFT(I16,3)="Imm",4,IF(LEFT(I16,3)="Sho",3,IF(LEFT(I16,3)="Med",2,1)))) | K16: =IF(E16="",-1,J16*1000+H16) | L16: ='2. Assessment'!H24 | M16: AT-1, AT-2, AT-3, AT-4 | N16: ☆ Recommended | O16: ='2. Assessment'!E24 | P16: ='2. Assessment'!G24 | Q16: Deepfake-enabled fraud, account compromise and faster, more scalable attacks that outpace defences.
A17: Q15 | B17: AI incidents, monitoring & assurance | C17: Governance & Ethics | D17: =IF('2. Assessment'!L25="",0,1) | E17: =IF(D17=0,"",'2. Assessment'!F25) | F17: =1.5+IF(AND(OR(Calc!$C$32="High",Calc!$C$32="Critical"),OR(A17="Q8",A17="Q9",A17="Q13")),0.5,0) | G17: =IF(E17="","",1-E17) | H17: =IF(E17="",-1,G17*F17*100+(15-14)/100) | I17: =IF(E17="","",IF(E17<=0.25,"Immediate (0-3 months)",IF(AND(E17=0.5,F17>=1.5),"Immediate (0-3 months)",IF(E17<=0.5,"Short term (3-6 months)",IF(E17<=0.75,"Medium term (6-12 months)","Sustain"))))) | J17: =IF(I17="",0,IF(LEFT(I17,3)="Imm",4,IF(LEFT(I17,3)="Sho",3,IF(LEFT(I17,3)="Med",2,1)))) | K17: =IF(E17="",-1,J17*1000+H17) | L17: ='2. Assessment'!H25 | M17: IM-1, IM-2, IM-3, AA-1, AA-2, RO-4 | N17: ⟳ Compliance Obligation | O17: ='2. Assessment'!E25 | P17: ='2. Assessment'!G25 | Q17: Delayed response to AI failures, missed regulatory notifications and lack of defensible evidence for regulators, auditors and clients.
A20: Answered | B20: =SUM(D3:D17)
A21: Complete | B21: =IF(B20=15,1,0)
A25: Inherent risk
A26: A1 | B26: =IF(E3="","",E3) | C26: 2
A27: A2 | B27: =IF(E4="","",E4) | C27: 3
A28: A3 | B28: =IF(E5="","",E5) | C28: 2
A29: A4 | B29: =IF(E6="","",E6) | C29: 3
A30: Inherent % | C30: =IF(COUNT(B26:B29)<4,"",SUMPRODUCT(B26:B29,C26:C29)/(4*SUM(C26:C29)))
A31: Score tier | C31: =IF(C30="","",IF(C30>=0.75,"Critical",IF(C30>=0.5,"High",IF(C30>=0.25,"Medium","Low"))))
A32: Final tier | C32: =IF(C31="","",IF(AND(B27=4,B29>=3),"Critical",IF(AND(B27=4,OR(C31="Low",C31="Medium")),"High",IF(AND(B28=4,C31="Low"),"Medium",C31))))
A33: Override note | C33: =IF(C31="","",IF(AND(B27=4,B29>=3),"Override: significant-effect decisions with limited oversight -> Critical",IF(AND(B27=4,OR(C31="Low",C31="Medium")),"Override: significant-effect decisions -> minimum High",IF(AND(B28=4,C31="Low"),"Override: sensitive data -> minimum Medium","No override applied"))))
A36: Pillar | B36: Score | C36: Maturity | D36: Target | E36: Risk statement | F36: Service | G36: Service priority | H36: Label
A37: Business Alignment | B37: =IFERROR(AVERAGEIF($C$7:$C$17,A37,$E$7:$E$17),"") | C37: =IF(B37="","",IF(B37>=0.9,"Adaptive",IF(B37>=0.7,"Repeatable",IF(B37>=0.5,"Informed","Partial")))) | D37: 0.7 | E37: Poor AI direction leads to inconsistent use, unmanaged risk, duplication and weak accountability, slowing adoption and reducing trust. | H37: Business | I37: =IF(B37="",0,B37*100) | J37: 70
A38: Governance & Ethics | B38: =IFERROR(AVERAGEIF($C$7:$C$17,A38,$E$7:$E$17),"") | C38: =IF(B38="","",IF(B38>=0.9,"Adaptive",IF(B38>=0.7,"Repeatable",IF(B38>=0.5,"Informed","Partial")))) | D38: 0.7 | E38: Weak AI governance (policies, guardrails, risk assessment, ownership) increases misuse, compliance breaches and uncontrolled AI sprawl. | H38: Governance | I38: =IF(B38="",0,B38*100) | J38: 70
A39: Training & Development | B39: =IFERROR(AVERAGEIF($C$7:$C$17,A39,$E$7:$E$17),"") | C39: =IF(B39="","",IF(B39>=0.9,"Adaptive",IF(B39>=0.7,"Repeatable",IF(B39>=0.5,"Informed","Partial")))) | D39: 0.7 | E39: Low AI literacy and skills increase unsafe use, susceptibility to AI-enabled threats, biased outcomes and limit effective adoption. | H39: Training | I39: =IF(B39="",0,B39*100) | J39: 70
A40: Data & Quality | B40: =IFERROR(AVERAGEIF($C$7:$C$17,A40,$E$7:$E$17),"") | C40: =IF(B40="","",IF(B40>=0.9,"Adaptive",IF(B40>=0.7,"Repeatable",IF(B40>=0.5,"Informed","Partial")))) | D40: 0.7 | E40: Weak data governance and oversight increase the risk of breaches, bias, data misuse, lack of transparency and non-compliance. | H40: Data | I40: =IF(B40="",0,B40*100) | J40: 70
A41: Architecture & Technology | B41: =IFERROR(AVERAGEIF($C$7:$C$17,A41,$E$7:$E$17),"") | C41: =IF(B41="","",IF(B41>=0.9,"Adaptive",IF(B41>=0.7,"Repeatable",IF(B41>=0.5,"Informed","Partial")))) | D41: 0.7 | E41: Weak AI architecture and controls increase security gaps, integration risk, undetected failures and unsustainable costs. | H41: Architecture | I41: =IF(B41="",0,B41*100) | J41: 70
A42: Protect AI Systems | B42: =IFERROR(AVERAGEIF($C$7:$C$17,A42,$E$7:$E$17),"") | C42: =IF(B42="","",IF(B42>=0.9,"Adaptive",IF(B42>=0.7,"Repeatable",IF(B42>=0.5,"Informed","Partial")))) | D42: 0.7 | E42: Weak AI security practices increase the risk of unauthorised access, data leakage, vulnerable deployments and undetected misuse. | H42: Protect AI | I42: =IF(B42="",0,B42*100) | J42: 70
A43: Protection from AI Threats | B43: =IFERROR(AVERAGEIF($C$7:$C$17,A43,$E$7:$E$17),"") | C43: =IF(B43="","",IF(B43>=0.9,"Adaptive",IF(B43>=0.7,"Repeatable",IF(B43>=0.5,"Informed","Partial")))) | D43: 0.7 | E43: Weak AI-threat detection and response increase exposure to deepfakes, AI-crafted attacks and delayed response. | H43: AI Threats | I43: =IF(B43="",0,B43*100) | J43: 70
A45: Overall readiness | B45: =IF(COUNT(B37:B43)=0,"",AVERAGE(B37:B43))
A46: Maturity | B46: =IF(B45="","",IF(B45>=0.9,"Adaptive",IF(B45>=0.7,"Repeatable",IF(B45>=0.5,"Informed","Partial"))))
A47: Strongest pillar | B47: =IFERROR(INDEX(A37:A43,MATCH(MAX(B37:B43),B37:B43,0)),"") | C47: =IFERROR(MAX(B37:B43),"")
A48: Weakest pillar | B48: =IFERROR(INDEX(A37:A43,MATCH(MIN(B37:B43),B37:B43,0)),"") | C48: =IFERROR(MIN(B37:B43),"")
...

Sheet Lists
A1: Yes | B1: Banking & financial services | C1: 1-50 employees | D1: Whole organisation | E1: Deployer only (uses AI built by others) | F1: Not started
A2: No | B2: Insurance | C2: 51-250 employees | D2: Business unit / function | E2: Provider (develops / sells AI systems) | F2: Planned
B3: Government & public sector | C3: 251-1,000 employees | D3: Specific AI system or use case | E3: Both provider and deployer | F3: In progress
B4: Telecommunications | C4: 1,001-5,000 employees | F4: Completed
B5: Healthcare | C5: More than 5,000 employees | F5: Deferred
B6: Hospitality & tourism
B7: Professional services
B8: Manufacturing & industry
B9: Retail & consumer
B10: Energy & utilities
B11: Education
B12: Other
