Workbook

Sheet Welcome
B1: GT AI READINESS & RISK ASSESSMENT TOOL
B2: Grant Thornton Bahrain | AI Governance, Risk & Compliance | Combines the NSW AI Assessment Framework, GT AI Ready7 and the GT AI Risk & Control Matrix v2.1
B4: WHEN TO USE THIS TOOL | D4: HOW IT WORKS (approx. 20-25 minutes) | F4: WHAT YOU GET
B5: - Before or early in your AI journey, to baseline readiness - Before scaling AI or deploying AI that affects customers or decisions - When AI is discovered in use without assessment (shadow AI) - When risk or context changes: new data, model, vendor, purpose or less human oversight - Annually, to track maturity progress Public GenAI tools used for low-risk drafting may be governed by your Acceptable Use Policy instead (AIAF approach). | D5: 1. PROFILE - organisation details and regulatory context 2. ASSESSMENT - 20 questions Part A: 4 questions on AI use and inherent risk (AIAF) Part B: 16 questions on readiness across 5 domains (8 on governance & risk) 3. REPORT - generated automatically, print-ready (A4) 4. ACTION PLAN - assign owners and dates to recommended actions | F5: - Overall AI readiness score and maturity level - Inherent AI risk tier (Low / Medium / High / Critical) - Overall AI risk exposure and recommended oversight pathway - Domain radar chart and responsible-AI principle coverage - Findings, potential risks and recommendations per area - Top-5 priorities and a phased roadmap - Applicable regulations (Bahrain PDPL, CBB, EU AI Act, GCC) - Printable report you can save as PDF and email
B7: COLOUR LEGEND | D7: REQUIREMENT TYPES (as in the AIAF) | F7: START HERE
B8: Input cell - select or type | D8: ⟳ Compliance Obligation - linked to laws / regulation | F8: Go to '1. Profile' >>
B9: Low / Largely met | D9: ⚠ Mandatory Requirement - baseline control expected for any AI use
B10: Medium / Moderate / Partially met | D10: ⚖ Ethical Consideration - responsible-AI principle | F10: Go to '2. Assessment' >>
B11: High / Minimal | D11: ☆ Recommended - good practice
B12: Critical / Very high / Not met | F12: View '3. Report' >>
B15: This is a self-assessment tool. Results depend on the accuracy of responses and do not constitute an audit, certification or legal advice. Version 2.0 - October 2026. GT internal scoring engine - do not distribute; clients complete the GT AI Readiness Questionnaire. SAMPLE: pre-completed with illustrative responses for Grant Thornton Bahrain, aligned to its AI Ready7 results (Sept 2026).

Sheet 1. Profile
B1: 1. ORGANISATION PROFILE
B2: Complete the yellow cells. The profile personalises the report and determines which regulatory considerations apply. Takes about 2 minutes.
B4: Organisation name | C4: Grant Thornton Bahrain | E4: Tip
B5: Sector | C5: Professional services | E5: Scope the assessment to the whole organisation for a readiness baseline, or to a single AI system to support a use-case decision. For use-case level risk assessment use the GT AI Risk Assessment Toolkit.
B6: Organisation size | C6: 251-1,000 employees
B7: Scope of assessment | C7: Whole organisation
B8: Scope description (optional) | C8: Firm-wide AI adoption across Audit, Tax, Advisory and internal functions
B9: Completed by | C9: AI Service Line Lead
B10: Role / title | C10: Director, Risk Advisory
B11: Email address (to send yourself the report)
B12: Assessment date (dd/mm/yyyy) | C12: 24/09/2026
B13: Grant Thornton contact (optional)
B15: REGULATORY CONTEXT
B16: Is the organisation licensed by the Central Bank of Bahrain (CBB)? | C16: No
B17: Do AI systems process personal data of individuals in Bahrain? | C17: Yes
B18: Are AI-enabled products / services offered in the EU, or AI outputs used in the EU? | C18: Yes
B19: Does the organisation operate in KSA, UAE or other GCC markets? | C19: Yes
B20: Is the organisation a government entity or public-sector body? | C20: No
B21: Does the organisation develop AI (provider) or only use it (deployer)? | C21: Deployer only (uses AI built by others)

Sheet 2. Assessment
B1: 2. ASSESSMENT - 20 questions | approx. 20 minutes
B2: Select the statement in column E that best describes your current state (choose the lower level if unsure - evidence should exist for the level selected). Part A profiles your AI use and inherent risk (based on the NSW AI Assessment Framework). Part B measures readiness across 5 domains (derived from the 7 GT AI Ready7 pillars), mapped to the GT AI RCM v2.1 controls. Results update live below and in the '3. Report' sheet.
B4: ANSWERED | D4: OVERALL AI READINESS | E4: MATURITY LEVEL | F4: INHERENT RISK TIER | H4: AI RISK EXPOSURE -> PATHWAY | I4: YOUR REPORT
B5: =Calc!B20&" / 20" -> 20 / 20 | D5: =IF(Calc!B45="","-",Calc!B45) -> 0.59166667 | E5: =IF(Calc!B46="","-",Calc!B46) -> Informed | F5: =IF(Calc!C32="","-",Calc!C32) -> Medium | H5: =IF(Calc!B57="","-",Calc!B57&" -> "&Calc!B58) -> Moderate -> PROCEED WITH CONDITIONS | I5: =IF(Calc!B21=1,"Ready - see 3. Report","Complete all questions") -> Ready - see 3. Report
B8: # | C8: Area | D8: Question | E8: Your response (select from list) | F8: Score | G8: Status | H8: What this means / recommended next step | I8: Linked controls (GT AI RCM v2.1) | J8: Requirement type
B9: PART A - AI USE & INHERENT RISK PROFILE (AIAF-based: how much could go wrong?)
B10: A1 | C10: AI use profile | D10: Which statement best describes how AI is used in your organisation today (including AI embedded in software and tools used by staff)? Consider approved and unapproved tools, vendor software with AI features and AI used by suppliers on your behalf. | E10: Approved enterprise GenAI tools and AI features embedded in business software across teams | F10: =IF(L10="","",INDEX(QBank!$C$2:$C$6,L10)) -> 2 | G10: =IF(L10="","Not answered",INDEX(QBank!$D$2:$D$6,L10)) -> Medium | H10: =IF(L10="","",INDEX(QBank!$E$2:$E$6,L10)) -> AI is part of day-to-day work. Exposure spans data protection, output quality, vendor dependence and consistent human review. | I10: Tiering factor (risk framework T1-T3) | J10: Inherent-risk driver | L10: =IF(E10="","",IFERROR(MATCH(E10,QBank!$B$2:$B$6,0),"")) -> 3
B11: A2 | C11: Decision impact | D11: What is the most significant type of decision or outcome your AI systems influence? Answer for the highest-impact AI use case in scope (AIAF: 'worst credible harm'). | E11: Customer- or client-facing outputs with limited individual impact (e.g., FAQ chatbots, marketing content) | F11: =IF(L11="","",INDEX(QBank!$C$7:$C$11,L11)) -> 2 | G11: =IF(L11="","Not answered",INDEX(QBank!$D$7:$D$11,L11)) -> Medium | H11: =IF(L11="","",INDEX(QBank!$E$7:$E$11,L11)) -> External stakeholders see AI outputs - disclosure, accuracy and reputational controls apply (e.g., EU AI Act Art. 50 where relevant). | I11: Tiering factor (risk framework T1-T3) | J11: Inherent-risk driver | L11: =IF(E11="","",IFERROR(MATCH(E11,QBank!$B$7:$B$11,0),"")) -> 3
B12: A3 | C12: Data sensitivity | D12: What is the most sensitive data processed by your AI systems (including data staff enter into AI tools)? Include prompts, uploaded documents, training / fine-tuning data, retrieval sources and logs. | E12: Confidential business or client information | F12: =IF(L12="","",INDEX(QBank!$C$12:$C$16,L12)) -> 2 | G12: =IF(L12="","Not answered",INDEX(QBank!$D$12:$D$16,L12)) -> Medium | H12: =IF(L12="","",INDEX(QBank!$E$12:$E$16,L12)) -> Confidentiality and contractual obligations apply; vendor data-use terms are critical. | I12: Tiering factor (risk framework T1-T3) | J12: Inherent-risk driver | L12: =IF(E12="","",IFERROR(MATCH(E12,QBank!$B$12:$B$16,0),"")) -> 3
B13: A4 | C13: Oversight & reversibility | D13: How much human oversight applies to AI outputs, and how reversible are the outcomes? AIAF considers autonomy, human oversight and whether outputs are reversible or correctable. | E13: A qualified human reviews and approves every AI output before it is used | F13: =IF(L13="","",INDEX(QBank!$C$17:$C$21,L13)) -> 1 | G13: =IF(L13="","Not answered",INDEX(QBank!$D$17:$D$21,L13)) -> Low | H13: =IF(L13="","",INDEX(QBank!$E$17:$E$21,L13)) -> Effective 'human-in-charge' control if reviewers are trained and have time and authority to challenge. | I13: Tiering factor (risk framework T1-T3) | J13: Inherent-risk driver | L13: =IF(E13="","",IFERROR(MATCH(E13,QBank!$B$17:$B$21,0),"")) -> 2
B14: PART B - AI READINESS & CONTROL MATURITY (5 domains + GT AI RCM: how well is it managed?)
B15: Q5 | C15: AI Governance AI governance structure & accountability | D15: Is there a defined AI governance structure - board / executive oversight, an AI committee with decision rights, named owners for every AI system and clear three-lines-of-defence responsibilities? Evidence: board / ExCo terms of reference covering AI, AI committee charter, RACI, AI system owner register, internal-audit coverage. | E15: AI committee or sponsor defined on paper; roles and decision rights partly documented | F15: =IF(L15="","",INDEX(QBank!$C$22:$C$26,L15)) -> 0.5 | G15: =IF(L15="","Not answered",INDEX(QBank!$D$22:$D$26,L15)) -> Partially met | H15: =IF(L15="","",INDEX(QBank!$E$22:$E$26,L15)) -> Assign named business and technical owners to every AI system and publish a RACI across the three lines of defence. | I15: GL-1, GL-2, GL-7, AA-1 | J15: ⚠ Mandatory Requirement | L15: =IF(E15="","",IFERROR(MATCH(E15,QBank!$B$22:$B$26,0),"")) -> 3
B16: Q6 | C16: AI Governance AI policy, acceptable use & regulatory compliance | D16: Do you have an approved AI (acceptable-use) policy and a process to identify and comply with applicable AI-related regulation (e.g., Bahrain PDPL, CBB rules, EU AI Act)? Evidence: AI policy, approved-tools list, staff acknowledgements, obligations register, compliance reviews. | E16: AI policy enforced with staff acknowledgement; obligations register maps regulations to controls and owners | F16: =IF(L16="","",INDEX(QBank!$C$27:$C$31,L16)) -> 0.75 | G16: =IF(L16="","Not answered",INDEX(QBank!$D$27:$D$31,L16)) -> Largely met | H16: =IF(L16="","",INDEX(QBank!$E$27:$E$31,L16)) -> Establish monthly regulatory horizon scanning and periodic compliance testing with evidence retention. | I16: GL-5, RO-1, RO-5 | J16: ⟳ Compliance Obligation | L16: =IF(E16="","",IFERROR(MATCH(E16,QBank!$B$27:$B$31,0),"")) -> 4
B17: Q7 | C17: AI Governance Responsible-AI guardrails & human oversight | D17: Are there practical guardrails for fairness, transparency and human oversight, overseen by an AI committee or centre of excellence? Evidence: committee / CoE charter, guardrail standards, human-in-charge procedures, bias tests, AI disclosures, appeal routes. | E17: AI committee / CoE established; guardrails defined for some areas (e.g., human review of outputs) | F17: =IF(L17="","",INDEX(QBank!$C$32:$C$36,L17)) -> 0.5 | G17: =IF(L17="","Not answered",INDEX(QBank!$D$32:$D$36,L17)) -> Partially met | H17: =IF(L17="","",INDEX(QBank!$E$32:$E$36,L17)) -> Apply mandatory human-in-charge controls and AI disclosure to all relevant AI; require committee approval for High / Critical uses. | I17: GL-7, RS-1, RS-4, RS-5, CO-1, CO-3 | J17: ⚖ Ethical Consideration | L17: =IF(E17="","",IFERROR(MATCH(E17,QBank!$B$32:$B$36,0),"")) -> 3
B18: Q8 | C18: AI Governance AI incidents, monitoring & assurance | D18: Are AI incidents detected, managed and reported, and is AI governance subject to internal audit or independent assurance? Evidence: AI incident categories, notification criteria, incident logs, internal-audit reports, vendor assurance, certification status. | E18: AI incident management with regulatory notification criteria; periodic internal audit of AI governance; assurance obtained from AI vendors | F18: =IF(L18="","",INDEX(QBank!$C$37:$C$41,L18)) -> 0.75 | G18: =IF(L18="","Not answered",INDEX(QBank!$D$37:$D$41,L18)) -> Largely met | H18: =IF(L18="","",INDEX(QBank!$E$37:$E$41,L18)) -> Implement post-incident learning and an ISO/IEC 42001 certification-readiness review. | I18: IM-1, IM-2, IM-3, AA-1, AA-2, RO-4 | J18: ⟳ Compliance Obligation | L18: =IF(E18="","",IFERROR(MATCH(E18,QBank!$B$37:$B$41,0),"")) -> 4
B19: Q9 | C19: AI Risk & Security AI risk management framework | D19: Is there a documented AI risk management framework - risk taxonomy, assessment method, scoring scales and treatment process - integrated with enterprise risk management? Evidence: AI risk framework / methodology (e.g., aligned to ISO/IEC 23894 or NIST AI RMF), AI risk register, link to the enterprise risk register, completed assessments. | E19: AI risks considered informally within general IT or project risk | F19: =IF(L19="","",INDEX(QBank!$C$42:$C$46,L19)) -> 0.25 | G19: =IF(L19="","Not answered",INDEX(QBank!$D$42:$D$46,L19)) -> Minimal | H19: =IF(L19="","",INDEX(QBank!$E$42:$E$46,L19)) -> Formalise the methodology, approve it at executive level and pilot it on current AI initiatives. | I19: RM-1, RM-2, RM-3, RM-5 | J19: ⚠ Mandatory Requirement | L19: =IF(E19="","",IFERROR(MATCH(E19,QBank!$B$42:$B$46,0),"")) -> 2
B20: Q10 | C20: AI Risk & Security AI risk appetite, KRIs & reporting | D20: Has the board approved an AI risk appetite with measurable tolerances, and are key risk indicators (KRIs) monitored and reported with defined escalation? Evidence: approved AI risk appetite statement, KRI library with thresholds, risk dashboards, escalation and breach records. | E20: AI risk appetite drafted; a few indicators tracked informally | F20: =IF(L20="","",INDEX(QBank!$C$47:$C$51,L20)) -> 0.5 | G20: =IF(L20="","Not answered",INDEX(QBank!$D$47:$D$51,L20)) -> Partially met | H20: =IF(L20="","",INDEX(QBank!$E$47:$E$51,L20)) -> Define KRIs with thresholds and escalation for each risk category and report them to the AI committee quarterly. | I20: RM-6, RM-4, GL-1 | J20: ⚠ Mandatory Requirement | L20: =IF(E20="","",IFERROR(MATCH(E20,QBank!$B$47:$B$51,0),"")) -> 3
B21: Q11 | C21: AI Risk & Security AI inventory & risk / impact assessment | D21: Do you maintain an inventory of AI systems with named owners, and assess AI risks and impacts (including third-party AI) before and after deployment? Evidence: AI register, risk-tiering records, impact assessments, vendor AI due diligence, re-assessment records. | E21: AI register with owners; risk assessments performed for some AI systems using a documented method | F21: =IF(L21="","",INDEX(QBank!$C$52:$C$56,L21)) -> 0.5 | G21: =IF(L21="","Not answered",INDEX(QBank!$D$52:$D$56,L21)) -> Partially met | H21: =IF(L21="","",INDEX(QBank!$E$52:$E$56,L21)) -> Extend assessments to all AI systems and third-party AI; set approval authority by risk tier. | I21: GL-8, RM-2, RM-5, TP-2 | J21: ⚠ Mandatory Requirement | L21: =IF(E21="","",IFERROR(MATCH(E21,QBank!$B$52:$B$56,0),"")) -> 3
B22: Q12 | C22: AI Risk & Security Third-party & AI supply-chain risk | D22: Are AI vendors, AI features in purchased software and foundation-model providers risk-assessed before use, with AI-specific contract clauses and ongoing monitoring? Evidence: AI vendor due-diligence questionnaire, contract clauses (no training on your data, residency, incident notice, audit rights), vendor assurance (ISO/IEC 42001, SOC 2), review records. | E22: AI questions added to vendor due diligence for some purchases; contract terms vary | F22: =IF(L22="","",INDEX(QBank!$C$57:$C$61,L22)) -> 0.5 | G22: =IF(L22="","Not answered",INDEX(QBank!$D$57:$D$61,L22)) -> Partially met | H22: =IF(L22="","",INDEX(QBank!$E$57:$E$61,L22)) -> Make AI due diligence mandatory and adopt standard AI contract clauses (no training on client data, residency, audit, incident notice). | I22: TP-1, TP-2, TP-3, SE-7, LC-6 | J22: ⟳ Compliance Obligation | L22: =IF(E22="","",IFERROR(MATCH(E22,QBank!$B$57:$B$61,0),"")) -> 3
B23: Q13 | C23: AI Risk & Security Securing AI systems | D23: Are AI systems protected with least-privilege access, secure development and testing (incl. red teaming for prompt injection), and runtime logging? Evidence: AI threat models, access reviews (incl. agent identities), AI red-team reports, guardrail and sandbox configurations, audit logs. Detailed test: GT AI Security & Agent Audit Checklist. | E23: AI-specific threats (e.g., prompt injection, data leakage) assessed for some systems; access controls and logging in place | F23: =IF(L23="","",INDEX(QBank!$C$62:$C$66,L23)) -> 0.5 | G23: =IF(L23="","Not answered",INDEX(QBank!$D$62:$D$66,L23)) -> Partially met | H23: =IF(L23="","",INDEX(QBank!$E$62:$E$66,L23)) -> Introduce AI red teaming before release, runtime guardrails (input / output filtering) and audit logging. | I23: SE-2, SE-3, SE-6 to SE-10, OM-2, AA-3 | J23: ⚠ Mandatory Requirement | L23: =IF(E23="","",IFERROR(MATCH(E23,QBank!$B$62:$B$66,0),"")) -> 3
B24: Q14 | C24: AI Risk & Security Defending against AI-enabled threats | D24: Is the organisation prepared for AI-enabled attacks such as deepfake impersonation, AI-crafted phishing and automated exploitation? Evidence: AI threat intelligence, out-of-band verification procedures, deepfake simulations, SOC use cases, playbooks, patch metrics. | E24: Deepfake-resilient verification for payments and sensitive requests; behaviour-based detection; AI incident playbooks exercised | F24: =IF(L24="","",INDEX(QBank!$C$67:$C$71,L24)) -> 0.75 | G24: =IF(L24="","Not answered",INDEX(QBank!$D$67:$D$71,L24)) -> Largely met | H24: =IF(L24="","",INDEX(QBank!$E$67:$E$71,L24)) -> Adopt continuous exposure management and AI-specific red teaming; reduce patch cycles to days. | I24: AT-1, AT-2, AT-3, AT-4 | J24: ☆ Recommended | L24: =IF(E24="","",IFERROR(MATCH(E24,QBank!$B$67:$B$71,0),"")) -> 4
B25: Q15 | C25: Training & Awareness AI training, literacy & awareness | D25: Have staff received AI literacy training appropriate to their role, and are specialist AI, governance and security skills being developed? Evidence: training curricula, completion records, role-based pathways, deepfake / phishing simulations, workforce plan. | E25: Mandatory AI literacy before tool access; role-based pathways for developers, oversight staff and leaders; scenario-based security awareness | F25: =IF(L25="","",INDEX(QBank!$C$72:$C$76,L25)) -> 0.75 | G25: =IF(L25="","Not answered",INDEX(QBank!$D$72:$D$76,L25)) -> Largely met | H25: =IF(L25="","",INDEX(QBank!$E$72:$E$76,L25)) -> Measure competence, refresh annually, and build an AI champions network and workforce plan. | I25: GL-4, RS-9 | J25: ⟳ Compliance Obligation | L25: =IF(E25="","",IFERROR(MATCH(E25,QBank!$B$72:$B$76,0),"")) -> 4
B26: Q16 | C26: Strategy & Value AI strategy & executive ownership | D26: Is there executive ownership and an approved AI strategy that defines the ambition, priorities and where AI will (and will not) be used? Evidence: approved AI strategy, named executive sponsor, AI budget, communicated priorities and experimentation boundaries. | E26: Executive sponsor named and AI strategy drafted, but not linked to business objectives or budget | F26: =IF(L26="","",INDEX(QBank!$C$77:$C$81,L26)) -> 0.5 | G26: =IF(L26="","Not answered",INDEX(QBank!$D$77:$D$81,L26)) -> Partially met | H26: =IF(L26="","",INDEX(QBank!$E$77:$E$81,L26)) -> Link the strategy to business objectives and budget; define experimentation ('sandbox') boundaries and communicate them. | I26: GL-1, GL-3 | J26: ☆ Recommended | L26: =IF(E26="","",IFERROR(MATCH(E26,QBank!$B$77:$B$81,0),"")) -> 3
B27: Q17 | C27: Strategy & Value Use-case portfolio & value realisation | D27: How are AI use cases identified, prioritised, approved and measured for value? Evidence: intake form, prioritisation criteria, business cases, benefit KPIs, portfolio reviews. | E27: Use-case intake exists and initiatives are prioritised, but benefits are not systematically tracked | F27: =IF(L27="","",INDEX(QBank!$C$82:$C$86,L27)) -> 0.5 | G27: =IF(L27="","Not answered",INDEX(QBank!$D$82:$D$86,L27)) -> Partially met | H27: =IF(L27="","",INDEX(QBank!$E$82:$E$86,L27)) -> Define benefit KPIs (financial and non-financial) at approval and assign benefit owners. | I27: GL-6, GL-5 | J27: ☆ Recommended | L27: =IF(E27="","",IFERROR(MATCH(E27,QBank!$B$82:$B$86,0),"")) -> 3
B28: Q18 | C28: Data & Technology Data governance, quality & privacy for AI | D28: Is data used by AI classified, quality-assured, traceable and protected in line with privacy requirements (e.g., Bahrain PDPL)? Evidence: data classification applied to AI, data-readiness assessments, lineage, DPIAs, redaction / anonymisation, transfer assessments. | E28: Data readiness assessed before approval; lineage and quality monitored; minimisation, anonymisation and prompt redaction applied; DPIAs standard | F28: =IF(L28="","",INDEX(QBank!$C$87:$C$91,L28)) -> 0.75 | G28: =IF(L28="","Not answered",INDEX(QBank!$D$87:$D$91,L28)) -> Largely met | H28: =IF(L28="","",INDEX(QBank!$E$87:$E$91,L28)) -> Automate data-quality and lineage monitoring; operationalise data-subject rights and transfer assessments for AI. | I28: LC-1, SE-4, PR-1, PR-4, PR-5, PR-6 | J28: ⟳ Compliance Obligation | L28: =IF(E28="","",IFERROR(MATCH(E28,QBank!$B$87:$B$91,0),"")) -> 4
B29: Q19 | C29: Data & Technology AI architecture, integration & monitoring | D29: Is there a common AI reference architecture with standard integration patterns, and are AI systems monitored for performance, drift and cost? Evidence: reference architecture, approved platforms, integration / agent patterns, monitoring dashboards, cost reports. | E29: Reference architecture drafted; approved platforms and integration patterns for most AI; basic performance monitoring | F29: =IF(L29="","",INDEX(QBank!$C$92:$C$96,L29)) -> 0.5 | G29: =IF(L29="","Not answered",INDEX(QBank!$D$92:$D$96,L29)) -> Partially met | H29: =IF(L29="","",INDEX(QBank!$E$92:$E$96,L29)) -> Centralise API / access control for AI, define agent execution authority and implement drift / performance monitoring with thresholds. | I29: LC-2, LC-3, LC-8, LC-12, OM-1, OM-4, RM-6 | J29: ☆ Recommended | L29: =IF(E29="","",IFERROR(MATCH(E29,QBank!$B$92:$B$96,0),"")) -> 3
B30: Q20 | C30: Data & Technology Model risk management & validation | D30: Are material AI / ML models independently validated before use and periodically, with a model inventory, performance thresholds and documented limitations? Evidence: model risk policy, model inventory with risk tiers, independent validation reports, performance monitoring, validation-findings tracker. | E30: Model inventory exists; validation performed for some material models | F30: =IF(L30="","",INDEX(QBank!$C$97:$C$101,L30)) -> 0.5 | G30: =IF(L30="","Not answered",INDEX(QBank!$D$97:$D$101,L30)) -> Partially met | H30: =IF(L30="","",INDEX(QBank!$E$97:$E$101,L30)) -> Validate all material models before use and on a risk-based cycle; document thresholds, limitations and conditions of use. | I30: LC-9, RS-6, LC-13, OM-1 | J30: ☆ Recommended | L30: =IF(E30="","",IFERROR(MATCH(E30,QBank!$B$97:$B$101,0),"")) -> 3

Sheet 3. Report
B1: AI READINESS & RISK ASSESSMENT - RESULTS REPORT | M1: HOW TO PRINT, SAVE OR EMAIL THIS REPORT
B2: =IF('1. Profile'!$C$4="","Organisation: (not specified)",'1. Profile'!$C$4)&" | "&IF('1. Profile'!$C$5="","",'1. Profile'!$C$5&" | ")&"Assessment date: "&IF('1. Profile'!$C$12="","-",IF(ISNUMBER('1. Profile'!$C$12),TEXT('1. Profile'!$C$12,"dd mmmm yyyy"),'1. Profile'!$C$12)) -> Grant Thornton Bahrain | Professional services | Assessment date: 24/09/2026 | M2: SAVE AS PDF (recommended): File > Save As > choose 'PDF' as the file type > Options > 'Active sheet(s)' > Save. Or File > Export > Create PDF/XPS. This uses Excel's built-in PDF engine and does not depend on any printer driver. PRINT: File > Print > 'Print Active Sheets' (A4 portrait, fitted to one page wide, page breaks between sections). Do not choose 'Print Entire Workbook'. IF 'MICROSOFT PRINT TO PDF' SHOWS AN ERROR: the Windows PDF printer driver is failing, not the workbook. Use Save As > PDF above, or select another printer. To repair the driver: Windows 'Turn Windows features on or off' > untick 'Microsoft Print to PDF' > OK > re-tick > OK, then restart Excel. EMAIL: save the PDF, then click the link below to open a pre-filled email with your headline results and attach the PDF. This panel is outside the print area and will not appear on the printed report.
B3: ="Scope: "&IF('1. Profile'!$C$7="","-",'1. Profile'!$C$7)&IF('1. Profile'!$C$8="",""," - "&'1. Profile'!$C$8)&" | Completed by: "&IF('1. Profile'!$C$9="","-",'1. Profile'!$C$9)&IF('1. Profile'!$C$10="",""," ("&'1. Profile'!$C$10&")") -> Scope: Whole organisation - Firm-wide AI adoption across Audit, Tax, Advisory and internal functions | Completed by: AI Service Line Lead (Director, Risk Advisory)
B4: =IF(Calc!B21=1,"Framework basis: NSW AI Assessment Framework (inherent risk) | ISO/IEC 42001, ISO/IEC 23894, NIST AI RMF | EU AI Act, Bahrain PDPL | GT AI RCM v2.1 (controls)","ASSESSMENT INCOMPLETE - "&Calc!B20&" of 20 questions answered. Results below are provisional.") -> Framework basis: NSW AI Assessment Framework (inherent risk) | ISO/IEC 42001, ISO/IEC 23894, NIST AI RMF | EU AI Act, Bahrain PDPL | GT AI RCM v2.1 (controls)
M5: =IF(Calc!B21=0,"Complete the assessment to enable email",IF('1. Profile'!$C$11="","Enter your email address in 1. Profile to enable the email link",HYPERLINK("mailto:"&'1. Profile'!$C$11&"?subject=AI%20Readiness%20Results&body="&SUBSTITUTE(SUBSTITUTE("AI readiness "&TEXT(Calc!B45,"0%")&" ("&Calc!B46&"); risk tier "&Calc!C32&"; exposure "&Calc!B57&". Report attached.","%","%25")," ","%20"),">> Click to email the results summary to "&'1. Profile'!$C$11))) -> Enter your email address in 1. Profile to enable the email link
B6: 1. EXECUTIVE SUMMARY
B7: OVERALL AI READINESS | E7: MATURITY LEVEL | G7: INHERENT RISK TIER | I7: OVERALL AI RISK EXPOSURE
B8: =IF(Calc!B45="","-",Calc!B45) -> 0.59166667 | E8: =IF(Calc!B46="","-",Calc!B46) -> Informed | G8: =IF(Calc!C32="","-",Calc!C32) -> Medium | I8: =IF(Calc!B57="","-",Calc!B57) -> Moderate
B9: ="Maturity scale: <50% Partial | 50-70% Informed | 70-90% Repeatable | 90%+ Adaptive" -> Maturity scale: <50% Partial | 50-70% Informed | 70-90% Repeatable | 90%+ Adaptive | E9: =Calc!B70 -> Awareness and some defined practices exist, but they are not consistently implemented. | G9: =IF(Calc!C30="","",TEXT(Calc!C30,"0%")&" of maximum inherent risk. "&Calc!C33) -> 43% of maximum inherent risk. No override applied | I9: ="Combines inherent risk tier and readiness maturity (see Methodology)" -> Combines inherent risk tier and readiness maturity (see Methodology)
B11: RECOMMENDED PATHWAY | D11: =IF(Calc!B58="","-",Calc!B58) -> PROCEED WITH CONDITIONS
B12: =Calc!C58 -> Continue AI adoption, but address the identified gaps through a time-bound remediation plan (within 90 days for priority items). Obtain SME review (risk, privacy, security) for new AI use cases.
B14: =Calc!B72 -> Based on the responses provided, Grant Thornton Bahrain has an overall AI readiness score of 59%, corresponding to the 'Informed' maturity level: awareness and some defined practices exist, but they are not consistently implemented. Its AI use profile indicates a MEDIUM inherent risk tier (43% of maximum inherent risk), resulting in an overall AI risk exposure rating of MODERATE. The strongest area is Training & Awareness (75%) and the area requiring most attention is AI Risk & Security (50%). Recommended pathway: PROCEED WITH CONDITIONS. Continue AI adoption, but address the identified gaps through a time-bound remediation plan (within 90 days for priority items). Obtain SME review (risk, privacy, security) for new AI use cases.
B16: POSITION ON THE AI ADOPTION MATURITY CURVE
B17: 1 Awareness | D17: 2 Use-case discovery | F17: 3 Controlled adoption | H17: 4 Enterprise enablement | J17: 5 Governance maturity
B18: =IF(Calc!$B$170=1,"▲ Adoption","")&IF(AND(Calc!$B$171=1,Calc!$B$170<>1),"● Governance",IF(Calc!$B$171=1," ● Governance","")) | D18: =IF(Calc!$B$170=2,"▲ Adoption","")&IF(AND(Calc!$B$171=2,Calc!$B$170<>2),"● Governance",IF(Calc!$B$171=2," ● Governance","")) | F18: =IF(Calc!$B$170=3,"▲ Adoption","")&IF(AND(Calc!$B$171=3,Calc!$B$170<>3),"● Governance",IF(Calc!$B$171=3," ● Governance","")) -> ▲ Adoption ● Governance | H18: =IF(Calc!$B$170=4,"▲ Adoption","")&IF(AND(Calc!$B$171=4,Calc!$B$170<>4),"● Governance",IF(Calc!$B$171=4," ● Governance","")) | J18: =IF(Calc!$B$170=5,"▲ Adoption","")&IF(AND(Calc!$B$171=5,Calc!$B$170<>5),"● Governance",IF(Calc!$B$171=5," ● Governance",""))
B19: =Calc!B174 -> Governance is keeping pace with adoption at Stage 3 (Controlled adoption). To move to Stage 4 (Enterprise enablement), put in place an AI committee, monitoring with KRIs, secure architecture and model validation.
B21: 2. READINESS BY DOMAIN
B22: Domain | D22: Score | E22: Maturity | F22: Progress
B23: AI Governance | D23: =IF(Calc!B37="","-",Calc!B37) -> 0.625 | E23: =IF(Calc!C37="","-",Calc!C37) -> Informed | F23: =IF(Calc!B37="",0,Calc!B37) -> 0.625
B24: AI Risk & Security | D24: =IF(Calc!B38="","-",Calc!B38) -> 0.5 | E24: =IF(Calc!C38="","-",Calc!C38) -> Informed | F24: =IF(Calc!B38="",0,Calc!B38) -> 0.5
B25: Training & Awareness | D25: =IF(Calc!B39="","-",Calc!B39) -> 0.75 | E25: =IF(Calc!C39="","-",Calc!C39) -> Repeatable | F25: =IF(Calc!B39="",0,Calc!B39) -> 0.75
B26: Strategy & Value | D26: =IF(Calc!B40="","-",Calc!B40) -> 0.5 | E26: =IF(Calc!C40="","-",Calc!C40) -> Informed | F26: =IF(Calc!B40="",0,Calc!B40) -> 0.5
B27: Data & Technology | D27: =IF(Calc!B41="","-",Calc!B41) -> 0.58333333 | E27: =IF(Calc!C41="","-",Calc!C41) -> Informed | F27: =IF(Calc!B41="",0,Calc!B41) -> 0.58333333
B28: OVERALL | D28: =IF(Calc!B45="","-",Calc!B45) -> 0.59166667 | E28: =IF(Calc!B46="","-",Calc!B46) -> Informed | F28: ="Target 70%" -> Target 70%
B30: Domain | D30: Potential risk if the domain is not strengthened (shown where score < 90%)
B31: AI Governance | D31: =IF(Calc!B37="","",IF(Calc!B37>=0.9,"Adaptive - maintain current practices.",Calc!E37)) -> Without clear accountability, policy, oversight and assurance, AI is adopted inconsistently, misused and breaches regulation without anyone noticing or answering for it.
B32: AI Risk & Security | D32: =IF(Calc!B38="","",IF(Calc!B38>=0.9,"Adaptive - maintain current practices.",Calc!E38)) -> Without an AI risk framework, risk appetite, impact assessments, third-party controls and AI security, the organisation is exposed to unmanaged AI risk, prompt injection, data leakage, model compromise and deepfake-enabled fraud.
B33: Training & Awareness | D33: =IF(Calc!B39="","",IF(Calc!B39>=0.9,"Adaptive - maintain current practices.",Calc!E39)) -> Low AI literacy and awareness increase unsafe use of AI tools, unchecked or biased outputs and susceptibility to AI-enabled phishing and deepfakes.
B34: Strategy & Value | D34: =IF(Calc!B40="","",IF(Calc!B40>=0.9,"Adaptive - maintain current practices.",Calc!E40)) -> Without clear direction, ownership and value tracking, AI adoption is fragmented, duplicated and hard to justify.
B35: Data & Technology | D35: =IF(Calc!B41="","",IF(Calc!B41>=0.9,"Adaptive - maintain current practices.",Calc!E41)) -> Weak data governance, architecture and model validation lead to inaccurate or biased outputs, privacy breaches, undetected drift and unsustainable costs.
B37: 3. AI USE & INHERENT RISK PROFILE (AIAF-based)
B38: Factor | D38: Your response | H38: Risk level | I38: Implication
B39: A1 AI use profile | D39: =IF('2. Assessment'!E10="","Not answered",'2. Assessment'!E10) -> Approved enterprise GenAI tools and AI features embedded in business software across teams | H39: ='2. Assessment'!G10 -> Medium | I39: ='2. Assessment'!H10 -> AI is part of day-to-day work. Exposure spans data protection, output quality, vendor dependence and consistent human review.
B40: A2 Decision impact | D40: =IF('2. Assessment'!E11="","Not answered",'2. Assessment'!E11) -> Customer- or client-facing outputs with limited individual impact (e.g., FAQ chatbots, marketing content) | H40: ='2. Assessment'!G11 -> Medium | I40: ='2. Assessment'!H11 -> External stakeholders see AI outputs - disclosure, accuracy and reputational controls apply (e.g., EU AI Act Art. 50 where relevant).
B41: A3 Data sensitivity | D41: =IF('2. Assessment'!E12="","Not answered",'2. Assessment'!E12) -> Confidential business or client information | H41: ='2. Assessment'!G12 -> Medium | I41: ='2. Assessment'!H12 -> Confidentiality and contractual obligations apply; vendor data-use terms are critical.
B42: A4 Oversight & reversibility | D42: =IF('2. Assessment'!E13="","Not answered",'2. Assessment'!E13) -> A qualified human reviews and approves every AI output before it is used | H42: ='2. Assessment'!G13 -> Low | I42: ='2. Assessment'!H13 -> Effective 'human-in-charge' control if reviewers are trained and have time and authority to challenge.
B43: ="Inherent risk tier: "&IF(Calc!C32="","-",UPPER(Calc!C32))&IF(Calc!C30="",""," ("&TEXT(Calc!C30,"0%")&" weighted inherent-risk score)") -> Inherent risk tier: MEDIUM (43% weighted inherent-risk score) | H43: =Calc!C33 -> No override applied
B45: 4. RESPONSIBLE-AI PRINCIPLE COVERAGE (NSW AIAF ethics principles)
B46: Principle | E46: Coverage | F46: Assessment | H46: Informed by questions
B47: Fairness | E47: =IF(Calc!B76="","-",Calc!B76) -> 0.58333333 | F47: =Calc!D76 -> Partially addressed | H47: =Calc!C76 -> Q7, Q18, Q20
...

Sheet 4. Action Plan
B1: 4. ACTION PLAN & RISK TREATMENT TRACKER
B2: Columns B-H update automatically from the assessment. Assign an owner, target date and status (yellow cells) to track remediation. Priority rank 1 = most urgent.
B4: # | C4: Area | D4: Current score | E4: Priority rank | F4: Timing | G4: Recommended action | H4: Linked controls (RCM v2.1) | I4: Owner | J4: Target date | K4: Status | L4: Notes / evidence
B5: Q5 | C5: AI governance structure & accountability (AI Governance) | D5: =IF(Calc!E204="","-",Calc!E204) -> 0.5 | E5: =IFERROR(MATCH(204,Calc!$B$87:$B$102,0),"-") -> 2 | F5: =Calc!I204 -> Immediate (0-3 months) | G5: =Calc!L204 -> Assign named business and technical owners to every AI system and publish a RACI across the three lines of defence. | H5: GL-1, GL-2, GL-7, AA-1
B6: Q6 | C6: AI policy, acceptable use & regulatory compliance (AI Governance) | D6: =IF(Calc!E205="","-",Calc!E205) -> 0.75 | E6: =IFERROR(MATCH(205,Calc!$B$87:$B$102,0),"-") -> 12 | F6: =Calc!I205 -> Medium term (6-12 months) | G6: =Calc!L205 -> Establish monthly regulatory horizon scanning and periodic compliance testing with evidence retention. | H6: GL-5, RO-1, RO-5
B7: Q7 | C7: Responsible-AI guardrails & human oversight (AI Governance) | D7: =IF(Calc!E206="","-",Calc!E206) -> 0.5 | E7: =IFERROR(MATCH(206,Calc!$B$87:$B$102,0),"-") -> 7 | F7: =Calc!I206 -> Short term (3-6 months) | G7: =Calc!L206 -> Apply mandatory human-in-charge controls and AI disclosure to all relevant AI; require committee approval for High / Critical uses. | H7: GL-7, RS-1, RS-4, RS-5, CO-1, CO-3
B8: Q8 | C8: AI incidents, monitoring & assurance (AI Governance) | D8: =IF(Calc!E207="","-",Calc!E207) -> 0.75 | E8: =IFERROR(MATCH(207,Calc!$B$87:$B$102,0),"-") -> 13 | F8: =Calc!I207 -> Medium term (6-12 months) | G8: =Calc!L207 -> Implement post-incident learning and an ISO/IEC 42001 certification-readiness review. | H8: IM-1, IM-2, IM-3, AA-1, AA-2, RO-4
B9: Q9 | C9: AI risk management framework (AI Risk & Security) | D9: =IF(Calc!E208="","-",Calc!E208) -> 0.25 | E9: =IFERROR(MATCH(208,Calc!$B$87:$B$102,0),"-") -> 1 | F9: =Calc!I208 -> Immediate (0-3 months) | G9: =Calc!L208 -> Formalise the methodology, approve it at executive level and pilot it on current AI initiatives. | H9: RM-1, RM-2, RM-3, RM-5
B10: Q10 | C10: AI risk appetite, KRIs & reporting (AI Risk & Security) | D10: =IF(Calc!E209="","-",Calc!E209) -> 0.5 | E10: =IFERROR(MATCH(209,Calc!$B$87:$B$102,0),"-") -> 3 | F10: =Calc!I209 -> Immediate (0-3 months) | G10: =Calc!L209 -> Define KRIs with thresholds and escalation for each risk category and report them to the AI committee quarterly. | H10: RM-6, RM-4, GL-1
B11: Q11 | C11: AI inventory & risk / impact assessment (AI Risk & Security) | D11: =IF(Calc!E210="","-",Calc!E210) -> 0.5 | E11: =IFERROR(MATCH(210,Calc!$B$87:$B$102,0),"-") -> 4 | F11: =Calc!I210 -> Immediate (0-3 months) | G11: =Calc!L210 -> Extend assessments to all AI systems and third-party AI; set approval authority by risk tier. | H11: GL-8, RM-2, RM-5, TP-2
B12: Q12 | C12: Third-party & AI supply-chain risk (AI Risk & Security) | D12: =IF(Calc!E211="","-",Calc!E211) -> 0.5 | E12: =IFERROR(MATCH(211,Calc!$B$87:$B$102,0),"-") -> 5 | F12: =Calc!I211 -> Immediate (0-3 months) | G12: =Calc!L211 -> Make AI due diligence mandatory and adopt standard AI contract clauses (no training on client data, residency, audit, incident notice). | H12: TP-1, TP-2, TP-3, SE-7, LC-6
B13: Q13 | C13: Securing AI systems (AI Risk & Security) | D13: =IF(Calc!E212="","-",Calc!E212) -> 0.5 | E13: =IFERROR(MATCH(212,Calc!$B$87:$B$102,0),"-") -> 6 | F13: =Calc!I212 -> Immediate (0-3 months) | G13: =Calc!L212 -> Introduce AI red teaming before release, runtime guardrails (input / output filtering) and audit logging. | H13: SE-2, SE-3, SE-6 to SE-10, OM-2, AA-3
B14: Q14 | C14: Defending against AI-enabled threats (AI Risk & Security) | D14: =IF(Calc!E213="","-",Calc!E213) -> 0.75 | E14: =IFERROR(MATCH(213,Calc!$B$87:$B$102,0),"-") -> 16 | F14: =Calc!I213 -> Medium term (6-12 months) | G14: =Calc!L213 -> Adopt continuous exposure management and AI-specific red teaming; reduce patch cycles to days. | H14: AT-1, AT-2, AT-3, AT-4
B15: Q15 | C15: AI training, literacy & awareness (Training & Awareness) | D15: =IF(Calc!E214="","-",Calc!E214) -> 0.75 | E15: =IFERROR(MATCH(214,Calc!$B$87:$B$102,0),"-") -> 14 | F15: =Calc!I214 -> Medium term (6-12 months) | G15: =Calc!L214 -> Measure competence, refresh annually, and build an AI champions network and workforce plan. | H15: GL-4, RS-9
B16: Q16 | C16: AI strategy & executive ownership (Strategy & Value) | D16: =IF(Calc!E215="","-",Calc!E215) -> 0.5 | E16: =IFERROR(MATCH(215,Calc!$B$87:$B$102,0),"-") -> 8 | F16: =Calc!I215 -> Short term (3-6 months) | G16: =Calc!L215 -> Link the strategy to business objectives and budget; define experimentation ('sandbox') boundaries and communicate them. | H16: GL-1, GL-3
B17: Q17 | C17: Use-case portfolio & value realisation (Strategy & Value) | D17: =IF(Calc!E216="","-",Calc!E216) -> 0.5 | E17: =IFERROR(MATCH(216,Calc!$B$87:$B$102,0),"-") -> 9 | F17: =Calc!I216 -> Short term (3-6 months) | G17: =Calc!L216 -> Define benefit KPIs (financial and non-financial) at approval and assign benefit owners. | H17: GL-6, GL-5
B18: Q18 | C18: Data governance, quality & privacy for AI (Data & Technology) | D18: =IF(Calc!E217="","-",Calc!E217) -> 0.75 | E18: =IFERROR(MATCH(217,Calc!$B$87:$B$102,0),"-") -> 15 | F18: =Calc!I217 -> Medium term (6-12 months) | G18: =Calc!L217 -> Automate data-quality and lineage monitoring; operationalise data-subject rights and transfer assessments for AI. | H18: LC-1, SE-4, PR-1, PR-4, PR-5, PR-6
B19: Q19 | C19: AI architecture, integration & monitoring (Data & Technology) | D19: =IF(Calc!E218="","-",Calc!E218) -> 0.5 | E19: =IFERROR(MATCH(218,Calc!$B$87:$B$102,0),"-") -> 10 | F19: =Calc!I218 -> Short term (3-6 months) | G19: =Calc!L218 -> Centralise API / access control for AI, define agent execution authority and implement drift / performance monitoring with thresholds. | H19: LC-2, LC-3, LC-8, LC-12, OM-1, OM-4, RM-6
B20: Q20 | C20: Model risk management & validation (Data & Technology) | D20: =IF(Calc!E219="","-",Calc!E219) -> 0.5 | E20: =IFERROR(MATCH(219,Calc!$B$87:$B$102,0),"-") -> 11 | F20: =Calc!I219 -> Short term (3-6 months) | G20: =Calc!L219 -> Validate all material models before use and on a risk-based cycle; document thresholds, limitations and conditions of use. | H20: LC-9, RS-6, LC-13, OM-1

Sheet Methodology
B1: METHODOLOGY & FRAMEWORK MAPPING
B3: How the tool combines three frameworks
B4: 1) NSW AI Assessment Framework (AIAF, Digital NSW): lifecycle triggers, inherent-risk questions (AI use, decision impact, data, autonomy / reversibility), Low-Critical risk bands, pattern overrides, oversight pathways and the 8 ethics principles. 2) GT AI Ready7: the 7 pillars (33 items) are consolidated into 5 domains - AI Governance; AI Risk & Security (Protect AI Systems + Protection from AI Threats, plus AI risk management); Training & Awareness; Strategy & Value; Data & Technology - using the AI Ready7 maturity scale Partial / Informed / Repeatable / Adaptive. 3) GT AI RCM v2.1: every readiness question is mapped to the controls that evidence it, so results convert directly into a control-remediation plan.
B6: Scoring - Part A (inherent risk)
B7: Each answer scores 0-4. Weights: A1 AI use x2, A2 decision impact x3, A3 data sensitivity x2, A4 oversight & reversibility x3 (max 40). Weighted % bands: <25% Low, 25-49% Medium, 50-74% High, >=75% Critical. Overrides (AIAF 'pattern risk'): significant-effect decisions (A2=4) -> minimum High; A2=4 with oversight A4>=3 -> Critical; sensitive data (A3=4) -> minimum Medium.
B9: Scoring - Part B (readiness)
B10: Each answer maps to a maturity level 0-4 scored 0%, 25%, 50%, 75%, 100%. Domain score = average of its questions; overall readiness = equal-weighted average of the 5 domain scores. Maturity: <50% Partial, 50-69% Informed, 70-89% Repeatable, >=90% Adaptive (AI Ready7 scale).
B12: Exposure & pathway
B13: Exposure = f(inherent tier, maturity) per the matrix below. Pathways mirror the AIAF oversight model: Low -> Proceed (self-managed); Moderate -> Proceed with conditions (SME review, 90-day plan); High -> Remediate before scaling (committee oversight); Critical -> Pause high-impact AI and escalate (board / ExCo).
B15: Prioritisation
B16: Priority = gap (1 - score) x weight. Weight 1.5 for compliance obligations / mandatory requirements, +0.5 for inventory, guardrails and security when the inherent tier is High or Critical. Timing: score <=25% Immediate; 50% on a weighted item Immediate; 50% otherwise Short term; 75% Medium term; 100% Sustain.
B18: Exposure matrix
C19: Inherent tier \ Maturity | D19: Adaptive | E19: Repeatable | F19: Informed | G19: Partial
C20: Low | D20: Low | E20: Low | F20: Moderate | G20: Moderate
C21: Medium | D21: Low | E21: Moderate | F21: Moderate | G21: High
C22: High | D22: Moderate | E22: Moderate | F22: High | G22: Critical
C23: Critical | D23: Moderate | E23: High | F23: Critical | G23: Critical
B25: Question-to-framework mapping
B26: # | C26: Topic | D26: Domain (AI Ready7 items) | E26: Type | F26: AIAF principles | G26: GT AI RCM v2.1 controls | H26: Key references
B27: A1 | C27: AI use profile | D27: Inherent risk (Part A) | E27: Inherent-risk driver | F27: All (risk exposure) | G27: RM-5 tiering factor | H27: AIAF Q2, Q5; EU AI Act Art. 3
B28: A2 | C28: Decision impact | D28: Inherent risk (Part A) | E28: Inherent-risk driver | F28: All (risk exposure) | G28: RM-5 tiering factor | H28: AIAF Q7, Q8; EU AI Act Annex III
B29: A3 | C29: Data sensitivity | D29: Inherent risk (Part A) | E29: Inherent-risk driver | F29: All (risk exposure) | G29: RM-5 tiering factor | H29: AIAF Q4; Bahrain PDPL
B30: A4 | C30: Oversight & reversibility | D30: Inherent risk (Part A) | E30: Inherent-risk driver | F30: All (risk exposure) | G30: RM-5 tiering factor | H30: AIAF Q9, Q10, Q13; EU AI Act Art. 14
B31: Q5 | C31: AI governance structure & accountability | D31: AI Governance (1.1, 2.3) | E31: ⚠ Mandatory Requirement | F31: Accountability | G31: GL-1, GL-2, GL-7, AA-1 | H31: ISO/IEC 42001 cl.5, 6.2; NIST AI RMF Govern 1
B32: Q6 | C32: AI policy, acceptable use & regulatory compliance | D32: AI Governance (2.1, 2.2) | E32: ⟳ Compliance Obligation | F32: Accountability, Privacy & Security | G32: GL-5, RO-1, RO-5 | H32: ISO/IEC 42001 6.2; NIST AI RMF Map 3
B33: Q7 | C33: Responsible-AI guardrails & human oversight | D33: AI Governance (2.3, 5.2) | E33: ⚖ Ethical Consideration | F33: Fairness, Transparency & Explainability, Human-Centred Values, Contestability | G33: GL-7, RS-1, RS-4, RS-5, CO-1, CO-3 | H33: ISO/IEC 42001 cl.5.1-5.3, A.3; NIST AI RMF Govern 2; IIA Three Lines Model
B34: Q8 | C34: AI incidents, monitoring & assurance | D34: AI Governance (2.2, 7.4) | E34: ⟳ Compliance Obligation | F34: Accountability, Reliability & Safety, Contestability, Transparency & Explainability | G34: IM-1, IM-2, IM-3, AA-1, AA-2, RO-4 | H34: ISO/IEC 42001 A.2; EU AI Act Art. 5; Bahrain PDPL; CBB
B35: Q9 | C35: AI risk management framework | D35: AI Risk & Security (2.4) | E35: ⚠ Mandatory Requirement | F35: Accountability, Reliability & Safety | G35: RM-1, RM-2, RM-3, RM-5 | H35: ISO/IEC 23894; ISO/IEC 42001 6.1; NIST AI RMF Map/Measure/Manage
B36: Q10 | C36: AI risk appetite, KRIs & reporting | D36: AI Risk & Security (1.1, 4.4) | E36: ⚠ Mandatory Requirement | F36: Accountability | G36: RM-6, RM-4, GL-1 | H36: NIST AI RMF Govern 1.3; ISO 31000; CBB RM Module
B37: Q11 | C37: AI inventory & risk / impact assessment | D37: AI Risk & Security (2.4, 2.5) | E37: ⚠ Mandatory Requirement | F37: Accountability, Human, Social & Environmental Wellbeing | G37: GL-8, RM-2, RM-5, TP-2 | H37: ISO/IEC 42001 6.1, A.4, A.5; ISO/IEC 42005; EU AI Act Art. 9, 27
... B46: Q20 | C46: Model risk management & validation | D46: Data & Technology (4.4, 6.3) | E46: ☆ Recommended | F46: Reliability & Safety, Fairness | G46: LC-9, RS-6, LC-13, OM-1 | H46: MITRE ATLAS; FinCEN deepfake alert

Sheet QBank
A1: QID | B1: Option | C1: Value | D1: Status label | E1: Playback / next step | F1: Level
A2: A1 | B2: No AI in use and none planned within 12 months | C2: 0 | D2: Low | E2: Minimal current AI exposure. Readiness still matters: governance is easier to establish before adoption. | F2: Risk level 0 of 4
A3: A1 | B3: Exploratory use of public GenAI tools (e.g., ChatGPT, Copilot web) for internal productivity only | C3: 1 | D3: Low | E3: Main exposures are data leakage into public tools, inaccurate outputs and shadow AI. An acceptable-use policy and literacy training are the first priorities. | F3: Risk level 1 of 4
A4: A1 | B4: Approved enterprise GenAI tools and AI features embedded in business software across teams | C4: 2 | D4: Medium | E4: AI is part of day-to-day work. Exposure spans data protection, output quality, vendor dependence and consistent human review. | F4: Risk level 2 of 4
A5: A1 | B5: Custom or vendor-built AI / ML models supporting core processes or client services | C5: 3 | D5: High | E5: AI influences core outcomes. Model validation, monitoring, data governance and third-party assurance become essential. | F5: Risk level 3 of 4
A6: A1 | B6: AI agents or automated AI decisions acting directly on systems, customers or transactions | C6: 4 | D6: Very high | E6: Highest exposure profile: autonomous actions require execution limits, human approval points, kill-switches and continuous monitoring. | F6: Risk level 4 of 4
A7: A2 | B7: None - AI is used only for drafting, research or personal productivity | C7: 0 | D7: Low | E7: No direct decisions about people; impact limited to quality of internal work products. | F7: Risk level 0 of 4
A8: A2 | B8: Internal operational decisions with minor impact (e.g., scheduling, document triage) | C8: 1 | D8: Low | E8: Errors cause inconvenience but are easily corrected. | F8: Risk level 1 of 4
A9: A2 | B9: Customer- or client-facing outputs with limited individual impact (e.g., FAQ chatbots, marketing content) | C9: 2 | D9: Medium | E9: External stakeholders see AI outputs - disclosure, accuracy and reputational controls apply (e.g., EU AI Act Art. 50 where relevant). | F9: Risk level 2 of 4
A10: A2 | B10: Decisions materially affecting individuals' services, employment or finances, with human review | C10: 3 | D10: High | E10: Fairness, explainability, contestability and effective human oversight are required; impact assessments recommended. | F10: Risk level 3 of 4
A11: A2 | B11: Decisions with legal or similarly significant effects on individuals (credit, hiring, insurance, eligibility, health) made or determined by AI | C11: 4 | D11: Very high | E11: Likely 'high-risk' AI (e.g., EU AI Act Annex III). Full impact assessment, independent validation and committee approval required. | F11: Risk level 4 of 4
A12: A3 | B12: Public or synthetic data only | C12: 0 | D12: Low | E12: Low data-protection exposure. | F12: Risk level 0 of 4
A13: A3 | B13: Internal, non-confidential business information | C13: 1 | D13: Low | E13: Low-moderate exposure; basic data-handling rules apply. | F13: Risk level 1 of 4
... A101: Q20 | B101: Model risk management aligned to SR 11-7 / PRA SS1/23 principles, with continuous monitoring and findings tracked to closure | C101: 1 | D101: Fully met | E101: Sustain: align with SR 11-7 / PRA SS1/23 principles and report model risk to the risk committee. | F101: Level 4 - Optimised

Sheet Calc
A1: Per-question calculations
A20: Answered | B20: =SUM(D200:D219) -> 20
A21: Complete | B21: =IF(B20=20,1,0) -> 1
A25: Inherent risk
A26: A1 | B26: =IF(E200="","",E200) -> 2 | C26: 2
A27: A2 | B27: =IF(E201="","",E201) -> 2 | C27: 3
A28: A3 | B28: =IF(E202="","",E202) -> 2 | C28: 2
A29: A4 | B29: =IF(E203="","",E203) -> 1 | C29: 3
A30: Inherent % | C30: =IF(COUNT(B26:B29)<4,"",SUMPRODUCT(B26:B29,C26:C29)/(4*SUM(C26:C29))) -> 0.425
A31: Score tier | C31: =IF(C30="","",IF(C30>=0.75,"Critical",IF(C30>=0.5,"High",IF(C30>=0.25,"Medium","Low")))) -> Medium
A32: Final tier | C32: =IF(C31="","",IF(AND(B27=4,B29>=3),"Critical",IF(AND(B27=4,OR(C31="Low",C31="Medium")),"High",IF(AND(B28=4,C31="Low"),"Medium",C31)))) -> Medium
A33: Override note | C33: =IF(C31="","",IF(AND(B27=4,B29>=3),"Override: significant-effect decisions with limited oversight -> Critical",IF(AND(B27=4,OR(C31="Low",C31="Medium")),"Override: significant-effect decisions -> minimum High",IF(AND(B28=4,C31="Low"),"Override: sensitive data -> minimum Medium","No override applied")))) -> No override applied
A36: Pillar | B36: Score | C36: Maturity | D36: Target | E36: Risk statement | F36: Service | G36: Service priority | H36: Label
A37: AI Governance | B37: =IFERROR(AVERAGEIF($C$204:$C$219,A37,$E$204:$E$219),"") -> 0.625 | C37: =IF(B37="","",IF(B37>=0.9,"Adaptive",IF(B37>=0.7,"Repeatable",IF(B37>=0.5,"Informed","Partial")))) -> Informed | D37: 0.7 | E37: Without clear accountability, policy, oversight and assurance, AI is adopted inconsistently, misused and breaches regulation without anyone noticing or answering for it. | H37: Governance | I37: =IF(B37="",0,B37*100) -> 62.5 | J37: 70
A38: AI Risk & Security | B38: =IFERROR(AVERAGEIF($C$204:$C$219,A38,$E$204:$E$219),"") -> 0.5 | C38: =IF(B38="","",IF(B38>=0.9,"Adaptive",IF(B38>=0.7,"Repeatable",IF(B38>=0.5,"Informed","Partial")))) -> Informed | D38: 0.7 | E38: Without an AI risk framework, risk appetite, impact assessments, third-party controls and AI security, the organisation is exposed to unmanaged AI risk, prompt injection, data leakage, model compromise and deepfake-enabled fraud. | H38: Risk & Security | I38: =IF(B38="",0,B38*100) -> 50 | J38: 70
A39: Training & Awareness | B39: =IFERROR(AVERAGEIF($C$204:$C$219,A39,$E$204:$E$219),"") -> 0.75 | C39: =IF(B39="","",IF(B39>=0.9,"Adaptive",IF(B39>=0.7,"Repeatable",IF(B39>=0.5,"Informed","Partial")))) -> Repeatable | D39: 0.7 | E39: Low AI literacy and awareness increase unsafe use of AI tools, unchecked or biased outputs and susceptibility to AI-enabled phishing and deepfakes. | H39: Training | I39: =IF(B39="",0,B39*100) -> 75 | J39: 70
A40: Strategy & Value | B40: =IFERROR(AVERAGEIF($C$204:$C$219,A40,$E$204:$E$219),"") -> 0.5 | C40: =IF(B40="","",IF(B40>=0.9,"Adaptive",IF(B40>=0.7,"Repeatable",IF(B40>=0.5,"Informed","Partial")))) -> Informed | D40: 0.7 | E40: Without clear direction, ownership and value tracking, AI adoption is fragmented, duplicated and hard to justify. | H40: Strategy | I40: =IF(B40="",0,B40*100) -> 50 | J40: 70
A41: Data & Technology | B41: =IFERROR(AVERAGEIF($C$204:$C$219,A41,$E$204:$E$219),"") -> 0.58333333 | C41: =IF(B41="","",IF(B41>=0.9,"Adaptive",IF(B41>=0.7,"Repeatable",IF(B41>=0.5,"Informed","Partial")))) -> Informed | D41: 0.7 | E41: Weak data governance, architecture and model validation lead to inaccurate or biased outputs, privacy breaches, undetected drift and unsustainable costs. | H41: Data & Tech | I41: =IF(B41="",0,B41*100) -> 58.333333 | J41: 70
A45: Overall readiness | B45: =IF(COUNT(B37:B41)=0,"",AVERAGE(B37:B41)) -> 0.59166667
A46: Maturity | B46: =IF(B45="","",IF(B45>=0.9,"Adaptive",IF(B45>=0.7,"Repeatable",IF(B45>=0.5,"Informed","Partial")))) -> Informed
A47: Strongest pillar | B47: =IFERROR(INDEX(A37:A41,MATCH(MAX(B37:B41),B37:B41,0)),"") -> Training & Awareness | C47: =IFERROR(MAX(B37:B41),"") -> 0.75
A48: Weakest pillar | B48: =IFERROR(INDEX(A37:A41,MATCH(MIN(B37:B41),B37:B41,0)),"") -> AI Risk & Security | C48: =IFERROR(MIN(B37:B41),"") -> 0.5
A51: Exposure matrix | B51: Adaptive | C51: Repeatable | D51: Informed | E51: Partial
A52: Low | B52: Low | C52: Low | D52: Moderate | E52: Moderate
A53: Medium | B53: Low | C53: Moderate | D53: Moderate | E53: High
A54: High | B54: Moderate | C54: Moderate | D54: High | E54: Critical
A55: Critical | B55: Moderate | C55: High | D55: Critical | E55: Critical
A57: Exposure | B57: =IFERROR(INDEX($B$52:$E$55,MATCH(C32,$A$52:$A$55,0),MATCH(B46,$B$51:$E$51,0)),"") -> Moderate
A58: Pathway | B58: =IFERROR(VLOOKUP(B57,$A$60:$C$63,2,FALSE),"") -> PROCEED WITH CONDITIONS | C58: =IFERROR(VLOOKUP(B57,$A$60:$C$63,3,FALSE),"") -> Continue AI adoption, but address the identified gaps through a time-bound remediation plan (within 90 days for priority items). Obtain SME review (risk, privacy, security) for new AI use cases.
A60: Low | B60: PROCEED - SELF-MANAGED | C60: AI capability is broadly commensurate with the organisation's AI risk profile. Maintain controls, keep the AI register current and reassess annually or on material change.
A61: Moderate | B61: PROCEED WITH CONDITIONS | C61: Continue AI adoption, but address the identified gaps through a time-bound remediation plan (within 90 days for priority items). Obtain SME review (risk, privacy, security) for new AI use cases.
A62: High | B62: REMEDIATE BEFORE SCALING | C62: Readiness is insufficient for the organisation's AI risk profile. Limit AI to lower-risk uses until priority gaps are closed; place AI adoption under AI committee / executive oversight.
A63: Critical | B63: PAUSE HIGH-IMPACT AI & ESCALATE | C63: Significant AI exposure with immature controls. Escalate to the board / executive committee; do not deploy or expand high-impact AI until critical controls are in place.
A66: Partial | B66: Foundational capabilities are missing or ad hoc; AI risk is largely unmanaged.
A67: Informed | B67: Awareness and some defined practices exist, but they are not consistently implemented.
A68: Repeatable | B68: Practices are defined and consistently applied across most of the organisation.
A69: Adaptive | B69: Practices are optimised, measured and continuously improved.
A70: Maturity description | B70: =IFERROR(VLOOKUP(B46,$A$66:$B$69,2,FALSE),"") -> Awareness and some defined practices exist, but they are not consistently implemented.
A72: Narrative | B72: =IF(B21=0,"The assessment is incomplete ("&B20&" of 20 questions answered). Complete all questions in the Assessment sheet to generate the executive summary.","Based on the responses provided, "&IF('1. Profile'!$C$4="","the organisation",'1. Profile'!$C$4)&" has an overall AI readiness score of "&TEXT(B45,"0%")&", corresponding to the "&CHAR(39)&B46&CHAR(39)&" maturity level: "&LOWER(LEFT(B70,1))&MID(B70,2,300)&" Its AI use profile indicates a "&UPPER(C32)&" inherent risk tier ("&TEXT(C30,"0%")&" of maximum inherent risk), resulting in an overall AI risk exposure rating of "&UPPER(B57)&". The strongest area is "&B47&" ("&TEXT(C47,"0%")&") and the area requiring most attention is "&B48&" ("&TEXT(C48,"0%")&"). Recommended pathway: "&B58&". "&C58) -> Based on the responses provided, Grant Thornton Bahrain has an overall AI readiness score of 59%, corresponding to the 'Informed' maturity level: awareness and some defined practices exist, but they are not consistently implemented. Its AI use profile indicates a MEDIUM inherent risk tier (43% of maximum inherent risk), resulting in an overall AI risk exposure rating of MODERATE. The strongest area is Training & Awareness (75%) and the area requiring most attention is AI Risk & Security (50%). Recommended pathway: PROCEED WITH CONDITIONS. Continue AI adoption, but address the identified gaps through a time-bound remediation plan (within 90 days for priority items). Obtain SME review (risk, privacy, security) for new AI use cases.
A75: AIAF principle coverage
...

Sheet Lists
A1: Yes | B1: Banking & financial services | C1: 1-50 employees | D1: Whole organisation | E1: Deployer only (uses AI built by others) | F1: Not started
A2: No | B2: Insurance | C2: 51-250 employees | D2: Business unit / function | E2: Provider (develops / sells AI systems) | F2: Planned
B3: Government & public sector | C3: 251-1,000 employees | D3: Specific AI system or use case | E3: Both provider and deployer | F3: In progress
B4: Telecommunications | C4: 1,001-5,000 employees | F4: Completed
B5: Healthcare | C5: More than 5,000 employees | F5: Deferred
B6: Hospitality & tourism
B7: Professional services
B8: Manufacturing & industry
B9: Retail & consumer
B10: Energy & utilities
B11: Education
B12: Other
